Workbook

Sheet Overview
A1: Company | C1: =advaltech_IS!C2
A2: Industry | C2: Industrial equipment
A3: Ticker | C3: ALTRI
A4: Country | C4: Europe (Fr)
A5: Currency | C5: Euros
A6: Price (input) | C6: 5.1
A7: Market Cap (mm USD) | C7: 22.4
A8: P/NCAV | C8: =ncav!AQ46
A9: Date Founded | C9: 1992
A10: Date Listed | C10: https://www.trilogiq.com/en-us
A11: Website

Sheet ncav
D1: 2015-09-30 | E1: 2015-12-31 | F1: 2016-03-31 | G1: 2016-06-30 | H1: 2016-09-30 | I1: 2016-12-31 | J1: 2017-03-31 | K1: 2017-06-30 | L1: 2017-09-30 | M1: 2017-12-31 | N1: 2018-03-31 | O1: 2018-06-30 | P1: 2018-09-30 | Q1: 2018-12-31 | R1: 2019-03-31 | S1: 2019-06-30 | T1: 2019-09-30 | U1: 2019-12-31 | V1: 2020-03-31 | W1: 2020-06-30 | X1: 2020-09-30 | Y1: 2020-12-31 | Z1: 2021-03-31 | AA1: 2021-06-30 | AB1: 2021-09-30 | AC1: 2021-12-31 | AD1: 2022-03-31 | AE1: 2022-06-30 | AF1: 2022-09-30 | AG1: 2022-12-31 | AH1: 2023-03-31 | AI1: 2023-06-30 | AJ1: 2023-09-30 | AK1: 2023-12-31 | AL1: 2024-03-31 | AM1: 2024-06-30 | AN1: 2024-09-30 | AO1: 2024-12-31 | AP1: 2025-03-31 | AQ1: 2025-06-30
A2: Cash & other liquid securities | D2: =_xlfn.NUMBERVALUE(advaltech_bs!D12)+_xlfn.NUMBERVALUE(advaltech_bs!D13) | E2: =_xlfn.NUMBERVALUE(advaltech_bs!E12)+_xlfn.NUMBERVALUE(advaltech_bs!E13) | F2: =_xlfn.NUMBERVALUE(advaltech_bs!F12)+_xlfn.NUMBERVALUE(advaltech_bs!F13) | G2: =_xlfn.NUMBERVALUE(advaltech_bs!G12)+_xlfn.NUMBERVALUE(advaltech_bs!G13) | H2: =_xlfn.NUMBERVALUE(advaltech_bs!H12)+_xlfn.NUMBERVALUE(advaltech_bs!H13) | I2: =_xlfn.NUMBERVALUE(advaltech_bs!I12)+_xlfn.NUMBERVALUE(advaltech_bs!I13) | J2: =_xlfn.NUMBERVALUE(advaltech_bs!J12)+_xlfn.NUMBERVALUE(advaltech_bs!J13) | K2: =_xlfn.NUMBERVALUE(advaltech_bs!K12)+_xlfn.NUMBERVALUE(advaltech_bs!K13) | ... AQ2: =_xlfn.NUMBERVALUE(advaltech_bs!AQ12)+_xlfn.NUMBERVALUE(advaltech_bs!AQ13)
A3: AR | C3: 0.8 | D3: =_xlfn.NUMBERVALUE(advaltech_bs!D14) | E3: =_xlfn.NUMBERVALUE(advaltech_bs!E14) | F3: =_xlfn.NUMBERVALUE(advaltech_bs!F14) | G3: =_xlfn.NUMBERVALUE(advaltech_bs!G14) | H3: =_xlfn.NUMBERVALUE(advaltech_bs!H14) | I3: =_xlfn.NUMBERVALUE(advaltech_bs!I14) | J3: =_xlfn.NUMBERVALUE(advaltech_bs!J14) | K3: =_xlfn.NUMBERVALUE(advaltech_bs!K14) | ... AQ3: =_xlfn.NUMBERVALUE(advaltech_bs!AQ14)
A4: Inventory | C4: 0.6 | D4: =_xlfn.NUMBERVALUE(advaltech_bs!D15) | E4: =_xlfn.NUMBERVALUE(advaltech_bs!E15) | F4: =_xlfn.NUMBERVALUE(advaltech_bs!F15) | G4: =_xlfn.NUMBERVALUE(advaltech_bs!G15) | H4: =_xlfn.NUMBERVALUE(advaltech_bs!H15) | I4: =_xlfn.NUMBERVALUE(advaltech_bs!I15) | J4: =_xlfn.NUMBERVALUE(advaltech_bs!J15) | K4: =_xlfn.NUMBERVALUE(advaltech_bs!K15) | ... AQ4: =_xlfn.NUMBERVALUE(advaltech_bs!AQ15)
A5: Current Assets | D5: =_xlfn.NUMBERVALUE(advaltech_bs!D18) | E5: =_xlfn.NUMBERVALUE(advaltech_bs!E18) | F5: =_xlfn.NUMBERVALUE(advaltech_bs!F18) | G5: =_xlfn.NUMBERVALUE(advaltech_bs!G18) | H5: =_xlfn.NUMBERVALUE(advaltech_bs!H18) | I5: =_xlfn.NUMBERVALUE(advaltech_bs!I18) | J5: =_xlfn.NUMBERVALUE(advaltech_bs!J18) | K5: =_xlfn.NUMBERVALUE(advaltech_bs!K18) | ... AQ5: =_xlfn.NUMBERVALUE(advaltech_bs!AQ18)
A6: Discounted CA | D6: =D3*$C$3+$C$4*D4+D2 | E6: =E3*$C$3+$C$4*E4+E2 | F6: =F3*$C$3+$C$4*F4+F2 | G6: =G3*$C$3+$C$4*G4+G2 | H6: =H3*$C$3+$C$4*H4+H2 | I6: =I3*$C$3+$C$4*I4+I2 | J6: =J3*$C$3+$C$4*J4+J2 | K6: =K3*$C$3+$C$4*K4+K2 | ... AQ6: =AQ3*$C$3+$C$4*AQ4+AQ2
A9: Total Assets | D9: =_xlfn.NUMBERVALUE(advaltech_bs!D27) | E9: =_xlfn.NUMBERVALUE(advaltech_bs!E27) | F9: =_xlfn.NUMBERVALUE(advaltech_bs!F27) | G9: =_xlfn.NUMBERVALUE(advaltech_bs!G27) | H9: =_xlfn.NUMBERVALUE(advaltech_bs!H27) | I9: =_xlfn.NUMBERVALUE(advaltech_bs!I27) | J9: =_xlfn.NUMBERVALUE(advaltech_bs!J27) | K9: =_xlfn.NUMBERVALUE(advaltech_bs!K27) | ... AQ9: =_xlfn.NUMBERVALUE(advaltech_bs!AQ27)
A10: Intangible Assets | D10: =_xlfn.NUMBERVALUE(SUM(advaltech_bs!D24:D25)) | E10: =_xlfn.NUMBERVALUE(SUM(advaltech_bs!E24:E25)) | F10: =_xlfn.NUMBERVALUE(SUM(advaltech_bs!F24:F25)) | G10: =_xlfn.NUMBERVALUE(SUM(advaltech_bs!G24:G25)) | H10: =_xlfn.NUMBERVALUE(SUM(advaltech_bs!H24:H25)) | I10: =_xlfn.NUMBERVALUE(SUM(advaltech_bs!I24:I25)) | J10: =_xlfn.NUMBERVALUE(SUM(advaltech_bs!J24:J25)) | K10: =_xlfn.NUMBERVALUE(SUM(advaltech_bs!K24:K25)) | ... AQ10: =_xlfn.NUMBERVALUE(SUM(advaltech_bs!AQ24:AQ25))
A12: Current Liabilities | D12: =_xlfn.NUMBERVALUE(advaltech_bs!D35) | E12: =_xlfn.NUMBERVALUE(advaltech_bs!E35) | F12: =_xlfn.NUMBERVALUE(advaltech_bs!F35) | G12: =_xlfn.NUMBERVALUE(advaltech_bs!G35) | H12: =_xlfn.NUMBERVALUE(advaltech_bs!H35) | I12: =_xlfn.NUMBERVALUE(advaltech_bs!I35) | J12: =_xlfn.NUMBERVALUE(advaltech_bs!J35) | K12: =_xlfn.NUMBERVALUE(advaltech_bs!K35) | ... AQ12: =_xlfn.NUMBERVALUE(advaltech_bs!AQ35)
A13: Total Liabilities | D13: =_xlfn.NUMBERVALUE(advaltech_bs!D40) | E13: =_xlfn.NUMBERVALUE(advaltech_bs!E40) | F13: =_xlfn.NUMBERVALUE(advaltech_bs!F40) | G13: =_xlfn.NUMBERVALUE(advaltech_bs!G40) | H13: =_xlfn.NUMBERVALUE(advaltech_bs!H40) | I13: =_xlfn.NUMBERVALUE(advaltech_bs!I40) | J13: =_xlfn.NUMBERVALUE(advaltech_bs!J40) | K13: =_xlfn.NUMBERVALUE(advaltech_bs!K40) | ... AQ13: =_xlfn.NUMBERVALUE(advaltech_bs!AQ40)
A15: Debt | D15: =_xlfn.NUMBERVALUE(advaltech_bs!D32)+_xlfn.NUMBERVALUE(advaltech_bs!D37)+_xlfn.NUMBERVALUE(advaltech_bs!D31) | E15: =_xlfn.NUMBERVALUE(advaltech_bs!E32)+_xlfn.NUMBERVALUE(advaltech_bs!E37)+_xlfn.NUMBERVALUE(advaltech_bs!E31) | F15: =_xlfn.NUMBERVALUE(advaltech_bs!F32)+_xlfn.NUMBERVALUE(advaltech_bs!F37)+_xlfn.NUMBERVALUE(advaltech_bs!F31) | G15: =_xlfn.NUMBERVALUE(advaltech_bs!G32)+_xlfn.NUMBERVALUE(advaltech_bs!G37)+_xlfn.NUMBERVALUE(advaltech_bs!G31) | H15: =_xlfn.NUMBERVALUE(advaltech_bs!H32)+_xlfn.NUMBERVALUE(advaltech_bs!H37)+_xlfn.NUMBERVALUE(advaltech_bs!H31) | I15: =_xlfn.NUMBERVALUE(advaltech_bs!I32)+_xlfn.NUMBERVALUE(advaltech_bs!I37)+_xlfn.NUMBERVALUE(advaltech_bs!I31) | J15: =_xlfn.NUMBERVALUE(advaltech_bs!J32)+_xlfn.NUMBERVALUE(advaltech_bs!J37)+_xlfn.NUMBERVALUE(advaltech_bs!J31) | K15: =_xlfn.NUMBERVALUE(advaltech_bs!K32)+_xlfn.NUMBERVALUE(advaltech_bs!K37)+_xlfn.NUMBERVALUE(advaltech_bs!K31) | ... AQ15: =_xlfn.NUMBERVALUE(advaltech_bs!AQ32)+_xlfn.NUMBERVALUE(advaltech_bs!AQ37)+_xlfn.NUMBERVALUE(advaltech_bs!AQ31)
A16: Equity | D16: =_xlfn.NUMBERVALUE(advaltech_bs!D51) | E16: =_xlfn.NUMBERVALUE(advaltech_bs!E51) | F16: =_xlfn.NUMBERVALUE(advaltech_bs!F51) | G16: =_xlfn.NUMBERVALUE(advaltech_bs!G51) | H16: =_xlfn.NUMBERVALUE(advaltech_bs!H51) | I16: =_xlfn.NUMBERVALUE(advaltech_bs!I51) | J16: =_xlfn.NUMBERVALUE(advaltech_bs!J51) | K16: =_xlfn.NUMBERVALUE(advaltech_bs!K51) | ... AQ16: =_xlfn.NUMBERVALUE(advaltech_bs!AQ51)
A18: Net Tangible Assets | D18: =D9-D10-D13 | E18: =E9-E10-E13 | F18: =F9-F10-F13 | G18: =G9-G10-G13 | H18: =H9-H10-H13 | I18: =I9-I10-I13 | J18: =J9-J10-J13 | K18: =K9-K10-K13 | ... AQ18: =AQ9-AQ10-AQ13
A20: Shares Outstanding | D20: =_xlfn.NUMBERVALUE(advaltech_IS!D41) | E20: =_xlfn.NUMBERVALUE(advaltech_IS!E41) | F20: =_xlfn.NUMBERVALUE(advaltech_IS!F41) | G20: =_xlfn.NUMBERVALUE(advaltech_IS!G41) | H20: =_xlfn.NUMBERVALUE(advaltech_IS!H41) | I20: =_xlfn.NUMBERVALUE(advaltech_IS!I41) | J20: =_xlfn.NUMBERVALUE(advaltech_IS!J41) | K20: =_xlfn.NUMBERVALUE(advaltech_IS!K41) | ... AQ20: =_xlfn.NUMBERVALUE(advaltech_IS!AQ41)
A22: Net Cash | D22: =IF(D2-D13>0,D2-D13, "NA") | E22: =IF(E2-E13>0,E2-E13, "NA") | F22: =IF(F2-F13>0,F2-F13, "NA") | G22: =IF(G2-G13>0,G2-G13, "NA") | H22: =IF(H2-H13>0,H2-H13, "NA") | I22: =IF(I2-I13>0,I2-I13, "NA") | J22: =IF(J2-J13>0,J2-J13, "NA") | K22: =IF(K2-K13>0,K2-K13, "NA") | ... AQ22: =IF(AQ2-AQ13>0,AQ2-AQ13, "NA")
A23: Net Current Assets | D23: =D5-D13 | E23: =E5-E13 | F23: =F5-F13 | G23: =G5-G13 | H23: =H5-H13 | I23: =I5-I13 | J23: =J5-J13 | K23: =K5-K13 | ... AQ23: =AQ5-AQ13
A24: Discounted Net Current Assets | D24: =D6-D13 | E24: =E6-E13 | F24: =F6-F13 | G24: =G6-G13 | H24: =H6-H13 | I24: =I6-I13 | J24: =J6-J13 | K24: =K6-K13 | ... AQ24: =AQ6-AQ13
A26: Current Ratio | D26: =D5/D12 | E26: =E5/E12 | F26: =F5/F12 | G26: =G5/G12 | H26: =H5/H12 | I26: =I5/I12 | J26: =J5/J12 | K26: =K5/K12 | ... AQ26: =AQ5/AQ12
A27: 4 period ma | D27: =AVERAGE(D26:D26) | E27: =AVERAGE(D26:E26) | F27: =AVERAGE(D26:F26) | G27: =AVERAGE(D26:G26) | H27: =AVERAGE(E26:H26) | I27: =AVERAGE(F26:I26) | J27: =AVERAGE(G26:J26) | K27: =AVERAGE(H26:K26) | L27: =AVERAGE(I26:L26) | M27: =AVERAGE(J26:M26) | N27: =AVERAGE(K26:N26) | ... AQ27: =AVERAGE(AN26:AQ26)
A29: Net Tangible Assets / Share | D29: =D18/D20 | E29: =E18/E20 | F29: =F18/F20 | G29: =G18/G20 | H29: =H18/H20 | I29: =I18/I20 | J29: =J18/J20 | K29: =K18/K20 | ... AQ29: =AQ18/AQ20
B30: % QoQ | E30: =E29/D29-1 | F30: =F29/E29-1 | G30: =G29/F29-1 | H30: =H29/G29-1 | I30: =I29/H29-1 | J30: =J29/I29-1 | K30: =K29/J29-1 | L30: =L29/K29-1 | ... W30: =W29/V29-1 | X30: =X29/V29-1 | Y30: =Y29/V29-1 | Z30: =Z29/V29-1 | AA30: =AA29/V29-1 | AB30: =AB29/V29-1 | AC30: =AC29/V29-1 | AD30: =AD29/V29-1 | AE30: =AE29/V29-1 | AF30: =AF29/V29-1 | AG30: =AG29/V29-1 | AH30: =AH29/V29-1 | AI30: =AI29/V29-1 | AJ30: =AJ29/V29-1 | AK30: =AK29/V29-1 | AL30: =AL29/V29-1 | AM30: =AM29/V29-1 | AN30: =AN29/V29-1 | AO30: =AO29/V29-1 | AP30: =AP29/V29-1 | AQ30: =AQ29/V29-1
B31: % YoY | G31: =G29/D29-1 | H31: =H29/E29-1 | I31: =I29/F29-1 | J31: =J29/G29-1 | K31: =K29/H29-1 | L31: =L29/I29-1 | M31: =M29/J29-1 | N31: =N29/K29-1 | ... W31: =W29/T29-1
A34: NCAV / Share | D34: =D23/D20 | E34: =E23/E20 | F34: =F23/F20 | G34: =G23/G20 | H34: =H23/H20 | I34: =I23/I20 | J34: =J23/J20 | K34: =K23/K20 | ... AQ34: =AQ23/AQ20
B35: % QoQ | E35: =E34/D34-1 | F35: =F34/E34-1 | G35: =G34/F34-1 | H35: =H34/G34-1 | I35: =I34/H34-1 | J35: =J34/I34-1 | K35: =K34/J34-1 | L35: =L34/K34-1 | ... AQ35: =AQ34/AP34-1
B36: % YoY | H36: =H34/D34-1 | I36: =I34/E34-1 | J36: =J34/F34-1 | K36: =K34/G34-1 | L36: =L34/H34-1 | M36: =M34/I34-1 | N36: =N34/J34-1 | O36: =O34/K34-1 | ... AQ36: =AQ34/AM34-1
A38: Discounted NCAV / Share | D38: =D24/D20 | E38: =E24/E20 | F38: =F24/F20 | G38: =G24/G20 | H38: =H24/H20 | I38: =I24/I20 | J38: =J24/J20 | K38: =K24/K20 | ... AQ38: =AQ24/AQ20
A41: Net Cash / Share | D41: =IFERROR(D22/D20, "NA") | E41: =IFERROR(E22/E20, "NA") | F41: =IFERROR(F22/F20, "NA") | G41: =IFERROR(G22/G20, "NA") | H41: =IFERROR(H22/H20, "NA") | I41: =IFERROR(I22/I20, "NA") | J41: =IFERROR(J22/J20, "NA") | K41: =IFERROR(K22/K20, "NA") | ... AQ41: =IFERROR(AQ22/AQ20, "NA")
B42: % QoQ | D42: =IFERROR(D41/#REF!-1, "NA") | E42: =IFERROR(E41/D41-1, "NA") | F42: =IFERROR(F41/E41-1, "NA") | G42: =IFERROR(G41/F41-1, "NA") | H42: =IFERROR(H41/G41-1, "NA") | I42: =IFERROR(I41/H41-1, "NA") | J42: =IFERROR(J41/I41-1, "NA") | K42: =IFERROR(K41/J41-1, "NA") | L42: =IFERROR(L41/K41-1, "NA") | ... AQ42: =IFERROR(AQ41/AP41-1, "NA")
A45: Price | AQ45: 5.1 | AR45: Buy below: | AS45: =W34*AS46
A46: P / NCAV | AQ46: =AQ45/AQ34 | AS46: 0.667
A47: P / Discounted NCAV | AQ47: =AQ45/AQ38
A48: P / NTA | AQ48: =AQ45/AQ29
A49: P / Net Cash | AQ49: =IFERROR(AQ45/AQ41, "NA")
A52: D / Assets | D52: =D15/D9 | E52: =E15/E9 | F52: =F15/F9 | G52: =G15/G9 | H52: =H15/H9 | I52: =I15/I9 | J52: =J15/J9 | K52: =K15/K9 | ... AQ52: =AQ15/AQ9
A53: D / E | D53: =D15/D16 | E53: =E15/E16 | F53: =F15/F16 | G53: =G15/G16 | H53: =H15/H16 | I53: =I15/I16 | J53: =J15/J16 | K53: =K15/K16 | ... AQ53: =AQ15/AQ16
A54: Total Liabilities / Equity | D54: =D13/D16 | E54: =E13/E16 | F54: =F13/F16 | G54: =G13/G16 | H54: =H13/H16 | I54: =I13/I16 | J54: =J13/J16 | K54: =K13/K16 | ... AQ54: =AQ13/AQ16

Sheet profitability
C1: 2015-09-30 | D1: 2015-12-31 | E1: 2016-03-31 | F1: 2016-06-30 | G1: 2016-09-30 | H1: 2016-12-31 | I1: 2017-03-31 | J1: 2017-06-30 | K1: 2017-09-30 | L1: 2017-12-31 | M1: 2018-03-31 | N1: 2018-06-30 | O1: 2018-09-30 | P1: 2018-12-31 | Q1: 2019-03-31 | R1: 2019-06-30 | S1: 2019-09-30 | T1: 2019-12-31 | U1: 2020-03-31 | V1: 2020-06-30 | W1: 2020-09-30 | X1: 2020-12-31 | Y1: 2021-03-31 | Z1: 2021-06-30 | AA1: 2021-09-30 | AB1: 2021-12-31 | AC1: 2022-03-31 | AD1: 2022-06-30 | AE1: 2022-09-30 | AF1: 2022-12-31 | AG1: 2023-03-31 | AH1: 2023-06-30 | AI1: 2023-09-30 | AJ1: 2023-12-31 | AK1: 2024-03-31 | AL1: 2024-06-30 | AM1: 2024-09-30 | AN1: 2024-12-31 | AO1: 2025-03-31 | AP1: 2025-06-30
A2: Sales | C2: =_xlfn.NUMBERVALUE(advaltech_IS!D12) | D2: =_xlfn.NUMBERVALUE(advaltech_IS!E12) | E2: =_xlfn.NUMBERVALUE(advaltech_IS!F12) | F2: =_xlfn.NUMBERVALUE(advaltech_IS!G12) | G2: =_xlfn.NUMBERVALUE(advaltech_IS!H12) | H2: =_xlfn.NUMBERVALUE(advaltech_IS!I12) | I2: =_xlfn.NUMBERVALUE(advaltech_IS!J12) | J2: =_xlfn.NUMBERVALUE(advaltech_IS!K12) | ... AP2: =_xlfn.NUMBERVALUE(advaltech_IS!AQ12)
B3: % QoQ | D3: =D2/C2-1 | E3: =E2/D2-1 | F3: =F2/E2-1 | G3: =G2/F2-1 | H3: =H2/G2-1 | I3: =I2/H2-1 | J3: =J2/I2-1 | K3: =K2/J2-1 | ... V3: =V2/U2-1 | W3: =W2/U2-1 | X3: =X2/U2-1 | Y3: =Y2/U2-1 | Z3: =Z2/U2-1 | AA3: =AA2/U2-1 | AB3: =AB2/U2-1 | AC3: =AC2/U2-1 | AD3: =AD2/U2-1 | AE3: =AE2/U2-1 | AF3: =AF2/U2-1 | AG3: =AG2/U2-1 | AH3: =AH2/U2-1 | AI3: =AI2/U2-1 | AJ3: =AJ2/U2-1 | AK3: =AK2/U2-1 | AL3: =AL2/U2-1 | AM3: =AM2/U2-1 | AN3: =AN2/U2-1 | AO3: =AO2/U2-1 | AP3: =AP2/U2-1
B4: % YoY | G4: =G2/C2-1 | H4: =H2/D2-1 | I4: =I2/E2-1 | J4: =J2/F2-1 | K4: =K2/G2-1 | L4: =L2/H2-1 | M4: =M2/I2-1 | N4: =N2/J2-1 | ... V4: =V2/R2-1 | W4: =W2/R2-1 | X4: =X2/R2-1 | Y4: =Y2/R2-1 | Z4: =Z2/R2-1 | AA4: =AA2/R2-1 | AB4: =AB2/R2-1 | AC4: =AC2/R2-1 | AD4: =AD2/R2-1 | AE4: =AE2/R2-1 | AF4: =AF2/R2-1 | AG4: =AG2/R2-1 | AH4: =AH2/R2-1 | AI4: =AI2/R2-1 | AJ4: =AJ2/R2-1 | AK4: =AK2/R2-1 | AL4: =AL2/R2-1 | AM4: =AM2/R2-1 | AN4: =AN2/R2-1 | AO4: =AO2/R2-1 | AP4: =AP2/R2-1
A6: Gross Income | C6: =_xlfn.NUMBERVALUE(advaltech_IS!D16) | D6: =_xlfn.NUMBERVALUE(advaltech_IS!E16) | E6: =_xlfn.NUMBERVALUE(advaltech_IS!F16) | F6: =_xlfn.NUMBERVALUE(advaltech_IS!G16) | G6: =_xlfn.NUMBERVALUE(advaltech_IS!H16) | H6: =_xlfn.NUMBERVALUE(advaltech_IS!I16) | I6: =_xlfn.NUMBERVALUE(advaltech_IS!J16) | J6: =_xlfn.NUMBERVALUE(advaltech_IS!K16) | ... V6: =_xlfn.NUMBERVALUE(advaltech_IS!W16) | W6: =_xlfn.NUMBERVALUE(advaltech_IS!W16) | X6: =_xlfn.NUMBERVALUE(advaltech_IS!X16) | Y6: =_xlfn.NUMBERVALUE(advaltech_IS!Y16) | Z6: =_xlfn.NUMBERVALUE(advaltech_IS!Z16) | AA6: =_xlfn.NUMBERVALUE(advaltech_IS!AA16) | AB6: =_xlfn.NUMBERVALUE(advaltech_IS!AB16) | AC6: =_xlfn.NUMBERVALUE(advaltech_IS!AC16) | AD6: =_xlfn.NUMBERVALUE(advaltech_IS!AD16) | ... AP6: =_xlfn.NUMBERVALUE(advaltech_IS!AP16)
B7: % Margin | C7: =C6/C2 | D7: =D6/D2 | E7: =E6/E2 | F7: =F6/F2 | G7: =G6/G2 | H7: =H6/H2 | I7: =I6/I2 | J7: =J6/J2 | ... AP7: =AP6/AP2
B8: % Margin 4 per MA | C8: =AVERAGE(C7:C7) | D8: =AVERAGE(C7:D7) | E8: =AVERAGE(C7:E7) | F8: =AVERAGE(C7:F7) | G8: =AVERAGE(D7:G7) | H8: =AVERAGE(E7:H7) | I8: =AVERAGE(F7:I7) | J8: =AVERAGE(G7:J7) | K8: =AVERAGE(H7:K7) | L8: =AVERAGE(I7:L7) | M8: =AVERAGE(J7:M7) | ... V8: =AVERAGE(S7:V7) | W8: =AVERAGE(S7:W7) | X8: =AVERAGE(S7:X7) | Y8: =AVERAGE(S7:Y7) | Z8: =AVERAGE(S7:Z7) | AA8: =AVERAGE(S7:AA7) | AB8: =AVERAGE(S7:AB7) | AC8: =AVERAGE(S7:AC7) | AD8: =AVERAGE(S7:AD7) | AE8: =AVERAGE(S7:AE7) | AF8: =AVERAGE(S7:AF7) | AG8: =AVERAGE(S7:AG7) | AH8: =AVERAGE(S7:AH7) | AI8: =AVERAGE(S7:AI7) | AJ8: =AVERAGE(S7:AJ7) | AK8: =AVERAGE(S7:AK7) | AL8: =AVERAGE(S7:AL7) | AM8: =AVERAGE(S7:AM7) | AN8: =AVERAGE(S7:AN7) | AO8: =AVERAGE(S7:AO7) | AP8: =AVERAGE(S7:AP7)
A10: Net Income | C10: =_xlfn.NUMBERVALUE(advaltech_IS!D32) | D10: =_xlfn.NUMBERVALUE(advaltech_IS!E32) | E10: =_xlfn.NUMBERVALUE(advaltech_IS!F32) | F10: =_xlfn.NUMBERVALUE(advaltech_IS!G32) | G10: =_xlfn.NUMBERVALUE(advaltech_IS!H32) | H10: =_xlfn.NUMBERVALUE(advaltech_IS!I32) | I10: =_xlfn.NUMBERVALUE(advaltech_IS!J32) | J10: =_xlfn.NUMBERVALUE(advaltech_IS!K32) | ... V10: =_xlfn.NUMBERVALUE(advaltech_IS!W32) | W10: =_xlfn.NUMBERVALUE(advaltech_IS!W32) | X10: =_xlfn.NUMBERVALUE(advaltech_IS!X32) | Y10: =_xlfn.NUMBERVALUE(advaltech_IS!Y32) | Z10: =_xlfn.NUMBERVALUE(advaltech_IS!Z32) | AA10: =_xlfn.NUMBERVALUE(advaltech_IS!AA32) | AB10: =_xlfn.NUMBERVALUE(advaltech_IS!AB32) | AC10: =_xlfn.NUMBERVALUE(advaltech_IS!AC32) | AD10: =_xlfn.NUMBERVALUE(advaltech_IS!AD33) | AE10: =_xlfn.NUMBERVALUE(advaltech_IS!AE33) | AF10: =_xlfn.NUMBERVALUE(advaltech_IS!AF33) | AG10: =_xlfn.NUMBERVALUE(advaltech_IS!AG33) | AH10: =_xlfn.NUMBERVALUE(advaltech_IS!AH33) | AI10: =_xlfn.NUMBERVALUE(advaltech_IS!AI33) | AJ10: =_xlfn.NUMBERVALUE(advaltech_IS!AJ33) | AK10: =_xlfn.NUMBERVALUE(advaltech_IS!AK33) | ... AP10: =_xlfn.NUMBERVALUE(advaltech_IS!AP33)
B11: % Margin | C11: =C10/C2 | D11: =D10/D2 | E11: =E10/E2 | F11: =F10/F2 | G11: =G10/G2 | H11: =H10/H2 | I11: =I10/I2 | J11: =J10/J2 | ... AP11: =AP10/AP2

Sheet piotrosky
A1: 1 | B1: Positive earnings | K1: 1 | L1: AUTO: NI = -91 (negative/zero)
A2: =A1+1 | B2: Positive CF | K2: 1 | L2: MANUAL: OCF data not available in standard export
A3: =A2+1 | B3: Increasing ROA | K3: 0 | L3: AUTO: ROA: 0.54% -> 1.92% (↑)
A4: =A3+1 | B4: Increasing CFO | K4: 0 | L4: MANUAL: OCF data not available for accruals check
A5: =A4+1 | B5: Decreasing long term debt as a proportion of total assets | K5: 1 | L5: AUTO: D/A: 1.56% -> 1.39% (↓)
A6: =A5+1 | B6: increasing current ratio | K6: 1 | L6: AUTO: CR: 7.11x -> 6.55x (↓)
A7: =A6+1 | B7: decreasing or stable numbers of standing shares | K7: 1 | L7: AUTO: Shares: 7 -> 7 (stable/↓)
A8: =A7+1 | B8: increasing assets turnover (increasing sales as a proportion of total assets) | K8: 0 | L8: AUTO: AT: 0.68x -> 0.60x (↓)
A9: =A8+1 | B9: increasing gross margin | K9: 1 | L9: AUTO: GM: 39.6% -> 41.0% (↑)
A10: Piotrosky score | K10: =SUM(K1:K9) | L10: =SUM(L1:L9) | M10: =SUM(M1:M9) | N10: =SUM(N1:N9) | O10: =SUM(O1:O9) | P10: =SUM(P1:P9) | Q10: =SUM(Q1:Q9) | R10: =SUM(R1:R9) | ... AQ10: =SUM(AQ1:AQ9)

Sheet C7
A1: Core 9 Criteria
A2: Not Majority Chinese | H2: 1 | I2: MANUAL: Check company domicile manually
A3: Low Price-to-NACV (less than 67%) | H3: 1 | I3: AUTO: P/NCAV = 0.97 (threshold: 0.67)
A4: Low Debt-to-Equity | H4: 1 | I4: AUTO: D/E = 0.02 (threshold: 0.5)
A5: Adequate Past Earnings or Catalyst (5%+ NI Margin) | H5: 1 | I5: AUTO: Max NI margin = 11.7% (threshold: 5%)
A6: Past Price Above NCAV | H6: 1 | I6: MANUAL: Requires historical price data
A7: Existing Operations or Liquidation | H7: 1 | I7: MANUAL: Qualitative assessment required
A8: Not Selling Shares | H8: 1 | I8: AUTO: Shares: 7 -> 7
A9: Market Cap <$50mm | H9: 1 | I9: MANUAL: Market cap = 10,650 (currency/unit check needed)
A10: Low NCAV Burn Rate | H10: 1 | I10: AUTO: Calculated NCAV YoY: -5.9%
A11: Total | H11: =SUM(H2:H10) | I11: =SUM(I2:I10) | J11: =SUM(J2:J10) | K11: =SUM(K2:K10) | L11: =SUM(L2:L10) | M11: =SUM(M2:M10) | N11: =SUM(N2:N10) | O11: =SUM(O2:O10) | ... AQ11: =SUM(AQ2:AQ10)
A13: Ranking Criteria (out of 9)
A14: Large Current Ratio (over 1.5x) | H14: 1 | I14: AUTO: CR = 6.55x (threshold: 1.5x)
A15: Not financial/real estate/closed end fund | H15: 1 | I15: MANUAL: Check industry classification manually
A16: Company is buying back stock | H16: 0 | I16: AUTO: Shares: 7 -> 7 (no buyback)
A17: Low Price-to-Net Cash | H17: 1 | I17: MANUAL: Net cash calculation requires manual review
A18: Insider Ownership | H18: 1 | I18: MANUAL: Check ownership sheet manually
A19: Insider Buys vs. Sells | H19: 0 | I19: MANUAL: Requires insider transaction data
A20: Burn Rate Low or Positive | H20: 1 | I20: AUTO: NCAV YoY: -5.9%
A21: Insider Pay | H21: 1 | I21: MANUAL: Qualitative assessment required
A22: Dividend Yield? | H22: 1 | I22: MANUAL: Requires dividend and price data
A23: Total | H23: =SUM(H14:H22)

Sheet ro
C1: 2015-09-30 | D1: 2015-12-31 | E1: 2016-03-31 | F1: 2016-06-30 | G1: 2016-09-30 | H1: 2016-12-31 | I1: 2017-03-31 | J1: 2017-06-30 | K1: 2017-09-30 | L1: 2017-12-31 | M1: 2018-03-31 | N1: 2018-06-30 | O1: 2018-09-30 | P1: 2018-12-31 | Q1: 2019-03-31 | R1: 2019-06-30 | S1: 2019-09-30 | T1: 2019-12-31 | U1: 2020-03-31 | V1: 2020-06-30 | W1: 2020-09-30 | X1: 2020-12-31 | Y1: 2021-03-31 | Z1: 2021-06-30 | AA1: 2021-09-30 | AB1: 2021-12-31 | AC1: 2022-03-31 | AD1: 2022-06-30 | AE1: 2022-09-30 | AF1: 2022-12-31 | AG1: 2023-03-31 | AH1: 2023-06-30 | AI1: 2023-09-30 | AJ1: 2023-12-31 | AK1: 2024-03-31 | AL1: 2024-06-30 | AM1: 2024-09-30 | AN1: 2024-12-31 | AO1: 2025-03-31 | AP1: 2025-06-30
A2: Total Assets | C2: =_xlfn.NUMBERVALUE(advaltech_bs!D27) | D2: =_xlfn.NUMBERVALUE(advaltech_bs!E27) | E2: =_xlfn.NUMBERVALUE(advaltech_bs!F27) | F2: =_xlfn.NUMBERVALUE(advaltech_bs!G27) | G2: =_xlfn.NUMBERVALUE(advaltech_bs!H27) | H2: =_xlfn.NUMBERVALUE(advaltech_bs!I27) | I2: =_xlfn.NUMBERVALUE(advaltech_bs!J27) | J2: =_xlfn.NUMBERVALUE(advaltech_bs!K27) | ... V2: =_xlfn.NUMBERVALUE(advaltech_bs!W27) | W2: =_xlfn.NUMBERVALUE(advaltech_bs!W27) | X2: =_xlfn.NUMBERVALUE(advaltech_bs!X27) | Y2: =_xlfn.NUMBERVALUE(advaltech_bs!Y27) | Z2: =_xlfn.NUMBERVALUE(advaltech_bs!Z27) | AA2: =_xlfn.NUMBERVALUE(advaltech_bs!AA27) | AB2: =_xlfn.NUMBERVALUE(advaltech_bs!AB27) | AC2: =_xlfn.NUMBERVALUE(advaltech_bs!AC27) | AD2: =_xlfn.NUMBERVALUE(advaltech_bs!AD27) | ... AP2: =_xlfn.NUMBERVALUE(advaltech_bs!AP27)
A3: 1 yr avg | D3: =AVERAGE(C2:D2) | E3: =AVERAGE(D2:E2) | F3: =AVERAGE(E2:F2) | G3: =AVERAGE(F2:G2) | H3: =AVERAGE(G2:H2) | I3: =AVERAGE(H2:I2) | J3: =AVERAGE(I2:J2) | K3: =AVERAGE(J2:K2) | ... V3: =AVERAGE(U2:V2) | W3: =AVERAGE(U2:W2) | X3: =AVERAGE(U2:X2) | Y3: =AVERAGE(U2:Y2) | Z3: =AVERAGE(U2:Z2) | AA3: =AVERAGE(U2:AA2) | AB3: =AVERAGE(U2:AB2) | AC3: =AVERAGE(U2:AC2) | AD3: =AVERAGE(U2:AD2) | AE3: =AVERAGE(U2:AE2) | AF3: =AVERAGE(U2:AF2) | AG3: =AVERAGE(U2:AG2) | AH3: =AVERAGE(U2:AH2) | AI3: =AVERAGE(U2:AI2) | AJ3: =AVERAGE(U2:AJ2) | AK3: =AVERAGE(U2:AK2) | AL3: =AVERAGE(U2:AL2) | AM3: =AVERAGE(U2:AM2) | AN3: =AVERAGE(U2:AN2) | AO3: =AVERAGE(U2:AO2) | AP3: =AVERAGE(U2:AP2)
A5: Total Equity | C5: =_xlfn.NUMBERVALUE(advaltech_bs!D51) | D5: =_xlfn.NUMBERVALUE(advaltech_bs!E51) | E5: =_xlfn.NUMBERVALUE(advaltech_bs!F51) | F5: =_xlfn.NUMBERVALUE(advaltech_bs!G51) | G5: =_xlfn.NUMBERVALUE(advaltech_bs!H51) | H5: =_xlfn.NUMBERVALUE(advaltech_bs!I51) | I5: =_xlfn.NUMBERVALUE(advaltech_bs!J51) | J5: =_xlfn.NUMBERVALUE(advaltech_bs!K51) | ... V5: =_xlfn.NUMBERVALUE(advaltech_bs!W51) | W5: =_xlfn.NUMBERVALUE(advaltech_bs!W51) | X5: =_xlfn.NUMBERVALUE(advaltech_bs!X51) | Y5: =_xlfn.NUMBERVALUE(advaltech_bs!Y51) | Z5: =_xlfn.NUMBERVALUE(advaltech_bs!Z51) | AA5: =_xlfn.NUMBERVALUE(advaltech_bs!AA51) | AB5: =_xlfn.NUMBERVALUE(advaltech_bs!AB51) | AC5: =_xlfn.NUMBERVALUE(advaltech_bs!AC51) | AD5: =_xlfn.NUMBERVALUE(advaltech_bs!AD51) | ... AP5: =_xlfn.NUMBERVALUE(advaltech_bs!AP51)
A6: 1 yr avg | D6: =AVERAGE(C5:D5) | E6: =AVERAGE(D5:E5) | F6: =AVERAGE(E5:F5) | G6: =AVERAGE(F5:G5) | H6: =AVERAGE(G5:H5) | I6: =AVERAGE(H5:I5) | J6: =AVERAGE(I5:J5) | K6: =AVERAGE(J5:K5) | ... V6: =AVERAGE(U5:V5) | W6: =AVERAGE(U5:W5) | X6: =AVERAGE(U5:X5) | Y6: =AVERAGE(U5:Y5) | Z6: =AVERAGE(U5:Z5) | AA6: =AVERAGE(U5:AA5) | AB6: =AVERAGE(U5:AB5) | AC6: =AVERAGE(U5:AC5) | AD6: =AVERAGE(U5:AD5) | AE6: =AVERAGE(U5:AE5) | AF6: =AVERAGE(U5:AF5) | AG6: =AVERAGE(U5:AG5) | AH6: =AVERAGE(U5:AH5) | AI6: =AVERAGE(U5:AI5) | AJ6: =AVERAGE(U5:AJ5) | AK6: =AVERAGE(U5:AK5) | AL6: =AVERAGE(U5:AL5) | AM6: =AVERAGE(U5:AM5) | AN6: =AVERAGE(U5:AN5) | AO6: =AVERAGE(U5:AO5) | AP6: =AVERAGE(U5:AP5)
A8: Sales | C8: =_xlfn.NUMBERVALUE(advaltech_IS!D12) | D8: =_xlfn.NUMBERVALUE(advaltech_IS!E12) | E8: =_xlfn.NUMBERVALUE(advaltech_IS!F12) | F8: =_xlfn.NUMBERVALUE(advaltech_IS!G12) | G8: =_xlfn.NUMBERVALUE(advaltech_IS!H12) | H8: =_xlfn.NUMBERVALUE(advaltech_IS!I12) | I8: =_xlfn.NUMBERVALUE(advaltech_IS!J12) | J8: =_xlfn.NUMBERVALUE(advaltech_IS!K12) | ... V8: =_xlfn.NUMBERVALUE(advaltech_IS!W12) | W8: =_xlfn.NUMBERVALUE(advaltech_IS!W12) | X8: =_xlfn.NUMBERVALUE(advaltech_IS!X12) | Y8: =_xlfn.NUMBERVALUE(advaltech_IS!Y12) | Z8: =_xlfn.NUMBERVALUE(advaltech_IS!Z12) | AA8: =_xlfn.NUMBERVALUE(advaltech_IS!AA12) | AB8: =_xlfn.NUMBERVALUE(advaltech_IS!AB12) | AC8: =_xlfn.NUMBERVALUE(advaltech_IS!AC12) | AD8: =_xlfn.NUMBERVALUE(advaltech_IS!AD12) | ... AP8: =_xlfn.NUMBERVALUE(advaltech_IS!AP12)
A9: EBIT | C9: =_xlfn.NUMBERVALUE(advaltech_IS!D24) | D9: =_xlfn.NUMBERVALUE(advaltech_IS!E43) | E9: =_xlfn.NUMBERVALUE(advaltech_IS!F43) | F9: =_xlfn.NUMBERVALUE(advaltech_IS!G43) | G9: =_xlfn.NUMBERVALUE(advaltech_IS!H43) | H9: =_xlfn.NUMBERVALUE(advaltech_IS!I43) | I9: =_xlfn.NUMBERVALUE(advaltech_IS!J43) | J9: =_xlfn.NUMBERVALUE(advaltech_IS!K43) | K9: =_xlfn.NUMBERVALUE(advaltech_IS!L43) | ... V9: =_xlfn.NUMBERVALUE(advaltech_IS!W43) | W9: =_xlfn.NUMBERVALUE(advaltech_IS!W43) | X9: =_xlfn.NUMBERVALUE(advaltech_IS!X43) | Y9: =_xlfn.NUMBERVALUE(advaltech_IS!Y43) | Z9: =_xlfn.NUMBERVALUE(advaltech_IS!Z43) | AA9: =_xlfn.NUMBERVALUE(advaltech_IS!AA43) | AB9: =_xlfn.NUMBERVALUE(advaltech_IS!AB43) | AC9: =_xlfn.NUMBERVALUE(advaltech_IS!AC43) | AD9: =_xlfn.NUMBERVALUE(advaltech_IS!AD43) | ... AP9: =_xlfn.NUMBERVALUE(advaltech_IS!AP43)
A10: NI | C10: =_xlfn.NUMBERVALUE(advaltech_IS!D33) | D10: =_xlfn.NUMBERVALUE(advaltech_IS!E32) | E10: =_xlfn.NUMBERVALUE(advaltech_IS!F32) | F10: =_xlfn.NUMBERVALUE(advaltech_IS!G32) | G10: =_xlfn.NUMBERVALUE(advaltech_IS!H32) | H10: =_xlfn.NUMBERVALUE(advaltech_IS!I32) | I10: =_xlfn.NUMBERVALUE(advaltech_IS!J32) | J10: =_xlfn.NUMBERVALUE(advaltech_IS!K32) | K10: =_xlfn.NUMBERVALUE(advaltech_IS!L32) | ... V10: =_xlfn.NUMBERVALUE(advaltech_IS!W32) | W10: =_xlfn.NUMBERVALUE(advaltech_IS!W32) | X10: =_xlfn.NUMBERVALUE(advaltech_IS!X32) | Y10: =_xlfn.NUMBERVALUE(advaltech_IS!Y32) | Z10: =_xlfn.NUMBERVALUE(advaltech_IS!Z32) | AA10: =_xlfn.NUMBERVALUE(advaltech_IS!AA32) | AB10: =_xlfn.NUMBERVALUE(advaltech_IS!AB32) | AC10: =_xlfn.NUMBERVALUE(advaltech_IS!AC32) | AD10: =_xlfn.NUMBERVALUE(advaltech_IS!AD32) | ... AP10: =_xlfn.NUMBERVALUE(advaltech_IS!AP32)
A12: Semi-Annually
A13: ROA (EBIT) | D13: =D9/D3 | E13: =E9/E3 | F13: =F9/F3 | G13: =G9/G3 | H13: =H9/H3 | I13: =I9/I3 | J13: =J9/J3 | K13: =K9/K3 | ... AP13: =AP9/AP3
A14: ROA (NI) | D14: =D10/D3 | E14: =E10/E3 | F14: =F10/F3 | G14: =G10/G3 | H14: =H10/H3 | I14: =I10/I3 | J14: =J10/J3 | K14: =K10/K3 | ... AP14: =AP10/AP3
A16: ROE (EBIT) | D16: =D9/D6 | E16: =E9/E6 | F16: =F9/F6 | G16: =G9/G6 | H16: =H9/H6 | I16: =I9/I6 | J16: =J9/J6 | K16: =K9/K6 | ... AP16: =AP9/AP6
A17: ROE (NI) | D17: =D10/D6 | E17: =E10/E6 | F17: =F10/F6 | G17: =G10/G6 | H17: =H10/H6 | I17: =I10/I6 | J17: =J10/J6 | K17: =K10/K6 | ... AP17: =AP10/AP6
A19: Annualized
A20: ROA (EBIT) | D20: =D13*2 | E20: =E13*2 | F20: =F13*2 | G20: =G13*2 | H20: =H13*2 | I20: =I13*2 | J20: =J13*2 | K20: =K13*2 | ... AP20: =AP13*2
A21: ROA (NI) | D21: =D14*2 | E21: =E14*2 | F21: =F14*2 | G21: =G14*2 | H21: =H14*2 | I21: =I14*2 | J21: =J14*2 | K21: =K14*2 | ... V21: =V14*2
A23: ROE (EBIT) | D23: =D16*2 | E23: =E16*2 | F23: =F16*2 | G23: =G16*2 | H23: =H16*2 | I23: =I16*2 | J23: =J16*2 | K23: =K16*2 | ... AP23: =AP16*2
A24: ROE (NI) | D24: =D17*2 | E24: =E17*2 | F24: =F17*2 | G24: =G17*2 | H24: =H17*2 | I24: =I17*2 | J24: =J17*2 | K24: =K17*2 | ... AP24: =AP17*2
A26: TTM
A27: ROA (EBIT) | G27: =SUM(F9:G9)/AVERAGE(E2,G2) | H27: =SUM(G9:H9)/AVERAGE(F2,H2) | I27: =SUM(H9:I9)/AVERAGE(G2,I2) | J27: =SUM(I9:J9)/AVERAGE(H2,J2) | K27: =SUM(J9:K9)/AVERAGE(I2,K2) | L27: =SUM(K9:L9)/AVERAGE(J2,L2) | M27: =SUM(L9:M9)/AVERAGE(K2,M2) | N27: =SUM(M9:N9)/AVERAGE(L2,N2) | ... AP27: =SUM(AO9:AP9)/AVERAGE(AN2,AP2)
A28: ROA (NI) | G28: =SUM(F10:G10)/AVERAGE(E2,G2) | H28: =SUM(G10:H10)/AVERAGE(F2,H2) | I28: =SUM(H10:I10)/AVERAGE(G2,I2) | J28: =SUM(I10:J10)/AVERAGE(H2,J2) | K28: =SUM(J10:K10)/AVERAGE(I2,K2) | L28: =SUM(K10:L10)/AVERAGE(J2,L2) | M28: =SUM(L10:M10)/AVERAGE(K2,M2) | N28: =SUM(M10:N10)/AVERAGE(L2,N2) | ... AP28: =SUM(AO10:AP10)/AVERAGE(AN2,AP2)
A30: ROE (EBIT) | G30: =SUM(F9:G9)/AVERAGE(E5,G5) | H30: =SUM(G9:H9)/AVERAGE(F5,H5) | I30: =SUM(H9:I9)/AVERAGE(G5,I5) | J30: =SUM(I9:J9)/AVERAGE(H5,J5) | K30: =SUM(J9:K9)/AVERAGE(I5,K5) | L30: =SUM(K9:L9)/AVERAGE(J5,L5) | M30: =SUM(L9:M9)/AVERAGE(K5,M5) | N30: =SUM(M9:N9)/AVERAGE(L5,N5) | ... AP30: =SUM(AO9:AP9)/AVERAGE(AN5,AP5)
A31: ROE (NI) | G31: =SUM(F10:G10)/AVERAGE(E5,G5) | H31: =SUM(G10:H10)/AVERAGE(F5,H5) | I31: =SUM(H10:I10)/AVERAGE(G5,I5) | J31: =SUM(I10:J10)/AVERAGE(H5,J5) | K31: =SUM(J10:K10)/AVERAGE(I5,K5) | L31: =SUM(K10:L10)/AVERAGE(J5,L5) | M31: =SUM(L10:M10)/AVERAGE(K5,M5) | N31: =SUM(M10:N10)/AVERAGE(L5,N5) | ... AP31: =SUM(AO10:AP10)/AVERAGE(AN5,AP5)
A33: Sales / Assets | D33: =D8*4/D3 | E33: =E8*4/E3 | F33: =F8*4/F3 | G33: =G8*4/G3 | H33: =H8*4/H3 | I33: =I8*4/I3 | J33: =J8*4/J3 | K33: =K8*4/K3 | ... AP33: =AP8*4/AP3

Sheet ownership
A1: Name | B1: Title | C1: shares | D1: voting rights | E1: % shares | F1: % Voting

Sheet advaltech_IS
C2: Trilogiq
C3: Premium Export
C6: Income Statement
D8: Q-39 | E8: Q-38 | F8: Q-37 | G8: Q-36 | H8: Q-35 | I8: Q-34 | J8: Q-33 | K8: Q-32 | L8: Q-31 | M8: Q-30 | N8: Q-29 | O8: Q-28 | P8: Q-27 | Q8: Q-26 | R8: Q-25 | S8: Q-24 | T8: Q-23 | U8: Q-22 | V8: Q-21 | W8: Q-20 | X8: Q-19 | Y8: Q-18 | Z8: Q-17 | AA8: Q-16 | AB8: Q-15 | AC8: Q-14 | AD8: Q-13 | AE8: Q-12 | AF8: Q-11 | AG8: Q-10 | AH8: Q-9 | AI8: Q-8 | AJ8: Q-7 | AK8: Q-6 | AL8: Q-5 | AM8: Q-4 | AN8: Q-3 | AO8: Q-2 | AP8: Q-1 | AQ8: Q
C10: Period End Date | D10: 2015-09-30 | E10: 2015-12-31 | F10: 2016-03-31 | G10: 2016-06-30 | H10: 2016-09-30 | I10: 2016-12-31 | J10: 2017-03-31 | K10: 2017-06-30 | L10: 2017-09-30 | M10: 2017-12-31 | N10: 2018-03-31 | O10: 2018-06-30 | P10: 2018-09-30 | Q10: 2018-12-31 | R10: 2019-03-31 | S10: 2019-06-30 | T10: 2019-09-30 | U10: 2019-12-31 | V10: 2020-03-31 | W10: 2020-06-30 | X10: 2020-09-30 | Y10: 2020-12-31 | Z10: 2021-03-31 | AA10: 2021-06-30 | AB10: 2021-09-30 | AC10: 2021-12-31 | AD10: 2022-03-31 | AE10: 2022-06-30 | AF10: 2022-09-30 | AG10: 2022-12-31 | AH10: 2023-03-31 | AI10: 2023-06-30 | AJ10: 2023-09-30 | AK10: 2023-12-31 | AL10: 2024-03-31 | AM10: 2024-06-30 | AN10: 2024-09-30 | AO10: 2024-12-31 | AP10: 2025-03-31 | AQ10: 2025-06-30
C12: Revenue | D12: 53.4 | E12: 53.4 | F12: 55.3 | G12: 55.3 | H12: 60.9 | I12: 60.9 | J12: 51.2 | K12: 51.2 | L12: 49 | M12: 49 | N12: 52 | O12: 52 | P12: 43.7 | Q12: 43.7 | R12: 48.3 | S12: 48.3 | T12: 38.5 | U12: 38.5 | V12: 30.8 | W12: 30.8 | X12: 36.7 | Y12: 36.7 | Z12: 45.2 | AA12: 45.2 | AB12: 38.1 | AC12: 38.1 | AD12: 45.4 | AE12: 45.4 | AF12: 43.9 | AG12: 43.9 | AH12: 45.6 | AI12: 45.6 | AJ12: 39.6 | AK12: 39.6 | AL12: 45.1 | AM12: 45.1 | AN12: 37.7 | AO12: 37.7 | AP12: 39.7 | AQ12: 39.7
C13: Revenue Growth (YoY) | D13: NM | E13: NM | F13: -0.1% | G13: -0.1% | H13: 14.1% | I13: 14.1% | J13: -7.3% | K13: -7.3% | L13: -19.6% | M13: -19.6% | N13: 1.6% | O13: 1.6% | P13: -10.8% | Q13: -10.8% | R13: -7.2% | S13: -7.2% | T13: -11.8% | U13: -11.8% | V13: -36.3% | W13: -36.3% | X13: -4.9% | Y13: -4.9% | Z13: 46.9% | AA13: 46.9% | AB13: 4.0% | AC13: 4.0% | AD13: 0.5% | AE13: 0.5% | AF13: 15.2% | AG13: 15.2% | AH13: 0.4% | AI13: 0.4% | AJ13: -10.0% | AK13: -10.0% | AL13: -1.1% | AM13: -1.1% | AN13: -4.7% | AO13: -4.7% | AP13: -11.9% | AQ13: -11.9%
C15: Cost of Revenues | D15: -23.3 | E15: -23.3 | F15: -21.8 | G15: -21.8 | H15: -33.3 | I15: -33.3 | J15: -25.1 | K15: -25.1 | L15: -24.7 | M15: -24.7 | N15: -24 | O15: -24 | P15: -21.9 | Q15: -21.9 | R15: -23 | S15: -23 | T15: -18.6 | U15: -18.6 | V15: -13.5 | W15: -13.5 | X15: -17.1 | Y15: -17.1 | Z15: -22.2 | AA15: -22.2 | AB15: -20.3 | AC15: -20.3 | AD15: -23.8 | AE15: -23.8 | AF15: -27.3 | AG15: -27.3 | AH15: -24.6 | AI15: -24.6 | AJ15: -21.7 | AK15: -21.7 | AL15: -23.4 | AM15: -23.4 | AN15: -22.8 | AO15: -22.8 | AP15: -20.6 | AQ15: -20.6
C16: Gross Profit | D16: 30.2 | E16: 30.2 | F16: 33.4 | G16: 33.4 | H16: 27.7 | I16: 27.7 | J16: 26.1 | K16: 26.1 | L16: 24.3 | M16: 24.3 | N16: 28.1 | O16: 28.1 | P16: 21.8 | Q16: 21.8 | R16: 25.3 | S16: 25.3 | T16: 19.9 | U16: 19.9 | V16: 17.3 | W16: 17.3 | X16: 19.6 | Y16: 19.6 | Z16: 23 | AA16: 23 | AB16: 17.8 | AC16: 17.8 | AD16: 21.7 | AE16: 21.7 | AF16: 16.6 | AG16: 16.6 | AH16: 21 | AI16: 21 | AJ16: 17.9 | AK16: 17.9 | AL16: 21.7 | AM16: 21.7 | AN16: 14.9 | AO16: 14.9 | AP16: 19.1 | AQ16: 19.1
C17: Gross Profit Margin | D17: 56.5% | E17: 56.5% | F17: 60.5% | G17: 60.5% | H17: 45.4% | I17: 45.4% | J17: 51.1% | K17: 51.1% | L17: 49.5% | M17: 49.5% | N17: 53.9% | O17: 53.9% | P17: 49.9% | Q17: 49.9% | R17: 52.4% | S17: 52.4% | T17: 51.7% | U17: 51.7% | V17: 56.1% | W17: 56.1% | X17: 53.3% | Y17: 53.3% | Z17: 50.8% | AA17: 50.8% | AB17: 46.7% | AC17: 46.7% | AD17: 47.7% | AE17: 47.7% | AF17: 37.8% | AG17: 37.8% | AH17: 46.0% | AI17: 46.0% | AJ17: 45.2% | AK17: 45.2% | AL17: 48.1% | AM17: 48.1% | AN17: 39.5% | AO17: 39.5% | AP17: 48.1% | AQ17: 48.1%
C19: R&D Expenses | D19: 0 | E19: 0 | F19: 0 | G19: 0 | H19: 0 | I19: 0 | J19: 0 | K19: 0 | L19: 0 | M19: 0 | N19: 0 | O19: 0 | P19: -0.5 | Q19: -0.5 | R19: 0 | S19: 0 | T19: -0.4 | U19: -0.4 | V19: 0 | W19: 0 | X19: -0.4 | Y19: -0.4 | Z19: 0 | AA19: 0 | AB19: -0.4 | AC19: -0.4 | AD19: 0 | AE19: 0 | AF19: -0.4 | AG19: -0.4 | AH19: 0 | AI19: 0 | AJ19: -0.4 | AK19: -0.4 | AL19: 0 | AM19: 0 | AN19: -0.1 | AO19: -0.1 | AP19: 0 | AQ19: 0
C20: Selling and Marketing Expense
C21: General & Admin Expenses
C22: Other Inc / (Exp) | D22: -9.8 | E22: -9.8 | F22: -12 | G22: -12 | H22: 9.4 | I22: 9.4 | J22: -8.2 | K22: -8.2 | L22: -5.9 | M22: -5.9 | N22: -7.1 | O22: -7.1 | P22: -5.2 | Q22: -5.2 | R22: -7.3 | S22: -7.3 | T22: -5.1 | U22: -5.1 | V22: -5.8 | W22: -5.8 | X22: -5.1 | Y22: -5.1 | Z22: -6.8 | AA22: -6.8 | AB22: -3.8 | AC22: -3.8 | AD22: -7.6 | AE22: -7.6 | AF22: -4.6 | AG22: -4.6 | AH22: -8 | AI22: -8 | AJ22: -5.3 | AK22: -5.3 | AL22: -9.3 | AM22: -9.3 | AN22: -4.2 | AO22: -4.2 | AP22: -8.2 | AQ22: -8.2
C23: Operating Expenses | D23: -27.7 | E23: -27.7 | F23: -32.3 | G23: -32.3 | H23: -8.1 | I23: -8.1 | J23: -24.1 | K23: -24.1 | L23: -21.7 | M23: -21.7 | N23: -23.6 | O23: -23.6 | P23: -20.4 | Q23: -20.4 | R23: -22.4 | S23: -22.4 | T23: -18.7 | U23: -18.7 | V23: -16.7 | W23: -16.7 | X23: -16.8 | Y23: -16.8 | Z23: -20 | AA23: -20 | AB23: -16 | AC23: -16 | AD23: -21.2 | AE23: -21.2 | AF23: -17.4 | AG23: -17.4 | AH23: -21.5 | AI23: -21.5 | AJ23: -19.2 | AK23: -19.2 | AL23: -23.1 | AM23: -23.1 | AN23: -17.1 | AO23: -17.1 | AP23: -21.1 | AQ23: -21.1
C24: Operating Income | D24: 2.5 | E24: 2.5 | F24: 1.2 | G24: 1.2 | H24: 19.6 | I24: 19.6 | J24: 2 | K24: 2 | L24: 2.6 | M24: 2.6 | N24: 4.4 | O24: 4.4 | P24: 1.4 | Q24: 1.4 | R24: 2.9 | S24: 2.9 | T24: 1.3 | U24: 1.3 | V24: 0.6 | W24: 0.6 | X24: 2.8 | Y24: 2.8 | Z24: 2.9 | AA24: 2.9 | AB24: 1.8 | AC24: 1.8 | AD24: 0.5 | AE24: 0.5 | AF24: -0.8 | AG24: -0.8 | AH24: -0.6 | AI24: -0.6 | AJ24: -1.3 | AK24: -1.3 | AL24: -1.4 | AM24: -1.4 | AN24: -2.2 | AO24: -2.2 | AP24: -2 | AQ24: -2
C26: Net Interest Expenses | D26: -0.3 | E26: -0.3 | F26: -0.5 | G26: -0.5 | H26: -0.1 | I26: -0.1 | J26: 0.1 | K26: 0.1 | L26: 0.1 | M26: 0.1 | N26: 0 | O26: 0 | P26: 0.1 | Q26: 0.1 | R26: 0 | S26: 0 | T26: 0.1 | U26: 0.1 | V26: 0 | W26: 0 | X26: 0 | Y26: 0 | Z26: 0 | AA26: 0 | AB26: 0 | AC26: 0 | AD26: 0 | AE26: 0 | AF26: 0.1 | AG26: 0.1 | AH26: 0.1 | AI26: 0.1 | AJ26: 0.1 | AK26: 0.1 | AL26: 0.1 | AM26: 0.1 | AN26: 0.1 | AO26: 0.1 | AP26: 0 | AQ26: 0
C27: EBT, Incl. Unusual Items | D27: 2.2 | E27: 2.2 | F27: 0.7 | G27: 0.7 | H27: 19.5 | I27: 19.5 | J27: 2.1 | K27: 2.1 | L27: 2.7 | M27: 2.7 | N27: 4.4 | O27: 4.4 | P27: 1.5 | Q27: 1.5 | R27: 2.9 | S27: 2.9 | T27: 1.4 | U27: 1.4 | V27: 0.6 | W27: 0.6 | X27: 2.8 | Y27: 2.8 | Z27: 2.9 | AA27: 2.9 | AB27: 1.8 | AC27: 1.8 | AD27: 0.5 | AE27: 0.5 | AF27: -0.8 | AG27: -0.8 | AH27: -0.5 | AI27: -0.5 | AJ27: -1.2 | AK27: -1.2 | AL27: -1.3 | AM27: -1.3 | AN27: -2.1 | AO27: -2.1 | AP27: -2.1 | AQ27: -2.1
C28: Earnings of Discontinued Ops.
C29: Income Tax Expense | D29: -0.5 | E29: -0.5 | F29: 0.4 | G29: 0.4 | H29: -0.7 | I29: -0.7 | J29: -0.2 | K29: -0.2 | L29: -0.2 | M29: -0.2 | N29: -0.5 | O29: -0.5 | P29: -1 | Q29: -1 | R29: -0.7 | S29: -0.7 | T29: 0.8 | U29: 0.8 | V29: -0.5 | W29: -0.5 | X29: -0.7 | Y29: -0.7 | Z29: -0.8 | AA29: -0.8 | AB29: -1 | AC29: -1 | AD29: -0.5 | AE29: -0.5 | AF29: -0.4 | AG29: -0.4 | AH29: -0.5 | AI29: -0.5 | AJ29: 0.3 | AK29: 0.3 | AL29: -0.3 | AM29: -0.3 | AN29: -0.2 | AO29: -0.2 | AP29: -0.3 | AQ29: -0.3
C30: Net Income to Company | D30: 1.7 | E30: 1.7 | F30: 1.1 | G30: 1.1 | H30: 18.8 | I30: 18.8 | J30: 1.8 | K30: 1.8 | L30: 2.5 | M30: 2.5 | N30: 3.9 | O30: 3.9 | P30: 0.5 | Q30: 0.5 | R30: 2.1 | S30: 2.1 | T30: 2.2 | U30: 2.2 | V30: 0 | W30: 0 | X30: 2.1 | Y30: 2.1 | Z30: 2.1 | AA30: 2.1 | AB30: 0.8 | AC30: 0.8 | AD30: 0 | AE30: 0 | AF30: -1.2 | AG30: -1.2 | AH30: -0.9 | AI30: -0.9 | AJ30: -1 | AK30: -1 | AL30: -1.6 | AM30: -1.6 | AN30: -2.2 | AO30: -2.2 | AP30: -2.4 | AQ30: -2.4
C32: Minority Interest in Earnings
C33: Net Income to Stockholders | D33: 1.7 | E33: 1.7 | F33: 1.1 | G33: 1.1 | H33: 18.8 | I33: 18.8 | J33: 1.8 | K33: 1.8 | L33: 2.5 | M33: 2.5 | N33: 3.9 | O33: 3.9 | P33: 0.5 | Q33: 0.5 | R33: 2.1 | S33: 2.1 | T33: 2.2 | U33: 2.2 | V33: 0 | W33: 0 | X33: 2.1 | Y33: 2.1 | Z33: 2.1 | AA33: 2.1 | AB33: 0.8 | AC33: 0.8 | AD33: 0 | AE33: 0 | AF33: -1.2 | AG33: -1.2 | AH33: -0.9 | AI33: -0.9 | AJ33: -1 | AK33: -1 | AL33: -1.6 | AM33: -1.6 | AN33: -2.2 | AO33: -2.2 | AP33: -2.4 | AQ33: -2.4
C35: Preferred Dividends & Other Adj. | D35: 0 | E35: 0 | F35: 0 | G35: 0 | H35: 0 | I35: 0 | J35: 0 | K35: 0 | L35: 0 | M35: 0 | N35: 0 | O35: 0 | P35: 0 | Q35: 0 | R35: 0 | S35: 0 | T35: 0 | U35: 0 | V35: 0 | W35: 0 | X35: 0 | Y35: 0 | Z35: 0 | AA35: 0 | AB35: 0 | AC35: 0 | AD35: 0 | AE35: 0 | AF35: 0 | AG35: 0 | AH35: 0 | AI35: 0 | AJ35: 0 | AK35: 0 | AL35: 0 | AM35: 0 | AN35: 0 | AO35: 0 | AP35: 0 | AQ35: 0
C36: Net Income to Common Excl Extra Items | D36: 1.7 | E36: 1.7 | F36: 1.1 | G36: 1.1 | H36: 18.8 | I36: 18.8 | J36: 1.8 | K36: 1.8 | L36: 2.5 | M36: 2.5 | N36: 3.9 | O36: 3.9 | P36: 0.5 | Q36: 0.5 | R36: 2.1 | S36: 2.1 | T36: 2.2 | U36: 2.2 | V36: 0 | W36: 0 | X36: 2.1 | Y36: 2.1 | Z36: 2.1 | AA36: 2.1 | AB36: 0.8 | AC36: 0.8 | AD36: 0 | AE36: 0 | AF36: -1.2 | AG36: -1.2 | AH36: -0.9 | AI36: -0.9 | AJ36: -1 | AK36: -1 | AL36: -1.6 | AM36: -1.6 | AN36: -2.2 | AO36: -2.2 | AP36: -2.4 | AQ36: -2.4
C38: Basic EPS (Cont. Ops) | D38: 2.36 | E38: 2.36 | F38: 1.54 | G38: 1.54 | H38: 25.69 | I38: 25.69 | J38: 2.51 | K38: 2.51 | L38: 3.48 | M38: 3.48 | N38: 5.37 | O38: 5.37 | P38: 0.64 | Q38: 0.64 | R38: 2.91 | S38: 2.91 | T38: 3.02 | U38: 3.02 | V38: 0.033 | W38: 0.033 | X38: 2.91 | Y38: 2.91 | Z38: 2.92 | AA38: 2.92 | AB38: 1.11 | AC38: 1.11 | AD38: -0.03 | AE38: -0.03 | AF38: -1.58 | AG38: -1.58 | AH38: -1.27 | AI38: -1.27 | AJ38: -1.37 | AK38: -1.37 | AL38: -2.24 | AM38: -2.24 | AN38: -3.08 | AO38: -3.08 | AP38: -3.23 | AQ38: -3.23
C39: Diluted EPS (Cont. Ops) | D39: 2.36 | E39: 2.36 | F39: 1.54 | G39: 1.54 | H39: 25.69 | I39: 25.69 | J39: 2.51 | K39: 2.51 | L39: 3.48 | M39: 3.48 | N39: 5.37 | O39: 5.37 | P39: 0.64 | Q39: 0.64 | R39: 2.91 | S39: 2.91 | T39: 3.02 | U39: 3.02 | V39: 0.033 | W39: 0.033 | X39: 2.91 | Y39: 2.91 | Z39: 2.92 | AA39: 2.92 | AB39: 1.11 | AC39: 1.11 | AD39: -0.03 | AE39: -0.03 | AF39: -1.58 | AG39: -1.58 | AH39: -1.27 | AI39: -1.27 | AJ39: -1.37 | AK39: -1.37 | AL39: -2.24 | AM39: -2.24 | AN39: -3.08 | AO39: -3.08 | AP39: -3.23 | AQ39: -3.23
C40: Weighted Average Basic Shares Out. | D40: 0.7 | E40: 0.7 | F40: 0.7 | G40: 0.7 | H40: 0.7 | I40: 0.7 | J40: 0.7 | K40: 0.7 | L40: 0.7 | M40: 0.7 | N40: 0.7 | O40: 0.7 | P40: 0.7 | Q40: 0.7 | R40: 0.7 | S40: 0.7 | T40: 0.7 | U40: 0.7 | V40: 0.7 | W40: 0.7 | X40: 0.7 | Y40: 0.7 | Z40: 0.7 | AA40: 0.7 | AB40: 0.7 | AC40: 0.7 | AD40: 0.7 | AE40: 0.7 | AF40: 0.7 | AG40: 0.7 | AH40: 0.7 | AI40: 0.7 | AJ40: 0.7 | AK40: 0.7 | AL40: 0.7 | AM40: 0.7 | AN40: 0.7 | AO40: 0.7 | AP40: 0.7 | AQ40: 0.7
C41: Weighted Average Diluted Shares Out. | D41: 0.7 | E41: 0.7 | F41: 0.7 | G41: 0.7 | H41: 0.7 | I41: 0.7 | J41: 0.7 | K41: 0.7 | L41: 0.7 | M41: 0.7 | N41: 0.7 | O41: 0.7 | P41: 0.7 | Q41: 0.7 | R41: 0.7 | S41: 0.7 | T41: 0.7 | U41: 0.7 | V41: 0.7 | W41: 0.7 | X41: 0.7 | Y41: 0.7 | Z41: 0.7 | AA41: 0.7 | AB41: 0.7 | AC41: 0.7 | AD41: 0.7 | AE41: 0.7 | AF41: 0.7 | AG41: 0.7 | AH41: 0.7 | AI41: 0.7 | AJ41: 0.7 | AK41: 0.7 | AL41: 0.7 | AM41: 0.7 | AN41: 0.7 | AO41: 0.7 | AP41: 0.7 | AQ41: 0.7
C43: EBITDA | D43: 6 | E43: 6 | F43: 5.1 | G43: 5.1 | H43: 5.5 | I43: 5.5 | J43: 4.6 | K43: 4.6 | L43: 4.5 | M43: 4.5 | N43: 5.5 | O43: 5.5 | P43: 4.3 | Q43: 4.3 | R43: 5 | S43: 5 | T43: 3.8 | U43: 3.8 | V43: 2.1 | W43: 2.1 | X43: 5.1 | Y43: 5.1 | Z43: 4.7 | AA43: 4.7 | AB43: 3.4 | AC43: 3.4 | AD43: 2.5 | AE43: 2.5 | AF43: 1.3 | AG43: 1.3 | AH43: 1.6 | AI43: 1.6 | AJ43: 0.8 | AK43: 0.8 | AL43: 0.7 | AM43: 0.7 | AN43: 0.7 | AO43: 0.7 | AP43: 0.2 | AQ43: 0.2
C44: EBIT | D44: 2.7 | E44: 2.7 | F44: 1.6 | G44: 1.6 | H44: 2.5 | I44: 2.5 | J44: 2.4 | K44: 2.4 | L44: 2.8 | M44: 2.8 | N44: 3.5 | O44: 3.5 | P44: 2.6 | Q44: 2.6 | R44: 3.2 | S44: 3.2 | T44: 1.9 | U44: 1.9 | V44: 0.6 | W44: 0.6 | X44: 2.7 | Y44: 2.7 | Z44: 2.9 | AA44: 2.9 | AB44: 1.7 | AC44: 1.7 | AD44: 0.7 | AE44: 0.7 | AF44: -0.5 | AG44: -0.5 | AH44: -0.1 | AI44: -0.1 | AJ44: -0.8 | AK44: -0.8 | AL44: -0.9 | AM44: -0.9 | AN44: -0.9 | AO44: -0.9 | AP44: -1.1 | AQ44: -1.1
C46: Revenue (Reported) | D46: 112.2 | E46: 112.2 | F46: 55.3 | G46: 55.3 | H46: 113.5 | I46: 113.5 | J46: 51.2 | K46: 51.2 | L46: 103.9 | M46: 103.9 | N46: 52 | O46: 52 | P46: 99.1 | Q46: 99.1 | R46: 48.3 | S46: 48.3 | T46: 89.4 | U46: 89.4 | V46: 30.8 | W46: 30.8 | X46: 70.4 | Y46: 70.4 | Z46: 45.2 | AA46: 45.2 | AB46: 85.4 | AC46: 85.4 | AD46: 45.4 | AE46: 45.4 | AF46: 93.7 | AG46: 93.7 | AH46: 45.6 | AI46: 45.6 | AJ46: 89.6 | AK46: 89.6 | AL46: 45.1 | AM46: 45.1 | AN46: 87.4 | AO46: 87.4 | AP46: 39.7 | AQ46: 39.7
C47: Operating Income (Reported) | D47: 2.8 | E47: 2.8 | F47: 1.6 | G47: 1.6 | H47: 2.5 | I47: 2.5 | J47: 2.4 | K47: 2.4 | L47: 2.9 | M47: 2.9 | N47: 3.5 | O47: 3.5 | P47: 2.7 | Q47: 2.7 | R47: 3.2 | S47: 3.2 | T47: 2 | U47: 2 | V47: 0.6 | W47: 0.6 | X47: 2.7 | Y47: 2.7 | Z47: 2.9 | AA47: 2.9 | AB47: 1.7 | AC47: 1.7 | AD47: 0.7 | AE47: 0.7 | AF47: -0.4 | AG47: -0.4 | AH47: -0.1 | AI47: -0.1 | AJ47: -0.8 | AK47: -0.8 | AL47: -0.9 | AM47: -0.9 | AN47: -1.8 | AO47: -1.8 | AP47: -1.1 | AQ47: -1.1
C48: Operating Income (Adjusted) | D48: 2.7 | E48: 2.7 | F48: 1.6 | G48: 1.6 | H48: 2.5 | I48: 2.5 | J48: 2.4 | K48: 2.4 | L48: 2.8 | M48: 2.8 | N48: 3.5 | O48: 3.5 | P48: 2.6 | Q48: 2.6 | R48: 3.2 | S48: 3.2 | T48: 1.9 | U48: 1.9 | V48: 0.6 | W48: 0.6 | X48: 2.7 | Y48: 2.7 | Z48: 2.9 | AA48: 2.9 | AB48: 1.7 | AC48: 1.7 | AD48: 0.7 | AE48: 0.7 | AF48: -0.5 | AG48: -0.5 | AH48: -0.1 | AI48: -0.1 | AJ48: -0.8 | AK48: -0.8 | AL48: -0.9 | AM48: -0.9 | AN48: -0.9 | AO48: -0.9 | AP48: -1.1 | AQ48: -1.1

Sheet advaltech_bs
C2: Trilogiq
C3: Premium Export
C6: Balance Sheet
D8: Q-39 | E8: Q-38 | F8: Q-37 | G8: Q-36 | H8: Q-35 | I8: Q-34 | J8: Q-33 | K8: Q-32 | L8: Q-31 | M8: Q-30 | N8: Q-29 | O8: Q-28 | P8: Q-27 | Q8: Q-26 | R8: Q-25 | S8: Q-24 | T8: Q-23 | U8: Q-22 | V8: Q-21 | W8: Q-20 | X8: Q-19 | Y8: Q-18 | Z8: Q-17 | AA8: Q-16 | AB8: Q-15 | AC8: Q-14 | AD8: Q-13 | AE8: Q-12 | AF8: Q-11 | AG8: Q-10 | AH8: Q-9 | AI8: Q-8 | AJ8: Q-7 | AK8: Q-6 | AL8: Q-5 | AM8: Q-4 | AN8: Q-3 | AO8: Q-2 | AP8: Q-1 | AQ8: Q
C10: Period End Date | D10: 2015-09-30 | E10: 2015-12-31 | F10: 2016-03-31 | G10: 2016-06-30 | H10: 2016-09-30 | I10: 2016-12-31 | J10: 2017-03-31 | K10: 2017-06-30 | L10: 2017-09-30 | M10: 2017-12-31 | N10: 2018-03-31 | O10: 2018-06-30 | P10: 2018-09-30 | Q10: 2018-12-31 | R10: 2019-03-31 | S10: 2019-06-30 | T10: 2019-09-30 | U10: 2019-12-31 | V10: 2020-03-31 | W10: 2020-06-30 | X10: 2020-09-30 | Y10: 2020-12-31 | Z10: 2021-03-31 | AA10: 2021-06-30 | AB10: 2021-09-30 | AC10: 2021-12-31 | AD10: 2022-03-31 | AE10: 2022-06-30 | AF10: 2022-09-30 | AG10: 2022-12-31 | AH10: 2023-03-31 | AI10: 2023-06-30 | AJ10: 2023-09-30 | AK10: 2023-12-31 | AL10: 2024-03-31 | AM10: 2024-06-30 | AN10: 2024-09-30 | AO10: 2024-12-31 | AP10: 2025-03-31 | AQ10: 2025-06-30
C12: Cash And Equivalents | D12: 16 | E12: 16 | F12: 21.3 | G12: 21.3 | H12: 53.9 | I12: 53.9 | J12: 12.4 | K12: 12.4 | L12: 18.1 | M12: 18.1 | N12: 22.9 | O12: 22.9 | P12: 27.5 | Q12: 27.5 | R12: 21.6 | S12: 21.6 | T12: 19.5 | U12: 19.5 | V12: 16 | W12: 16 | X12: 19.9 | Y12: 19.9 | Z12: 18.1 | AA12: 18.1 | AB12: 31.9 | AC12: 31.9 | AD12: 29.9 | AE12: 29.9 | AF12: 28.6 | AG12: 28.6 | AH12: 26.8 | AI12: 26.8 | AJ12: 27.3 | AK12: 27.3 | AL12: 16.3 | AM12: 16.3 | AN12: 17.8 | AO12: 17.8 | AP12: 14.7 | AQ12: 14.7
C13: Short Term Investments
C14: Accounts Receivable, Net | D14: 37.6 | E14: 37.6 | F14: 44.3 | G14: 44.3 | H14: 28.8 | I14: 28.8 | J14: 29.9 | K14: 29.9 | L14: 31.4 | M14: 31.4 | N14: 31.1 | O14: 31.1 | P14: 30.3 | Q14: 30.3 | R14: 26.8 | S14: 26.8 | T14: 28.5 | U14: 28.5 | V14: 19.4 | W14: 19.4 | X14: 28.1 | Y14: 28.1 | Z14: 31.2 | AA14: 31.2 | AB14: 25.3 | AC14: 25.3 | AD14: 28.7 | AE14: 28.7 | AF14: 26.1 | AG14: 26.1 | AH14: 33.7 | AI14: 33.7 | AJ14: 23.7 | AK14: 23.7 | AL14: 25.8 | AM14: 25.8 | AN14: 28.4 | AO14: 28.4 | AP14: 30.2 | AQ14: 30.2
C15: Inventory | D15: 43.5 | E15: 43.5 | F15: 52.1 | G15: 52.1 | H15: 23.2 | I15: 23.2 | J15: 36.8 | K15: 36.8 | L15: 34.7 | M15: 34.7 | N15: 38.2 | O15: 38.2 | P15: 37.6 | Q15: 37.6 | R15: 39.7 | S15: 39.7 | T15: 31.9 | U15: 31.9 | V15: 33.8 | W15: 33.8 | X15: 37.2 | Y15: 37.2 | Z15: 39.1 | AA15: 39.1 | AB15: 39.4 | AC15: 39.4 | AD15: 40.2 | AE15: 40.2 | AF15: 50 | AG15: 50 | AH15: 42.4 | AI15: 42.4 | AJ15: 37.8 | AK15: 37.8 | AL15: 46.5 | AM15: 46.5 | AN15: 47.6 | AO15: 47.6 | AP15: 39.2 | AQ15: 39.2
C16: Prepaid Expenses | D16: 2.1 | E16: 2.1 | F16: 5.1 | G16: 5.1 | H16: 1.4 | I16: 1.4 | J16: 1.9 | K16: 1.9 | L16: 0.6 | M16: 0.6 | N16: 1.6 | O16: 1.6 | P16: 1.1 | Q16: 1.1 | T16: 0.9 | U16: 0.9 | X16: 1.3 | Y16: 1.3 | Z16: 2 | AA16: 2 | AB16: 1.5 | AC16: 1.5 | AD16: 2.1 | AE16: 2.1 | AF16: 2 | AG16: 2 | AH16: 2.3 | AI16: 2.3 | AJ16: 1.9 | AK16: 1.9 | AL16: 2.4 | AM16: 2.4 | AN16: 1.8 | AO16: 1.8 | AP16: 2.4 | AQ16: 2.4
C17: Other Current Assets | D17: 7.3 | E17: 7.3 | F17: 11.9 | G17: 11.9 | H17: 13.7 | I17: 13.7 | J17: 7 | K17: 7 | L17: 11.8 | M17: 11.8 | N17: 2.9 | O17: 2.9 | P17: 3.8 | Q17: 3.8 | R17: 8.7 | S17: 8.7 | T17: 3.3 | U17: 3.3 | V17: 8.5 | W17: 8.5 | X17: 3.3 | Y17: 3.3 | Z17: 6.5 | AA17: 6.5 | AB17: 2.4 | AC17: 2.4 | AD17: 4 | AE17: 4 | AF17: 3.2 | AG17: 3.2 | AH17: 3.6 | AI17: 3.6 | AJ17: 4.3 | AK17: 4.3 | AL17: 3.8 | AM17: 3.8 | AN17: 4.8 | AO17: 4.8 | AP17: 5.9 | AQ17: 5.9
C18: Total Current Assets | D18: 106.5 | E18: 106.5 | F18: 134.6 | G18: 134.6 | H18: 120.9 | I18: 120.9 | J18: 87.9 | K18: 87.9 | L18: 96.6 | M18: 96.6 | N18: 96.7 | O18: 96.7 | P18: 100.2 | Q18: 100.2 | R18: 96.8 | S18: 96.8 | T18: 84.2 | U18: 84.2 | V18: 77.7 | W18: 77.7 | X18: 89.8 | Y18: 89.8 | Z18: 96.8 | AA18: 96.8 | AB18: 100.5 | AC18: 100.5 | AD18: 105 | AE18: 105 | AF18: 109.9 | AG18: 109.9 | AH18: 108.8 | AI18: 108.8 | AJ18: 95 | AK18: 95 | AL18: 94.8 | AM18: 94.8 | AN18: 100.3 | AO18: 100.3 | AP18: 92.4 | AQ18: 92.4
C20: Property Plant And Equipment, Net | D20: 76.1 | E20: 76.1 | F20: 85.9 | G20: 85.9 | H20: 60.3 | I20: 60.3 | J20: 64.2 | K20: 64.2 | L20: 66.3 | M20: 66.3 | N20: 69 | O20: 69 | P20: 70.7 | Q20: 70.7 | R20: 69.1 | S20: 69.1 | T20: 66.8 | U20: 66.8 | V20: 64.6 | W20: 64.6 | X20: 61.6 | Y20: 61.6 | Z20: 60.3 | AA20: 60.3 | AB20: 57.7 | AC20: 57.7 | AD20: 54.9 | AE20: 54.9 | AF20: 52.4 | AG20: 52.4 | AH20: 52.7 | AI20: 52.7 | AJ20: 53.5 | AK20: 53.5 | AL20: 51.6 | AM20: 51.6 | AN20: 50.1 | AO20: 50.1 | AP20: 48.9 | AQ20: 48.9
C21: Real Estate Owned
C22: Capitalized / Purchased Software
C23: Long-term Investments | F23: 6.3 | G23: 6.3 | J23: 5.1 | K23: 5.1 | N23: 3.3 | O23: 3.3 | R23: 3.8 | S23: 3.8
C24: Goodwill
C25: Other Intangibles | D25: 0.6 | E25: 0.6 | F25: 9 | G25: 9 | H25: 0 | I25: 0 | J25: 5.3 | K25: 5.3 | L25: 0 | M25: 0 | N25: 4.4 | O25: 4.4 | P25: 0 | Q25: 0 | R25: 3.4 | S25: 3.4 | T25: 0 | U25: 0 | V25: 2.7 | W25: 2.7 | X25: 0 | Y25: 0 | AB25: 0 | AC25: 0 | AF25: 0 | AG25: 0 | AJ25: 0 | AK25: 0 | AN25: 1.7 | AO25: 1.7
C26: Other Long-term Assets | D26: 18 | E26: 18 | F26: 4 | G26: 4 | H26: 12.3 | I26: 12.3 | J26: 1.4 | K26: 1.4 | L26: 10 | M26: 10 | N26: 1.7 | O26: 1.7 | P26: 8.7 | Q26: 8.7 | R26: 1.1 | S26: 1.1 | T26: 11.2 | U26: 11.2 | V26: 10.1 | W26: 10.1 | X26: 11.1 | Y26: 11.1 | Z26: 9.1 | AA26: 9.1 | AB26: 4.7 | AC26: 4.7 | AD26: 3.9 | AE26: 3.9 | AF26: 3.2 | AG26: 3.2 | AH26: 3 | AI26: 3 | AJ26: 3.2 | AK26: 3.2 | AL26: 4.2 | AM26: 4.2 | AN26: 3.1 | AO26: 3.1 | AP26: 4.8 | AQ26: 4.8
C27: Total Assets | D27: 201.2 | E27: 201.2 | F27: 239.9 | G27: 239.9 | H27: 193.6 | I27: 193.6 | J27: 163.9 | K27: 163.9 | L27: 172.9 | M27: 172.9 | N27: 175 | O27: 175 | P27: 179.6 | Q27: 179.6 | R27: 174.2 | S27: 174.2 | T27: 162.3 | U27: 162.3 | V27: 155.1 | W27: 155.1 | X27: 162.6 | Y27: 162.6 | Z27: 166.2 | AA27: 166.2 | AB27: 162.9 | AC27: 162.9 | AD27: 163.8 | AE27: 163.8 | AF27: 165.6 | AG27: 165.6 | AH27: 164.5 | AI27: 164.5 | AJ27: 151.7 | AK27: 151.7 | AL27: 150.5 | AM27: 150.5 | AN27: 155.2 | AO27: 155.2 | AP27: 146.1 | AQ27: 146.1
C29: Accounts Payable | D29: 15.8 | E29: 15.8 | F29: 20.8 | G29: 20.8 | H29: 15 | I29: 15 | J29: 16.1 | K29: 16.1 | L29: 19.8 | M29: 19.8 | N29: 15.6 | O29: 15.6 | P29: 18.6 | Q29: 18.6 | R29: 10.6 | S29: 10.6 | T29: 12.9 | U29: 12.9 | V29: 7.1 | W29: 7.1 | X29: 12 | Y29: 12 | Z29: 10.3 | AA29: 10.3 | AB29: 8.9 | AC29: 8.9 | AD29: 11.8 | AE29: 11.8 | AF29: 12.6 | AG29: 12.6 | AH29: 11.6 | AI29: 11.6 | AJ29: 13.6 | AK29: 13.6 | AL29: 11.2 | AM29: 11.2 | AN29: 12.9 | AO29: 12.9 | AP29: 12.3 | AQ29: 12.3
C30: Accrued Expenses | D30: 9.1 | E30: 9.1 | H30: 11.4 | I30: 11.4 | L30: 9 | M30: 9 | P30: 6.2 | Q30: 6.2 | T30: 4.9 | U30: 4.9 | X30: 6 | Y30: 6 | AB30: 6.1 | AC30: 6.1 | AF30: 7.5 | AG30: 7.5 | AJ30: 5.9 | AK30: 5.9 | AN30: 5.8 | AO30: 5.8
C31: Short-term Borrowings | D31: 14.1 | E31: 14.1 | F31: 97.4 | G31: 97.4 | H31: 0.5 | I31: 0.5 | J31: 3.1 | K31: 3.1 | L31: 0.1 | M31: 0.1 | N31: 0.5 | O31: 0.5 | V31: 0 | W31: 0 | Z31: 0 | AA31: 0 | AD31: 0.1 | AE31: 0.1 | AH31: 0.6 | AI31: 0.6 | AL31: 0.2 | AM31: 0.2
C32: Current Portion of LT Debt | AN32: 9.5 | AO32: 9.5 | AP32: 5 | AQ32: 5
C33: Current Portion of Capital Lease Obligations | D33: 0.3 | E33: 0.3 | F33: 1.1 | G33: 1.1 | H33: 1 | I33: 1 | J33: 1 | K33: 1 | L33: 1 | M33: 1 | N33: 0.7 | O33: 0.7 | P33: 0.9 | Q33: 0.9 | R33: 0.7 | S33: 0.7 | T33: 0.3 | U33: 0.3 | V33: 0.3 | W33: 0.3 | X33: 0.4 | Y33: 0.4 | Z33: 0.3 | AA33: 0.3 | AB33: 0.3 | AC33: 0.3 | AD33: 0.3 | AE33: 0.3 | AF33: 0.2 | AG33: 0.2 | AH33: 0.1 | AI33: 0.1 | AJ33: 0.1 | AK33: 0.1 | AL33: 0.1 | AM33: 0.1 | AN33: 0.2 | AO33: 0.2 | AP33: 0.2 | AQ33: 0.2
C34: Other Current Liabilities | D34: 27.7 | E34: 27.7 | F34: 58 | G34: 58 | H34: 25.9 | I34: 25.9 | J34: 29.9 | K34: 29.9 | L34: 21.7 | M34: 21.7 | N34: 33.5 | O34: 33.5 | P34: 25.7 | Q34: 25.7 | R34: 34.5 | S34: 34.5 | T34: 13.3 | U34: 13.3 | V34: 21.7 | W34: 21.7 | X34: 13.1 | Y34: 13.1 | Z34: 20.1 | AA34: 20.1 | AB34: 15.6 | AC34: 15.6 | AD34: 22.5 | AE34: 22.5 | AF34: 20.1 | AG34: 20.1 | AH34: 28.2 | AI34: 28.2 | AJ34: 12.7 | AK34: 12.7 | AL34: 19.5 | AM34: 19.5 | AN34: 13.6 | AO34: 13.6 | AP34: 22.5 | AQ34: 22.5
C35: Total Current Liabilities | D35: 67 | E35: 67 | F35: 177.2 | G35: 177.2 | H35: 53.8 | I35: 53.8 | J35: 50.2 | K35: 50.2 | L35: 51.7 | M35: 51.7 | N35: 50.4 | O35: 50.4 | P35: 51.4 | Q35: 51.4 | R35: 45.8 | S35: 45.8 | T35: 31.4 | U35: 31.4 | V35: 29.2 | W35: 29.2 | X35: 31.4 | Y35: 31.4 | Z35: 30.7 | AA35: 30.7 | AB35: 30.9 | AC35: 30.9 | AD35: 34.8 | AE35: 34.8 | AF35: 40.5 | AG35: 40.5 | AH35: 40.4 | AI35: 40.4 | AJ35: 32.3 | AK35: 32.3 | AL35: 31.1 | AM35: 31.1 | AN35: 42.1 | AO35: 42.1 | AP35: 40 | AQ35: 40
C37: Long-term Debt | D37: 61.1 | E37: 61.1 | F37: 0.8 | G37: 0.8 | AJ37: 0.9 | AK37: 0.9 | AL37: 1.9 | AM37: 1.9 | AN37: 1.6 | AO37: 1.6 | AP37: 1.4 | AQ37: 1.4
C38: Capital Leases | D38: 0.5 | E38: 0.5 | F38: 2.2 | G38: 2.2 | H38: 1.7 | I38: 1.7 | J38: 1.2 | K38: 1.2 | L38: 1.3 | M38: 1.3 | N38: 0.6 | O38: 0.6 | P38: 0.9 | Q38: 0.9 | R38: 1 | S38: 1 | T38: 0.9 | U38: 0.9 | V38: 0.7 | W38: 0.7 | X38: 0.4 | Y38: 0.4 | Z38: 0.3 | AA38: 0.3 | AB38: 0.5 | AC38: 0.5 | AD38: 0.3 | AE38: 0.3 | AF38: 0.2 | AG38: 0.2 | AH38: 0.2 | AI38: 0.2 | AJ38: 0.4 | AK38: 0.4 | AL38: 0.3 | AM38: 0.3 | AN38: 0.1 | AO38: 0.1 | AP38: 0.1 | AQ38: 0.1
C39: Other Non-current Liabilities | D39: 8 | E39: 8 | F39: 6.4 | G39: 6.4 | H39: 4.9 | I39: 4.9 | J39: 4.7 | K39: 4.7 | L39: 2.7 | M39: 2.7 | N39: 2.7 | O39: 2.7 | P39: 3.8 | Q39: 3.8 | R39: 3.6 | S39: 3.6 | T39: 3.7 | U39: 3.7 | V39: 3.6 | W39: 3.6 | X39: 4.2 | Y39: 4.2 | Z39: 4.8 | AA39: 4.8 | AB39: 4 | AC39: 4 | AD39: 4.2 | AE39: 4.2 | AF39: 3.6 | AG39: 3.6 | AH39: 3.7 | AI39: 3.7 | AJ39: 3.6 | AK39: 3.6 | AL39: 3.7 | AM39: 3.7 | AN39: 3.4 | AO39: 3.4 | AP39: 3.5 | AQ39: 3.5
C40: Total Liabilities | D40: 136.6 | E40: 136.6 | F40: 186.5 | G40: 186.5 | H40: 60.3 | I40: 60.3 | J40: 56 | K40: 56 | L40: 55.6 | M40: 55.6 | N40: 53.7 | O40: 53.7 | P40: 56.1 | Q40: 56.1 | R40: 50.5 | S40: 50.5 | T40: 36 | U40: 36 | V40: 33.5 | W40: 33.5 | X40: 36.1 | Y40: 36.1 | Z40: 35.8 | AA40: 35.8 | AB40: 35.4 | AC40: 35.4 | AD40: 39.2 | AE40: 39.2 | AF40: 44.3 | AG40: 44.3 | AH40: 44.3 | AI40: 44.3 | AJ40: 37.2 | AK40: 37.2 | AL40: 37 | AM40: 37 | AN40: 47.2 | AO40: 47.2 | AP40: 44.9 | AQ40: 44.9
C42: Common Stock | D42: 14.6 | E42: 14.6 | F42: 14.6 | G42: 14.6 | H42: 14.6 | I42: 14.6 | J42: 14.6 | K42: 14.6 | L42: 14.6 | M42: 14.6 | N42: 14.6 | O42: 14.6 | P42: 14.6 | Q42: 14.6 | R42: 14.6 | S42: 14.6 | T42: 14.6 | U42: 14.6 | V42: 14.6 | W42: 14.6 | X42: 14.6 | Y42: 14.6 | Z42: 14.6 | AA42: 14.6 | AB42: 14.6 | AC42: 14.6 | AD42: 14.6 | AE42: 14.6 | AF42: 14.6 | AG42: 14.6 | AH42: 14.6 | AI42: 14.6 | AJ42: 14.6 | AK42: 14.6 | AL42: 14.6 | AM42: 14.6 | AN42: 14.6 | AO42: 14.6 | AP42: 14.6 | AQ42: 14.6
C43: Additional Paid In Capital
C44: Retained Earnings | D44: -32.9 | E44: -32.9 | F44: -30.7 | G44: -30.7 | H44: 52.6 | I44: 52.6 | J44: 56.3 | K44: 56.3 | L44: 62.3 | M44: 62.3 | N44: 69.2 | O44: 69.2 | P44: 71 | Q44: 71 | R44: 75.3 | S44: 75.3 | T44: 79.7 | U44: 79.7 | V44: 78.7 | W44: 78.7 | X44: 83 | Y44: 83 | Z44: 86.7 | AA44: 86.7 | AB44: 88.3 | AC44: 88.3 | AD44: 87.6 | AE44: 87.6 | AF44: 85.3 | AG44: 85.3 | AH44: 83.4 | AI44: 83.4 | AJ44: 81.3 | AK44: 81.3 | AL44: 78.1 | AM44: 78.1 | AN44: 73.6 | AO44: 73.6 | AP44: 68.9 | AQ44: 68.9
C45: Treasury Stock | D45: -0.1 | E45: -0.1 | H45: -0.2 | I45: -0.2 | J45: 0 | K45: 0 | L45: -0.1 | M45: -0.1 | R45: 0 | S45: 0 | T45: 0 | U45: 0 | V45: 0 | W45: 0 | X45: 0 | Y45: 0 | Z45: 0 | AA45: 0 | AB45: 0 | AC45: 0
C46: Other Common Equity Adj | D46: 83 | E46: 83 | F46: 69.4 | G46: 69.4 | H46: 66.2 | I46: 66.2 | J46: 37 | K46: 37 | L46: 40.5 | M46: 40.5 | N46: 37.5 | O46: 37.5 | P46: 37.9 | Q46: 37.9 | R46: 33.9 | S46: 33.9 | T46: 32.1 | U46: 32.1 | V46: 28.3 | W46: 28.3 | X46: 29 | Y46: 29 | Z46: 29.1 | AA46: 29.1 | AB46: 24.6 | AC46: 24.6 | AD46: 22.4 | AE46: 22.4 | AF46: 21.5 | AG46: 21.5 | AH46: 22.2 | AI46: 22.2 | AJ46: 18.5 | AK46: 18.5 | AL46: 20.9 | AM46: 20.9 | AN46: 19.9 | AO46: 19.9 | AP46: 17.7 | AQ46: 17.7
C47: Common Equity | D47: 64.6 | E47: 64.6 | F47: 53.3 | G47: 53.3 | H47: 133.2 | I47: 133.2 | J47: 107.8 | K47: 107.8 | L47: 117.3 | M47: 117.3 | N47: 121.4 | O47: 121.4 | P47: 123.5 | Q47: 123.5 | R47: 123.7 | S47: 123.7 | T47: 126.4 | U47: 126.4 | V47: 121.6 | W47: 121.6 | X47: 126.5 | Y47: 126.5 | Z47: 130.4 | AA47: 130.4 | AB47: 127.5 | AC47: 127.5 | AD47: 124.5 | AE47: 124.5 | AF47: 121.4 | AG47: 121.4 | AH47: 120.2 | AI47: 120.2 | AJ47: 114.5 | AK47: 114.5 | AL47: 113.6 | AM47: 113.6 | AN47: 108 | AO47: 108 | AP47: 101.2 | AQ47: 101.2
C48: Total Preferred Equity
C49: Minority Interest, Total
C50: Other Equity | D50: 0 | E50: 0 | F50: 0 | G50: 0 | H50: 0 | I50: 0 | J50: 0 | K50: 0 | L50: 0 | M50: 0 | N50: 0 | O50: 0 | P50: 0 | Q50: 0 | R50: 0 | S50: 0 | T50: 0 | U50: 0 | V50: 0 | W50: 0 | X50: 0 | Y50: 0 | Z50: 0 | AA50: 0 | AB50: 0 | AC50: 0 | AD50: 0 | AE50: 0 | AF50: 0 | AG50: 0 | AH50: 0 | AI50: 0 | AJ50: 0 | AK50: 0 | AL50: 0 | AM50: 0 | AN50: 0 | AO50: 0 | AP50: 0 | AQ50: 0
...
