Workbook

Sheet Overview
A1: Company | C1: =trilogiq_IS!C2 -> Trilogiq
A2: Industry | C2: Industrial equipment
A3: Ticker | C3: ALTRI
A4: Country | C4: Europe (Fr)
A5: Currency | C5: Euros
A6: Price (input) | C6: 5.1
A7: Market Cap (mm USD) | C7: 22.4
A8: P/NCAV | C8: =ncav!AQ46 -> 0.64788274
A9: Date Founded | C9: 1992
A10: Date Listed | C10: https://www.trilogiq.com/en-us
A11: Website

Sheet ncav
D1: 2015-06-30 | E1: 2015-09-30 | F1: 2015-12-31 | G1: 2016-03-31 | H1: 2016-06-30 | I1: 2016-09-30 | J1: 2016-12-31 | K1: 2017-03-31 | L1: 2017-06-30 | M1: 2017-09-30 | N1: 2017-12-31 | O1: 2018-03-31 | P1: 2018-06-30 | Q1: 2018-09-30 | R1: 2018-12-31 | S1: 2019-03-31 | T1: 2019-06-30 | U1: 2019-09-30 | V1: 2019-12-31 | W1: 2020-03-31 | X1: 2020-06-30 | Y1: 2020-09-30 | Z1: 2020-12-31 | AA1: 2021-03-31 | AB1: 2021-06-30 | AC1: 2021-09-30 | AD1: 2021-12-31 | AE1: 2022-03-31 | AF1: 2022-06-30 | AG1: 2022-09-30 | AH1: 2022-12-31 | AI1: 2023-03-31 | AJ1: 2023-06-30 | AK1: 2023-09-30 | AL1: 2023-12-31 | AM1: 2024-03-31 | AN1: 2024-06-30 | AO1: 2024-09-30 | AP1: 2024-12-31 | AQ1: 2025-03-31
A2: Cash & other liquid securities | D2: =_xlfn.NUMBERVALUE(trilogiq_bs!D12)+_xlfn.NUMBERVALUE(trilogiq_bs!D13) -> 20.4 | E2: =_xlfn.NUMBERVALUE(trilogiq_bs!E12)+_xlfn.NUMBERVALUE(trilogiq_bs!E13) -> 20.4 | F2: =_xlfn.NUMBERVALUE(trilogiq_bs!F12)+_xlfn.NUMBERVALUE(trilogiq_bs!F13) -> 20.6 | G2: =_xlfn.NUMBERVALUE(trilogiq_bs!G12)+_xlfn.NUMBERVALUE(trilogiq_bs!G13) -> 20.6 | H2: =_xlfn.NUMBERVALUE(trilogiq_bs!H12)+_xlfn.NUMBERVALUE(trilogiq_bs!H13) -> 20.2 | I2: =_xlfn.NUMBERVALUE(trilogiq_bs!I12)+_xlfn.NUMBERVALUE(trilogiq_bs!I13) -> 20.2 | J2: =_xlfn.NUMBERVALUE(trilogiq_bs!J12)+_xlfn.NUMBERVALUE(trilogiq_bs!J13) -> 17.6 | K2: =_xlfn.NUMBERVALUE(trilogiq_bs!K12)+_xlfn.NUMBERVALUE(trilogiq_bs!K13) -> 17.6 | ... AQ2: =_xlfn.NUMBERVALUE(trilogiq_bs!AQ12)+_xlfn.NUMBERVALUE(trilogiq_bs!AQ13) -> 25.2
A3: AR | C3: 0.8 | D3: =_xlfn.NUMBERVALUE(trilogiq_bs!D14) -> 12.8 | E3: =_xlfn.NUMBERVALUE(trilogiq_bs!E14) -> 12.8 | F3: =_xlfn.NUMBERVALUE(trilogiq_bs!F14) -> 9 | G3: =_xlfn.NUMBERVALUE(trilogiq_bs!G14) -> 9 | H3: =_xlfn.NUMBERVALUE(trilogiq_bs!H14) -> 8.2 | I3: =_xlfn.NUMBERVALUE(trilogiq_bs!I14) -> 8.2 | J3: =_xlfn.NUMBERVALUE(trilogiq_bs!J14) -> 7.8 | K3: =_xlfn.NUMBERVALUE(trilogiq_bs!K14) -> 7.8 | ... AQ3: =_xlfn.NUMBERVALUE(trilogiq_bs!AQ14) -> 4.1
A4: Inventory | C4: 0.6 | D4: =_xlfn.NUMBERVALUE(trilogiq_bs!D15) -> 9 | E4: =_xlfn.NUMBERVALUE(trilogiq_bs!E15) -> 9 | F4: =_xlfn.NUMBERVALUE(trilogiq_bs!F15) -> 7 | G4: =_xlfn.NUMBERVALUE(trilogiq_bs!G15) -> 7 | H4: =_xlfn.NUMBERVALUE(trilogiq_bs!H15) -> 7.6 | I4: =_xlfn.NUMBERVALUE(trilogiq_bs!I15) -> 7.6 | J4: =_xlfn.NUMBERVALUE(trilogiq_bs!J15) -> 7.2 | K4: =_xlfn.NUMBERVALUE(trilogiq_bs!K15) -> 7.2 | ... AQ4: =_xlfn.NUMBERVALUE(trilogiq_bs!AQ15) -> 4
A5: Current Assets | D5: =_xlfn.NUMBERVALUE(trilogiq_bs!D18) -> 45.6 | E5: =_xlfn.NUMBERVALUE(trilogiq_bs!E18) -> 45.6 | F5: =_xlfn.NUMBERVALUE(trilogiq_bs!F18) -> 41.1 | G5: =_xlfn.NUMBERVALUE(trilogiq_bs!G18) -> 41.1 | H5: =_xlfn.NUMBERVALUE(trilogiq_bs!H18) -> 40.5 | I5: =_xlfn.NUMBERVALUE(trilogiq_bs!I18) -> 40.5 | J5: =_xlfn.NUMBERVALUE(trilogiq_bs!J18) -> 36.7 | K5: =_xlfn.NUMBERVALUE(trilogiq_bs!K18) -> 36.7 | ... AQ5: =_xlfn.NUMBERVALUE(trilogiq_bs!AQ18) -> 34.7
A6: Discounted CA | D6: =D3*$C$3+$C$4*D4+D2 -> 36.04 | E6: =E3*$C$3+$C$4*E4+E2 -> 36.04 | F6: =F3*$C$3+$C$4*F4+F2 -> 32 | G6: =G3*$C$3+$C$4*G4+G2 -> 32 | H6: =H3*$C$3+$C$4*H4+H2 -> 31.32 | I6: =I3*$C$3+$C$4*I4+I2 -> 31.32 | J6: =J3*$C$3+$C$4*J4+J2 -> 28.16 | K6: =K3*$C$3+$C$4*K4+K2 -> 28.16 | ... AQ6: =AQ3*$C$3+$C$4*AQ4+AQ2 -> 30.88
A9: Total Assets | D9: =_xlfn.NUMBERVALUE(trilogiq_bs!D27) -> 66.9 | E9: =_xlfn.NUMBERVALUE(trilogiq_bs!E27) -> 66.9 | F9: =_xlfn.NUMBERVALUE(trilogiq_bs!F27) -> 63.3 | G9: =_xlfn.NUMBERVALUE(trilogiq_bs!G27) -> 63.3 | H9: =_xlfn.NUMBERVALUE(trilogiq_bs!H27) -> 63.2 | I9: =_xlfn.NUMBERVALUE(trilogiq_bs!I27) -> 63.2 | J9: =_xlfn.NUMBERVALUE(trilogiq_bs!J27) -> 60.1 | K9: =_xlfn.NUMBERVALUE(trilogiq_bs!K27) -> 60.1 | ... AQ9: =_xlfn.NUMBERVALUE(trilogiq_bs!AQ27) -> 42
A10: Intangible Assets | D10: =_xlfn.NUMBERVALUE(SUM(trilogiq_bs!D24:D25)) -> 0.2 | E10: =_xlfn.NUMBERVALUE(SUM(trilogiq_bs!E24:E25)) -> 0.2 | F10: =_xlfn.NUMBERVALUE(SUM(trilogiq_bs!F24:F25)) -> 0.2 | G10: =_xlfn.NUMBERVALUE(SUM(trilogiq_bs!G24:G25)) -> 0.2 | H10: =_xlfn.NUMBERVALUE(SUM(trilogiq_bs!H24:H25)) -> 0.2 | I10: =_xlfn.NUMBERVALUE(SUM(trilogiq_bs!I24:I25)) -> 0.2 | J10: =_xlfn.NUMBERVALUE(SUM(trilogiq_bs!J24:J25)) -> 0.6 | K10: =_xlfn.NUMBERVALUE(SUM(trilogiq_bs!K24:K25)) -> 0.6 | ... AQ10: =_xlfn.NUMBERVALUE(SUM(trilogiq_bs!AQ24:AQ25)) -> 0
A12: Current Liabilities | D12: =_xlfn.NUMBERVALUE(trilogiq_bs!D35) -> 10.4 | E12: =_xlfn.NUMBERVALUE(trilogiq_bs!E35) -> 10.4 | F12: =_xlfn.NUMBERVALUE(trilogiq_bs!F35) -> 7 | G12: =_xlfn.NUMBERVALUE(trilogiq_bs!G35) -> 7 | H12: =_xlfn.NUMBERVALUE(trilogiq_bs!H35) -> 6.2 | I12: =_xlfn.NUMBERVALUE(trilogiq_bs!I35) -> 6.2 | J12: =_xlfn.NUMBERVALUE(trilogiq_bs!J35) -> 5.2 | K12: =_xlfn.NUMBERVALUE(trilogiq_bs!K35) -> 5.2 | ... AQ12: =_xlfn.NUMBERVALUE(trilogiq_bs!AQ35) -> 1.7
A13: Total Liabilities | D13: =_xlfn.NUMBERVALUE(trilogiq_bs!D40) -> 10.8 | E13: =_xlfn.NUMBERVALUE(trilogiq_bs!E40) -> 10.8 | F13: =_xlfn.NUMBERVALUE(trilogiq_bs!F40) -> 7.6 | G13: =_xlfn.NUMBERVALUE(trilogiq_bs!G40) -> 7.6 | H13: =_xlfn.NUMBERVALUE(trilogiq_bs!H40) -> 8.1 | I13: =_xlfn.NUMBERVALUE(trilogiq_bs!I40) -> 8.1 | J13: =_xlfn.NUMBERVALUE(trilogiq_bs!J40) -> 7.2 | K13: =_xlfn.NUMBERVALUE(trilogiq_bs!K40) -> 7.2 | ... AQ13: =_xlfn.NUMBERVALUE(trilogiq_bs!AQ40) -> 4
A15: Debt | D15: =_xlfn.NUMBERVALUE(trilogiq_bs!D32)+_xlfn.NUMBERVALUE(trilogiq_bs!D37)+_xlfn.NUMBERVALUE(trilogiq_bs!D31) -> 0 | E15: =_xlfn.NUMBERVALUE(trilogiq_bs!E32)+_xlfn.NUMBERVALUE(trilogiq_bs!E37)+_xlfn.NUMBERVALUE(trilogiq_bs!E31) -> 0 | F15: =_xlfn.NUMBERVALUE(trilogiq_bs!F32)+_xlfn.NUMBERVALUE(trilogiq_bs!F37)+_xlfn.NUMBERVALUE(trilogiq_bs!F31) -> 0 | G15: =_xlfn.NUMBERVALUE(trilogiq_bs!G32)+_xlfn.NUMBERVALUE(trilogiq_bs!G37)+_xlfn.NUMBERVALUE(trilogiq_bs!G31) -> 0 | H15: =_xlfn.NUMBERVALUE(trilogiq_bs!H32)+_xlfn.NUMBERVALUE(trilogiq_bs!H37)+_xlfn.NUMBERVALUE(trilogiq_bs!H31) -> 1.4 | I15: =_xlfn.NUMBERVALUE(trilogiq_bs!I32)+_xlfn.NUMBERVALUE(trilogiq_bs!I37)+_xlfn.NUMBERVALUE(trilogiq_bs!I31) -> 1.4 | J15: =_xlfn.NUMBERVALUE(trilogiq_bs!J32)+_xlfn.NUMBERVALUE(trilogiq_bs!J37)+_xlfn.NUMBERVALUE(trilogiq_bs!J31) -> 1.6 | K15: =_xlfn.NUMBERVALUE(trilogiq_bs!K32)+_xlfn.NUMBERVALUE(trilogiq_bs!K37)+_xlfn.NUMBERVALUE(trilogiq_bs!K31) -> 1.6 | ... AQ15: =_xlfn.NUMBERVALUE(trilogiq_bs!AQ32)+_xlfn.NUMBERVALUE(trilogiq_bs!AQ37)+_xlfn.NUMBERVALUE(trilogiq_bs!AQ31) -> 0
A16: Equity | D16: =_xlfn.NUMBERVALUE(trilogiq_bs!D51) -> 56.1 | E16: =_xlfn.NUMBERVALUE(trilogiq_bs!E51) -> 56.1 | F16: =_xlfn.NUMBERVALUE(trilogiq_bs!F51) -> 55.8 | G16: =_xlfn.NUMBERVALUE(trilogiq_bs!G51) -> 55.8 | H16: =_xlfn.NUMBERVALUE(trilogiq_bs!H51) -> 55.1 | I16: =_xlfn.NUMBERVALUE(trilogiq_bs!I51) -> 55.1 | J16: =_xlfn.NUMBERVALUE(trilogiq_bs!J51) -> 52.9 | K16: =_xlfn.NUMBERVALUE(trilogiq_bs!K51) -> 52.9 | ... AQ16: =_xlfn.NUMBERVALUE(trilogiq_bs!AQ51) -> 37.9
A18: Net Tangible Assets | D18: =D9-D10-D13 -> 55.9 | E18: =E9-E10-E13 -> 55.9 | F18: =F9-F10-F13 -> 55.5 | G18: =G9-G10-G13 -> 55.5 | H18: =H9-H10-H13 -> 54.9 | I18: =I9-I10-I13 -> 54.9 | J18: =J9-J10-J13 -> 52.3 | K18: =K9-K10-K13 -> 52.3 | ... AQ18: =AQ9-AQ10-AQ13 -> 38
A20: Shares Outstanding | D20: =_xlfn.NUMBERVALUE(trilogiq_IS!D41) -> 3.4 | E20: =_xlfn.NUMBERVALUE(trilogiq_IS!E41) -> 3.4 | F20: =_xlfn.NUMBERVALUE(trilogiq_IS!F41) -> 3.5 | G20: =_xlfn.NUMBERVALUE(trilogiq_IS!G41) -> 3.5 | H20: =_xlfn.NUMBERVALUE(trilogiq_IS!H41) -> 3.6 | I20: =_xlfn.NUMBERVALUE(trilogiq_IS!I41) -> 3.6 | J20: =_xlfn.NUMBERVALUE(trilogiq_IS!J41) -> 3.8 | K20: =_xlfn.NUMBERVALUE(trilogiq_IS!K41) -> 3.8 | ... AQ20: =_xlfn.NUMBERVALUE(trilogiq_IS!AQ41) -> 3.9
A22: Net Cash | D22: =IF(D2-D13>0,D2-D13, "NA") -> 9.6 | E22: =IF(E2-E13>0,E2-E13, "NA") -> 9.6 | F22: =IF(F2-F13>0,F2-F13, "NA") -> 13 | G22: =IF(G2-G13>0,G2-G13, "NA") -> 13 | H22: =IF(H2-H13>0,H2-H13, "NA") -> 12.1 | I22: =IF(I2-I13>0,I2-I13, "NA") -> 12.1 | J22: =IF(J2-J13>0,J2-J13, "NA") -> 10.4 | K22: =IF(K2-K13>0,K2-K13, "NA") -> 10.4 | ... AQ22: =IF(AQ2-AQ13>0,AQ2-AQ13, "NA") -> 21.2
A23: Net Current Assets | D23: =D5-D13 -> 34.8 | E23: =E5-E13 -> 34.8 | F23: =F5-F13 -> 33.5 | G23: =G5-G13 -> 33.5 | H23: =H5-H13 -> 32.4 | I23: =I5-I13 -> 32.4 | J23: =J5-J13 -> 29.5 | K23: =K5-K13 -> 29.5 | ... AQ23: =AQ5-AQ13 -> 30.7
A24: Discounted Net Current Assets | D24: =D6-D13 -> 25.24 | E24: =E6-E13 -> 25.24 | F24: =F6-F13 -> 24.4 | G24: =G6-G13 -> 24.4 | H24: =H6-H13 -> 23.22 | I24: =I6-I13 -> 23.22 | J24: =J6-J13 -> 20.96 | K24: =K6-K13 -> 20.96 | ... AQ24: =AQ6-AQ13 -> 26.88
A26: Current Ratio | D26: =D5/D12 -> 4.3846154 | E26: =E5/E12 -> 4.3846154 | F26: =F5/F12 -> 5.8714286 | G26: =G5/G12 -> 5.8714286 | H26: =H5/H12 -> 6.5322581 | I26: =I5/I12 -> 6.5322581 | J26: =J5/J12 -> 7.0576923 | K26: =K5/K12 -> 7.0576923 | ... AQ26: =AQ5/AQ12 -> 20.411765
A27: 4 period ma | D27: =AVERAGE(D26:D26) -> 4.3846154 | E27: =AVERAGE(D26:E26) -> 4.3846154 | F27: =AVERAGE(D26:F26) -> 4.8802198 | G27: =AVERAGE(D26:G26) -> 5.128022 | H27: =AVERAGE(E26:H26) -> 5.6649326 | I27: =AVERAGE(F26:I26) -> 6.2018433 | J27: =AVERAGE(G26:J26) -> 6.4984093 | K27: =AVERAGE(H26:K26) -> 6.7949752 | L27: =AVERAGE(I26:L26) -> 6.8563551 | M27: =AVERAGE(J26:M26) -> 6.917735 | N27: =AVERAGE(K26:N26) -> 6.7905669 | ... AQ27: =AVERAGE(AN26:AQ26) -> 19.258514
A29: Net Tangible Assets / Share | D29: =D18/D20 -> 16.441176 | E29: =E18/E20 -> 16.441176 | F29: =F18/F20 -> 15.857143 | G29: =G18/G20 -> 15.857143 | H29: =H18/H20 -> 15.25 | I29: =I18/I20 -> 15.25 | J29: =J18/J20 -> 13.763158 | K29: =K18/K20 -> 13.763158 | ... AQ29: =AQ18/AQ20 -> 9.7435897
B30: % QoQ | E30: =E29/D29-1 -> 0 | F30: =F29/E29-1 -> -0.035522617 | G30: =G29/F29-1 -> 0 | H30: =H29/G29-1 -> -0.038288288 | I30: =I29/H29-1 -> 0 | J30: =J29/I29-1 -> -0.097497843 | K30: =K29/J29-1 -> 0 | L30: =L29/K29-1 -> -0.061340499 | ... W30: =W29/V29-1 -> 0 | X30: =X29/V29-1 -> -0.038461538 | Y30: =Y29/V29-1 -> -0.038461538 | Z30: =Z29/V29-1 -> #DIV/0! | AA30: =AA29/V29-1 -> #DIV/0! | AB30: =AB29/V29-1 -> -0.21098901 | AC30: =AC29/V29-1 -> -0.21098901 | AD30: =AD29/V29-1 -> #DIV/0! | AE30: =AE29/V29-1 -> #DIV/0! | AF30: =AF29/V29-1 -> -0.021681022 | AG30: =AG29/V29-1 -> -0.021681022 | AH30: =AH29/V29-1 -> -0.068247542 | AI30: =AI29/V29-1 -> -0.068247542 | AJ30: =AJ29/V29-1 -> -0.0578369 | AK30: =AK29/V29-1 -> -0.0578369 | AL30: =AL29/V29-1 -> 0.024725275 | AM30: =AM29/V29-1 -> 0.024725275 | AN30: =AN29/V29-1 -> 0.018414018 | AO30: =AO29/V29-1 -> 0.018414018 | AP30: =AP29/V29-1 -> -0.036348267 | AQ30: =AQ29/V29-1 -> -0.036348267
B31: % YoY | G31: =G29/D29-1 -> -0.035522617 | H31: =H29/E29-1 -> -0.072450805 | I31: =I29/F29-1 -> -0.038288288 | J31: =J29/G29-1 -> -0.13205311 | K31: =K29/H29-1 -> -0.097497843 | L31: =L29/I29-1 -> -0.15285778 | M31: =M29/J29-1 -> -0.061340499 | N31: =N29/K29-1 -> #DIV/0! | ... W31: =W29/T29-1 -> -0.054545455
A34: NCAV / Share | D34: =D23/D20 -> 10.235294 | E34: =E23/E20 -> 10.235294 | F34: =F23/F20 -> 9.5714286 | G34: =G23/G20 -> 9.5714286 | H34: =H23/H20 -> 9 | I34: =I23/I20 -> 9 | J34: =J23/J20 -> 7.7631579 | K34: =K23/K20 -> 7.7631579 | ... AQ34: =AQ23/AQ20 -> 7.8717949
B35: % QoQ | E35: =E34/D34-1 -> 0 | F35: =F34/E34-1 -> -0.064860427 | G35: =G34/F34-1 -> 0 | H35: =H34/G34-1 -> -0.059701493 | I35: =I34/H34-1 -> 0 | J35: =J34/I34-1 -> -0.1374269 | K35: =K34/J34-1 -> 0 | L35: =L34/K34-1 -> -0.077416399 | ... AQ35: =AQ34/AP34-1 -> 0
B36: % YoY | H36: =H34/D34-1 -> -0.12068966 | I36: =I34/E34-1 -> -0.12068966 | J36: =J34/F34-1 -> -0.1889238 | K36: =K34/G34-1 -> -0.1889238 | L36: =L34/H34-1 -> -0.2042042 | M36: =M34/I34-1 -> -0.2042042 | N36: =N34/J34-1 -> #DIV/0! | O36: =O34/K34-1 -> -0.15400825 | ... AQ36: =AQ34/AM34-1 -> -0.03610675
A38: Discounted NCAV / Share | D38: =D24/D20 -> 7.4235294 | E38: =E24/E20 -> 7.4235294 | F38: =F24/F20 -> 6.9714286 | G38: =G24/G20 -> 6.9714286 | H38: =H24/H20 -> 6.45 | I38: =I24/I20 -> 6.45 | J38: =J24/J20 -> 5.5157895 | K38: =K24/K20 -> 5.5157895 | ... AQ38: =AQ24/AQ20 -> 6.8923077
A41: Net Cash / Share | D41: =IFERROR(D22/D20, "NA") -> 2.8235294 | E41: =IFERROR(E22/E20, "NA") -> 2.8235294 | F41: =IFERROR(F22/F20, "NA") -> 3.7142857 | G41: =IFERROR(G22/G20, "NA") -> 3.7142857 | H41: =IFERROR(H22/H20, "NA") -> 3.3611111 | I41: =IFERROR(I22/I20, "NA") -> 3.3611111 | J41: =IFERROR(J22/J20, "NA") -> 2.7368421 | K41: =IFERROR(K22/K20, "NA") -> 2.7368421 | ... AQ41: =IFERROR(AQ22/AQ20, "NA") -> 5.4358974
B42: % QoQ | D42: =IFERROR(D41/#REF!-1, "NA") -> NA | E42: =IFERROR(E41/D41-1, "NA") -> 0 | F42: =IFERROR(F41/E41-1, "NA") -> 0.31547619 | G42: =IFERROR(G41/F41-1, "NA") -> 0 | H42: =IFERROR(H41/G41-1, "NA") -> -0.09508547 | I42: =IFERROR(I41/H41-1, "NA") -> 0 | J42: =IFERROR(J41/I41-1, "NA") -> -0.18573293 | K42: =IFERROR(K41/J41-1, "NA") -> 0 | L42: =IFERROR(L41/K41-1, "NA") -> -0.18035343 | ... AQ42: =IFERROR(AQ41/AP41-1, "NA") -> 0
A45: Price | AQ45: 5.1 | AR45: Buy below: | AS45: =W34*AS46 -> 4.4837222
A46: P / NCAV | AQ46: =AQ45/AQ34 -> 0.64788274 | AS46: 0.667
A47: P / Discounted NCAV | AQ47: =AQ45/AQ38 -> 0.73995536
A48: P / NTA | AQ48: =AQ45/AQ29 -> 0.52342105
A49: P / Net Cash | AQ49: =IFERROR(AQ45/AQ41, "NA") -> 0.93820755
A52: D / Assets | D52: =D15/D9 -> 0 | E52: =E15/E9 -> 0 | F52: =F15/F9 -> 0 | G52: =G15/G9 -> 0 | H52: =H15/H9 -> 0.022151899 | I52: =I15/I9 -> 0.022151899 | J52: =J15/J9 -> 0.026622296 | K52: =K15/K9 -> 0.026622296 | ... AQ52: =AQ15/AQ9 -> 0
A53: D / E | D53: =D15/D16 -> 0 | E53: =E15/E16 -> 0 | F53: =F15/F16 -> 0 | G53: =G15/G16 -> 0 | H53: =H15/H16 -> 0.025408348 | I53: =I15/I16 -> 0.025408348 | J53: =J15/J16 -> 0.030245747 | K53: =K15/K16 -> 0.030245747 | ... AQ53: =AQ15/AQ16 -> 0
A54: Total Liabilities / Equity | D54: =D13/D16 -> 0.19251337 | E54: =E13/E16 -> 0.19251337 | F54: =F13/F16 -> 0.13620072 | G54: =G13/G16 -> 0.13620072 | H54: =H13/H16 -> 0.14700544 | I54: =I13/I16 -> 0.14700544 | J54: =J13/J16 -> 0.13610586 | K54: =K13/K16 -> 0.13610586 | ... AQ54: =AQ13/AQ16 -> 0.1055409

Sheet profitability
C1: 2015-06-30 | D1: 2015-09-30 | E1: 2015-12-31 | F1: 2016-03-31 | G1: 2016-06-30 | H1: 2016-09-30 | I1: 2016-12-31 | J1: 2017-03-31 | K1: 2017-06-30 | L1: 2017-09-30 | M1: 2017-12-31 | N1: 2018-03-31 | O1: 2018-06-30 | P1: 2018-09-30 | Q1: 2018-12-31 | R1: 2019-03-31 | S1: 2019-06-30 | T1: 2019-09-30 | U1: 2019-12-31 | V1: 2020-03-31 | W1: 2020-06-30 | X1: 2020-09-30 | Y1: 2020-12-31 | Z1: 2021-03-31 | AA1: 2021-06-30 | AB1: 2021-09-30 | AC1: 2021-12-31 | AD1: 2022-03-31 | AE1: 2022-06-30 | AF1: 2022-09-30 | AG1: 2022-12-31 | AH1: 2023-03-31 | AI1: 2023-06-30 | AJ1: 2023-09-30 | AK1: 2023-12-31 | AL1: 2024-03-31 | AM1: 2024-06-30 | AN1: 2024-09-30 | AO1: 2024-12-31 | AP1: 2025-03-31
A2: Sales | C2: =_xlfn.NUMBERVALUE(trilogiq_IS!D12) -> 16.2 | D2: =_xlfn.NUMBERVALUE(trilogiq_IS!E12) -> 16.2 | E2: =_xlfn.NUMBERVALUE(trilogiq_IS!F12) -> 11.8 | F2: =_xlfn.NUMBERVALUE(trilogiq_IS!G12) -> 11.8 | G2: =_xlfn.NUMBERVALUE(trilogiq_IS!H12) -> 9.1 | H2: =_xlfn.NUMBERVALUE(trilogiq_IS!I12) -> 9.1 | I2: =_xlfn.NUMBERVALUE(trilogiq_IS!J12) -> 8.4 | J2: =_xlfn.NUMBERVALUE(trilogiq_IS!K12) -> 8.4 | ... AP2: =_xlfn.NUMBERVALUE(trilogiq_IS!AQ12) -> 5.5
B3: % QoQ | D3: =D2/C2-1 -> 0 | E3: =E2/D2-1 -> -0.27160494 | F3: =F2/E2-1 -> 0 | G3: =G2/F2-1 -> -0.22881356 | H3: =H2/G2-1 -> 0 | I3: =I2/H2-1 -> -0.076923077 | J3: =J2/I2-1 -> 0 | K3: =K2/J2-1 -> -0.035714286 | ... V3: =V2/U2-1 -> 0 | W3: =W2/U2-1 -> -0.074074074 | X3: =X2/U2-1 -> -0.074074074 | Y3: =Y2/U2-1 -> 0.16666667 | Z3: =Z2/U2-1 -> 0.16666667 | AA3: =AA2/U2-1 -> -0.018518519 | AB3: =AB2/U2-1 -> -0.018518519 | AC3: =AC2/U2-1 -> 0 | AD3: =AD2/U2-1 -> 0 | AE3: =AE2/U2-1 -> -0.018518519 | AF3: =AF2/U2-1 -> -0.018518519 | AG3: =AG2/U2-1 -> 0.074074074 | AH3: =AH2/U2-1 -> 0.074074074 | AI3: =AI2/U2-1 -> 0.037037037 | AJ3: =AJ2/U2-1 -> 0.037037037 | AK3: =AK2/U2-1 -> 0.18518519 | AL3: =AL2/U2-1 -> 0.18518519 | AM3: =AM2/U2-1 -> 0.12962963 | AN3: =AN2/U2-1 -> 0.12962963 | AO3: =AO2/U2-1 -> 0.018518519 | AP3: =AP2/U2-1 -> 0.018518519
B4: % YoY | G4: =G2/C2-1 -> -0.4382716 | H4: =H2/D2-1 -> -0.4382716 | I4: =I2/E2-1 -> -0.28813559 | J4: =J2/F2-1 -> -0.28813559 | K4: =K2/G2-1 -> -0.10989011 | L4: =L2/H2-1 -> -0.10989011 | M4: =M2/I2-1 -> 0.035714286 | N4: =N2/J2-1 -> 0.035714286 | ... V4: =V2/R2-1 -> -0.30769231 | W4: =W2/R2-1 -> -0.35897436 | X4: =X2/R2-1 -> -0.35897436 | Y4: =Y2/R2-1 -> -0.19230769 | Z4: =Z2/R2-1 -> -0.19230769 | AA4: =AA2/R2-1 -> -0.32051282 | AB4: =AB2/R2-1 -> -0.32051282 | AC4: =AC2/R2-1 -> -0.30769231 | AD4: =AD2/R2-1 -> -0.30769231 | AE4: =AE2/R2-1 -> -0.32051282 | AF4: =AF2/R2-1 -> -0.32051282 | AG4: =AG2/R2-1 -> -0.25641026 | AH4: =AH2/R2-1 -> -0.25641026 | AI4: =AI2/R2-1 -> -0.28205128 | AJ4: =AJ2/R2-1 -> -0.28205128 | AK4: =AK2/R2-1 -> -0.17948718 | AL4: =AL2/R2-1 -> -0.17948718 | AM4: =AM2/R2-1 -> -0.21794872 | AN4: =AN2/R2-1 -> -0.21794872 | AO4: =AO2/R2-1 -> -0.29487179 | AP4: =AP2/R2-1 -> -0.29487179
A6: Gross Income | C6: =_xlfn.NUMBERVALUE(trilogiq_IS!D16) -> 6.9 | D6: =_xlfn.NUMBERVALUE(trilogiq_IS!E16) -> 6.9 | E6: =_xlfn.NUMBERVALUE(trilogiq_IS!F16) -> 4.1 | F6: =_xlfn.NUMBERVALUE(trilogiq_IS!G16) -> 4.1 | G6: =_xlfn.NUMBERVALUE(trilogiq_IS!H16) -> 3.5 | H6: =_xlfn.NUMBERVALUE(trilogiq_IS!I16) -> 3.5 | I6: =_xlfn.NUMBERVALUE(trilogiq_IS!J16) -> 2.5 | J6: =_xlfn.NUMBERVALUE(trilogiq_IS!K16) -> 2.5 | ... V6: =_xlfn.NUMBERVALUE(trilogiq_IS!W16) -> 1.9 | W6: =_xlfn.NUMBERVALUE(trilogiq_IS!W16) -> 1.9 | X6: =_xlfn.NUMBERVALUE(trilogiq_IS!X16) -> 2.1 | Y6: =_xlfn.NUMBERVALUE(trilogiq_IS!Y16) -> 2.1 | Z6: =_xlfn.NUMBERVALUE(trilogiq_IS!Z16) -> 2.6 | AA6: =_xlfn.NUMBERVALUE(trilogiq_IS!AA16) -> 2.6 | AB6: =_xlfn.NUMBERVALUE(trilogiq_IS!AB16) -> 3.1 | AC6: =_xlfn.NUMBERVALUE(trilogiq_IS!AC16) -> 3.1 | AD6: =_xlfn.NUMBERVALUE(trilogiq_IS!AD16) -> 2 | ... AP6: =_xlfn.NUMBERVALUE(trilogiq_IS!AP16) -> 3.5
B7: % Margin | C7: =C6/C2 -> 0.42592593 | D7: =D6/D2 -> 0.42592593 | E7: =E6/E2 -> 0.34745763 | F7: =F6/F2 -> 0.34745763 | G7: =G6/G2 -> 0.38461538 | H7: =H6/H2 -> 0.38461538 | I7: =I6/I2 -> 0.29761905 | J7: =J6/J2 -> 0.29761905 | ... AP7: =AP6/AP2 -> 0.63636364
B8: % Margin 4 per MA | C8: =AVERAGE(C7:C7) -> 0.42592593 | D8: =AVERAGE(C7:D7) -> 0.42592593 | E8: =AVERAGE(C7:E7) -> 0.39976983 | F8: =AVERAGE(C7:F7) -> 0.38669178 | G8: =AVERAGE(D7:G7) -> 0.37636414 | H8: =AVERAGE(E7:H7) -> 0.36603651 | I8: =AVERAGE(F7:I7) -> 0.35357686 | J8: =AVERAGE(G7:J7) -> 0.34111722 | K8: =AVERAGE(H7:K7) -> 0.31903744 | L8: =AVERAGE(I7:L7) -> 0.29695767 | M8: =AVERAGE(J7:M7) -> 0.22830004 | ... V8: =AVERAGE(S7:V7) -> 0.35846561 | W8: =AVERAGE(S7:W7) -> 0.36277249 | X8: =AVERAGE(S7:X7) -> 0.37231041 | Y8: =AVERAGE(S7:Y7) -> 0.36674225 | Z8: =AVERAGE(S7:Z7) -> 0.37248677 | AA8: =AVERAGE(S7:AA7) -> 0.38560669 | AB8: =AVERAGE(S7:AB7) -> 0.40553659 | AC8: =AVERAGE(S7:AC7) -> 0.42085818 | AD8: =AVERAGE(S7:AD7) -> 0.41665086 | AE8: =AVERAGE(S7:AE7) -> 0.41362837 | AF8: =AVERAGE(S7:AF7) -> 0.42721017 | AG8: =AVERAGE(S7:AG7) -> 0.4355111 | AH8: =AVERAGE(S7:AH7) -> 0.44277442 | AI8: =AVERAGE(S7:AI7) -> 0.45034231 | AJ8: =AVERAGE(S7:AJ7) -> 0.45806139 | AK8: =AVERAGE(S7:AK7) -> 0.46109105 | AL8: =AVERAGE(S7:AL7) -> 0.47006775 | AM8: =AVERAGE(S7:AM7) -> 0.47968981 | AN8: =AVERAGE(S7:AN7) -> 0.48694683 | AO8: =AVERAGE(S7:AO7) -> 0.49660527 | AP8: =AVERAGE(S7:AP7) -> 0.50242854
A10: Net Income | C10: =_xlfn.NUMBERVALUE(trilogiq_IS!D32) -> -0.1 | D10: =_xlfn.NUMBERVALUE(trilogiq_IS!E32) -> -0.1 | E10: =_xlfn.NUMBERVALUE(trilogiq_IS!F32) -> 0 | F10: =_xlfn.NUMBERVALUE(trilogiq_IS!G32) -> 0 | G10: =_xlfn.NUMBERVALUE(trilogiq_IS!H32) -> 0 | H10: =_xlfn.NUMBERVALUE(trilogiq_IS!I32) -> 0 | I10: =_xlfn.NUMBERVALUE(trilogiq_IS!J32) -> 0 | J10: =_xlfn.NUMBERVALUE(trilogiq_IS!K32) -> 0 | ... V10: =_xlfn.NUMBERVALUE(trilogiq_IS!W32) -> 0 | W10: =_xlfn.NUMBERVALUE(trilogiq_IS!W32) -> 0 | X10: =_xlfn.NUMBERVALUE(trilogiq_IS!X32) -> 0 | Y10: =_xlfn.NUMBERVALUE(trilogiq_IS!Y32) -> 0 | Z10: =_xlfn.NUMBERVALUE(trilogiq_IS!Z32) -> 0 | AA10: =_xlfn.NUMBERVALUE(trilogiq_IS!AA32) -> 0 | AB10: =_xlfn.NUMBERVALUE(trilogiq_IS!AB32) -> 0 | AC10: =_xlfn.NUMBERVALUE(trilogiq_IS!AC32) -> 0 | AD10: =_xlfn.NUMBERVALUE(trilogiq_IS!AD33) -> 0.2 | AE10: =_xlfn.NUMBERVALUE(trilogiq_IS!AE33) -> 0.2 | AF10: =_xlfn.NUMBERVALUE(trilogiq_IS!AF33) -> -0.1 | AG10: =_xlfn.NUMBERVALUE(trilogiq_IS!AG33) -> -0.1 | AH10: =_xlfn.NUMBERVALUE(trilogiq_IS!AH33) -> -0.2 | AI10: =_xlfn.NUMBERVALUE(trilogiq_IS!AI33) -> -0.2 | AJ10: =_xlfn.NUMBERVALUE(trilogiq_IS!AJ33) -> 0.2 | AK10: =_xlfn.NUMBERVALUE(trilogiq_IS!AK33) -> 0.2 | ... AP10: =_xlfn.NUMBERVALUE(trilogiq_IS!AP33) -> -0.1
B11: % Margin | C11: =C10/C2 -> -0.0061728395 | D11: =D10/D2 -> -0.0061728395 | E11: =E10/E2 -> 0 | F11: =F10/F2 -> 0 | G11: =G10/G2 -> 0 | H11: =H10/H2 -> 0 | I11: =I10/I2 -> 0 | J11: =J10/J2 -> 0 | ... AP11: =AP10/AP2 -> -0.018181818

Sheet piotrosky
A1: 1 | B1: Positive earnings | K1: 1 | L1: AUTO: NI = -91 (negative/zero)
A2: =A1+1 -> 2 | B2: Positive CF | K2: 1 | L2: MANUAL: OCF data not available in standard export
A3: =A2+1 -> 3 | B3: Increasing ROA | K3: 0 | L3: AUTO: ROA: 0.54% -> 1.92% (↑)
A4: =A3+1 -> 4 | B4: Increasing CFO | K4: 0 | L4: MANUAL: OCF data not available for accruals check
A5: =A4+1 -> 5 | B5: Decreasing long term debt as a proportion of total assets | K5: 1 | L5: AUTO: D/A: 1.56% -> 1.39% (↓)
A6: =A5+1 -> 6 | B6: increasing current ratio | K6: 1 | L6: AUTO: CR: 7.11x -> 6.55x (↓)
A7: =A6+1 -> 7 | B7: decreasing or stable numbers of standing shares | K7: 1 | L7: AUTO: Shares: 7 -> 7 (stable/↓)
A8: =A7+1 -> 8 | B8: increasing assets turnover (increasing sales as a proportion of total assets) | K8: 0 | L8: AUTO: AT: 0.68x -> 0.60x (↓)
A9: =A8+1 -> 9 | B9: increasing gross margin | K9: 1 | L9: AUTO: GM: 39.6% -> 41.0% (↑)
A10: Piotrosky score | K10: =SUM(K1:K9) -> 6 | L10: =SUM(L1:L9) -> 0 | M10: =SUM(M1:M9) -> 0 | N10: =SUM(N1:N9) -> 0 | O10: =SUM(O1:O9) -> 0 | P10: =SUM(P1:P9) -> 0 | Q10: =SUM(Q1:Q9) -> 0 | R10: =SUM(R1:R9) -> 0 | ... AQ10: =SUM(AQ1:AQ9) -> 0

Sheet C7
A1: Core 9 Criteria
A2: Not Majority Chinese | H2: 1 | I2: MANUAL: Check company domicile manually
A3: Low Price-to-NACV (less than 67%) | H3: 1 | I3: AUTO: P/NCAV = 0.97 (threshold: 0.67)
A4: Low Debt-to-Equity | H4: 1 | I4: AUTO: D/E = 0.02 (threshold: 0.5)
A5: Adequate Past Earnings or Catalyst (5%+ NI Margin) | H5: 1 | I5: AUTO: Max NI margin = 11.7% (threshold: 5%)
A6: Past Price Above NCAV | H6: 1 | I6: MANUAL: Requires historical price data
A7: Existing Operations or Liquidation | H7: 1 | I7: MANUAL: Qualitative assessment required
A8: Not Selling Shares | H8: 1 | I8: AUTO: Shares: 7 -> 7
A9: Market Cap <$50mm | H9: 1 | I9: MANUAL: Market cap = 10,650 (currency/unit check needed)
A10: Low NCAV Burn Rate | H10: 1 | I10: AUTO: Calculated NCAV YoY: -5.9%
A11: Total | H11: =SUM(H2:H10) -> 9 | I11: =SUM(I2:I10) -> 0 | J11: =SUM(J2:J10) -> 0 | K11: =SUM(K2:K10) -> 0 | L11: =SUM(L2:L10) -> 0 | M11: =SUM(M2:M10) -> 0 | N11: =SUM(N2:N10) -> 0 | O11: =SUM(O2:O10) -> 0 | ... AQ11: =SUM(AQ2:AQ10) -> 0
A13: Ranking Criteria (out of 9)
A14: Large Current Ratio (over 1.5x) | H14: 1 | I14: AUTO: CR = 6.55x (threshold: 1.5x)
A15: Not financial/real estate/closed end fund | H15: 1 | I15: MANUAL: Check industry classification manually
A16: Company is buying back stock | H16: 0 | I16: AUTO: Shares: 7 -> 7 (no buyback)
A17: Low Price-to-Net Cash | H17: 1 | I17: MANUAL: Net cash calculation requires manual review
A18: Insider Ownership | H18: 1 | I18: MANUAL: Check ownership sheet manually
A19: Insider Buys vs. Sells | H19: 0 | I19: MANUAL: Requires insider transaction data
A20: Burn Rate Low or Positive | H20: 1 | I20: AUTO: NCAV YoY: -5.9%
A21: Insider Pay | H21: 1 | I21: MANUAL: Qualitative assessment required
A22: Dividend Yield? | H22: 1 | I22: MANUAL: Requires dividend and price data
A23: Total | H23: =SUM(H14:H22) -> 7

Sheet ro
C1: 2015-06-30 | D1: 2015-09-30 | E1: 2015-12-31 | F1: 2016-03-31 | G1: 2016-06-30 | H1: 2016-09-30 | I1: 2016-12-31 | J1: 2017-03-31 | K1: 2017-06-30 | L1: 2017-09-30 | M1: 2017-12-31 | N1: 2018-03-31 | O1: 2018-06-30 | P1: 2018-09-30 | Q1: 2018-12-31 | R1: 2019-03-31 | S1: 2019-06-30 | T1: 2019-09-30 | U1: 2019-12-31 | V1: 2020-03-31 | W1: 2020-06-30 | X1: 2020-09-30 | Y1: 2020-12-31 | Z1: 2021-03-31 | AA1: 2021-06-30 | AB1: 2021-09-30 | AC1: 2021-12-31 | AD1: 2022-03-31 | AE1: 2022-06-30 | AF1: 2022-09-30 | AG1: 2022-12-31 | AH1: 2023-03-31 | AI1: 2023-06-30 | AJ1: 2023-09-30 | AK1: 2023-12-31 | AL1: 2024-03-31 | AM1: 2024-06-30 | AN1: 2024-09-30 | AO1: 2024-12-31 | AP1: 2025-03-31
A2: Total Assets | C2: =_xlfn.NUMBERVALUE(trilogiq_bs!D27) -> 66.9 | D2: =_xlfn.NUMBERVALUE(trilogiq_bs!E27) -> 66.9 | E2: =_xlfn.NUMBERVALUE(trilogiq_bs!F27) -> 63.3 | F2: =_xlfn.NUMBERVALUE(trilogiq_bs!G27) -> 63.3 | G2: =_xlfn.NUMBERVALUE(trilogiq_bs!H27) -> 63.2 | H2: =_xlfn.NUMBERVALUE(trilogiq_bs!I27) -> 63.2 | I2: =_xlfn.NUMBERVALUE(trilogiq_bs!J27) -> 60.1 | J2: =_xlfn.NUMBERVALUE(trilogiq_bs!K27) -> 60.1 | ... V2: =_xlfn.NUMBERVALUE(trilogiq_bs!W27) -> 40.8 | W2: =_xlfn.NUMBERVALUE(trilogiq_bs!W27) -> 40.8 | X2: =_xlfn.NUMBERVALUE(trilogiq_bs!X27) -> 39.7 | Y2: =_xlfn.NUMBERVALUE(trilogiq_bs!Y27) -> 39.7 | Z2: =_xlfn.NUMBERVALUE(trilogiq_bs!Z27) -> 0 | AA2: =_xlfn.NUMBERVALUE(trilogiq_bs!AA27) -> 0 | AB2: =_xlfn.NUMBERVALUE(trilogiq_bs!AB27) -> 40 | AC2: =_xlfn.NUMBERVALUE(trilogiq_bs!AC27) -> 40 | AD2: =_xlfn.NUMBERVALUE(trilogiq_bs!AD27) -> 0 | ... AP2: =_xlfn.NUMBERVALUE(trilogiq_bs!AP27) -> 42
A3: 1 yr avg | D3: =AVERAGE(C2:D2) -> 66.9 | E3: =AVERAGE(D2:E2) -> 65.1 | F3: =AVERAGE(E2:F2) -> 63.3 | G3: =AVERAGE(F2:G2) -> 63.25 | H3: =AVERAGE(G2:H2) -> 63.2 | I3: =AVERAGE(H2:I2) -> 61.65 | J3: =AVERAGE(I2:J2) -> 60.1 | K3: =AVERAGE(J2:K2) -> 59.5 | ... V3: =AVERAGE(U2:V2) -> 40.8 | W3: =AVERAGE(U2:W2) -> 40.8 | X3: =AVERAGE(U2:X2) -> 40.525 | Y3: =AVERAGE(U2:Y2) -> 40.36 | Z3: =AVERAGE(U2:Z2) -> 33.633333 | AA3: =AVERAGE(U2:AA2) -> 28.828571 | AB3: =AVERAGE(U2:AB2) -> 30.225 | AC3: =AVERAGE(U2:AC2) -> 31.311111 | AD3: =AVERAGE(U2:AD2) -> 28.18 | AE3: =AVERAGE(U2:AE2) -> 25.618182 | AF3: =AVERAGE(U2:AF2) -> 26.875 | AG3: =AVERAGE(U2:AG2) -> 27.938462 | AH3: =AVERAGE(U2:AH2) -> 28.785714 | AI3: =AVERAGE(U2:AI2) -> 29.52 | AJ3: =AVERAGE(U2:AJ2) -> 30.1875 | AK3: =AVERAGE(U2:AK2) -> 30.776471 | AL3: =AVERAGE(U2:AL2) -> 31.394444 | AM3: =AVERAGE(U2:AM2) -> 31.947368 | AN3: =AVERAGE(U2:AN2) -> 32.45 | AO3: =AVERAGE(U2:AO2) -> 32.904762 | AP3: =AVERAGE(U2:AP2) -> 33.318182
A5: Total Equity | C5: =_xlfn.NUMBERVALUE(trilogiq_bs!D51) -> 56.1 | D5: =_xlfn.NUMBERVALUE(trilogiq_bs!E51) -> 56.1 | E5: =_xlfn.NUMBERVALUE(trilogiq_bs!F51) -> 55.8 | F5: =_xlfn.NUMBERVALUE(trilogiq_bs!G51) -> 55.8 | G5: =_xlfn.NUMBERVALUE(trilogiq_bs!H51) -> 55.1 | H5: =_xlfn.NUMBERVALUE(trilogiq_bs!I51) -> 55.1 | I5: =_xlfn.NUMBERVALUE(trilogiq_bs!J51) -> 52.9 | J5: =_xlfn.NUMBERVALUE(trilogiq_bs!K51) -> 52.9 | ... V5: =_xlfn.NUMBERVALUE(trilogiq_bs!W51) -> 36.4 | W5: =_xlfn.NUMBERVALUE(trilogiq_bs!W51) -> 36.4 | X5: =_xlfn.NUMBERVALUE(trilogiq_bs!X51) -> 35.1 | Y5: =_xlfn.NUMBERVALUE(trilogiq_bs!Y51) -> 35.1 | Z5: =_xlfn.NUMBERVALUE(trilogiq_bs!Z51) -> 35.1 | AA5: =_xlfn.NUMBERVALUE(trilogiq_bs!AA51) -> 0 | AB5: =_xlfn.NUMBERVALUE(trilogiq_bs!AB51) -> 35.8 | AC5: =_xlfn.NUMBERVALUE(trilogiq_bs!AC51) -> 35.8 | AD5: =_xlfn.NUMBERVALUE(trilogiq_bs!AD51) -> 35.8 | ... AP5: =_xlfn.NUMBERVALUE(trilogiq_bs!AP51) -> 37.9
A6: 1 yr avg | D6: =AVERAGE(C5:D5) -> 56.1 | E6: =AVERAGE(D5:E5) -> 55.95 | F6: =AVERAGE(E5:F5) -> 55.8 | G6: =AVERAGE(F5:G5) -> 55.45 | H6: =AVERAGE(G5:H5) -> 55.1 | I6: =AVERAGE(H5:I5) -> 54 | J6: =AVERAGE(I5:J5) -> 52.9 | K6: =AVERAGE(J5:K5) -> 50.85 | ... V6: =AVERAGE(U5:V5) -> 36.4 | W6: =AVERAGE(U5:W5) -> 36.4 | X6: =AVERAGE(U5:X5) -> 36.075 | Y6: =AVERAGE(U5:Y5) -> 35.88 | Z6: =AVERAGE(U5:Z5) -> 35.75 | AA6: =AVERAGE(U5:AA5) -> 30.642857 | AB6: =AVERAGE(U5:AB5) -> 31.2875 | AC6: =AVERAGE(U5:AC5) -> 31.788889 | AD6: =AVERAGE(U5:AD5) -> 32.19 | AE6: =AVERAGE(U5:AE5) -> 29.263636 | AF6: =AVERAGE(U5:AF5) -> 29.875 | AG6: =AVERAGE(U5:AG5) -> 30.392308 | AH6: =AVERAGE(U5:AH5) -> 30.778571 | AI6: =AVERAGE(U5:AI5) -> 31.113333 | AJ6: =AVERAGE(U5:AJ5) -> 31.43125 | AK6: =AVERAGE(U5:AK5) -> 31.711765 | AL6: =AVERAGE(U5:AL5) -> 32.027778 | AM6: =AVERAGE(U5:AM5) -> 32.310526 | AN6: =AVERAGE(U5:AN5) -> 32.6 | AO6: =AVERAGE(U5:AO5) -> 32.861905 | AP6: =AVERAGE(U5:AP5) -> 33.090909
A8: Sales | C8: =_xlfn.NUMBERVALUE(trilogiq_IS!D12) -> 16.2 | D8: =_xlfn.NUMBERVALUE(trilogiq_IS!E12) -> 16.2 | E8: =_xlfn.NUMBERVALUE(trilogiq_IS!F12) -> 11.8 | F8: =_xlfn.NUMBERVALUE(trilogiq_IS!G12) -> 11.8 | G8: =_xlfn.NUMBERVALUE(trilogiq_IS!H12) -> 9.1 | H8: =_xlfn.NUMBERVALUE(trilogiq_IS!I12) -> 9.1 | I8: =_xlfn.NUMBERVALUE(trilogiq_IS!J12) -> 8.4 | J8: =_xlfn.NUMBERVALUE(trilogiq_IS!K12) -> 8.4 | ... V8: =_xlfn.NUMBERVALUE(trilogiq_IS!W12) -> 5.4 | W8: =_xlfn.NUMBERVALUE(trilogiq_IS!W12) -> 5.4 | X8: =_xlfn.NUMBERVALUE(trilogiq_IS!X12) -> 5 | Y8: =_xlfn.NUMBERVALUE(trilogiq_IS!Y12) -> 5 | Z8: =_xlfn.NUMBERVALUE(trilogiq_IS!Z12) -> 6.3 | AA8: =_xlfn.NUMBERVALUE(trilogiq_IS!AA12) -> 6.3 | AB8: =_xlfn.NUMBERVALUE(trilogiq_IS!AB12) -> 5.3 | AC8: =_xlfn.NUMBERVALUE(trilogiq_IS!AC12) -> 5.3 | AD8: =_xlfn.NUMBERVALUE(trilogiq_IS!AD12) -> 5.4 | ... AP8: =_xlfn.NUMBERVALUE(trilogiq_IS!AP12) -> 5.5
A9: EBIT | C9: =_xlfn.NUMBERVALUE(trilogiq_IS!D24) -> 1.1 | D9: =_xlfn.NUMBERVALUE(trilogiq_IS!E43) -> 1.9 | E9: =_xlfn.NUMBERVALUE(trilogiq_IS!F43) -> 0.1 | F9: =_xlfn.NUMBERVALUE(trilogiq_IS!G43) -> 0.1 | G9: =_xlfn.NUMBERVALUE(trilogiq_IS!H43) -> 0.5 | H9: =_xlfn.NUMBERVALUE(trilogiq_IS!I43) -> 0.5 | I9: =_xlfn.NUMBERVALUE(trilogiq_IS!J43) -> -0.5 | J9: =_xlfn.NUMBERVALUE(trilogiq_IS!K43) -> -0.5 | K9: =_xlfn.NUMBERVALUE(trilogiq_IS!L43) -> -0.5 | ... V9: =_xlfn.NUMBERVALUE(trilogiq_IS!W43) -> 0 | W9: =_xlfn.NUMBERVALUE(trilogiq_IS!W43) -> 0 | X9: =_xlfn.NUMBERVALUE(trilogiq_IS!X43) -> 0.3 | Y9: =_xlfn.NUMBERVALUE(trilogiq_IS!Y43) -> 0.3 | Z9: =_xlfn.NUMBERVALUE(trilogiq_IS!Z43) -> 0.7 | AA9: =_xlfn.NUMBERVALUE(trilogiq_IS!AA43) -> 0.7 | AB9: =_xlfn.NUMBERVALUE(trilogiq_IS!AB43) -> 0.5 | AC9: =_xlfn.NUMBERVALUE(trilogiq_IS!AC43) -> 0.5 | AD9: =_xlfn.NUMBERVALUE(trilogiq_IS!AD43) -> 0.3 | ... AP9: =_xlfn.NUMBERVALUE(trilogiq_IS!AP43) -> 0
A10: NI | C10: =_xlfn.NUMBERVALUE(trilogiq_IS!D33) -> 0.7 | D10: =_xlfn.NUMBERVALUE(trilogiq_IS!E32) -> -0.1 | E10: =_xlfn.NUMBERVALUE(trilogiq_IS!F32) -> 0 | F10: =_xlfn.NUMBERVALUE(trilogiq_IS!G32) -> 0 | G10: =_xlfn.NUMBERVALUE(trilogiq_IS!H32) -> 0 | H10: =_xlfn.NUMBERVALUE(trilogiq_IS!I32) -> 0 | I10: =_xlfn.NUMBERVALUE(trilogiq_IS!J32) -> 0 | J10: =_xlfn.NUMBERVALUE(trilogiq_IS!K32) -> 0 | K10: =_xlfn.NUMBERVALUE(trilogiq_IS!L32) -> 0 | ... V10: =_xlfn.NUMBERVALUE(trilogiq_IS!W32) -> 0 | W10: =_xlfn.NUMBERVALUE(trilogiq_IS!W32) -> 0 | X10: =_xlfn.NUMBERVALUE(trilogiq_IS!X32) -> 0 | Y10: =_xlfn.NUMBERVALUE(trilogiq_IS!Y32) -> 0 | Z10: =_xlfn.NUMBERVALUE(trilogiq_IS!Z32) -> 0 | AA10: =_xlfn.NUMBERVALUE(trilogiq_IS!AA32) -> 0 | AB10: =_xlfn.NUMBERVALUE(trilogiq_IS!AB32) -> 0 | AC10: =_xlfn.NUMBERVALUE(trilogiq_IS!AC32) -> 0 | AD10: =_xlfn.NUMBERVALUE(trilogiq_IS!AD32) -> 0 | ... AP10: =_xlfn.NUMBERVALUE(trilogiq_IS!AP32) -> 0
A12: Semi-Annually
A13: ROA (EBIT) | D13: =D9/D3 -> 0.028400598 | E13: =E9/E3 -> 0.0015360983 | F13: =F9/F3 -> 0.0015797788 | G13: =G9/G3 -> 0.0079051383 | H13: =H9/H3 -> 0.0079113924 | I13: =I9/I3 -> -0.0081103001 | J13: =J9/J3 -> -0.0083194676 | K13: =K9/K3 -> -0.0084033613 | ... AP13: =AP9/AP3 -> 0
A14: ROA (NI) | D14: =D10/D3 -> -0.0014947683 | E14: =E10/E3 -> 0 | F14: =F10/F3 -> 0 | G14: =G10/G3 -> 0 | H14: =H10/H3 -> 0 | I14: =I10/I3 -> 0 | J14: =J10/J3 -> 0 | K14: =K10/K3 -> 0 | ... AP14: =AP10/AP3 -> 0
A16: ROE (EBIT) | D16: =D9/D6 -> 0.033868093 | E16: =E9/E6 -> 0.0017873101 | F16: =F9/F6 -> 0.0017921147 | G16: =G9/G6 -> 0.0090171326 | H16: =H9/H6 -> 0.0090744102 | I16: =I9/I6 -> -0.0092592593 | J16: =J9/J6 -> -0.0094517958 | K16: =K9/K6 -> -0.0098328417 | ... AP16: =AP9/AP6 -> 0
A17: ROE (NI) | D17: =D10/D6 -> -0.0017825312 | E17: =E10/E6 -> 0 | F17: =F10/F6 -> 0 | G17: =G10/G6 -> 0 | H17: =H10/H6 -> 0 | I17: =I10/I6 -> 0 | J17: =J10/J6 -> 0 | K17: =K10/K6 -> 0 | ... AP17: =AP10/AP6 -> 0
A19: Annualized
A20: ROA (EBIT) | D20: =D13*2 -> 0.056801196 | E20: =E13*2 -> 0.0030721966 | F20: =F13*2 -> 0.0031595577 | G20: =G13*2 -> 0.015810277 | H20: =H13*2 -> 0.015822785 | I20: =I13*2 -> -0.0162206 | J20: =J13*2 -> -0.016638935 | K20: =K13*2 -> -0.016806723 | ... AP20: =AP13*2 -> 0
A21: ROA (NI) | D21: =D14*2 -> -0.0029895366 | E21: =E14*2 -> 0 | F21: =F14*2 -> 0 | G21: =G14*2 -> 0 | H21: =H14*2 -> 0 | I21: =I14*2 -> 0 | J21: =J14*2 -> 0 | K21: =K14*2 -> 0 | ... V21: =V14*2 -> 0
A23: ROE (EBIT) | D23: =D16*2 -> 0.067736185 | E23: =E16*2 -> 0.0035746202 | F23: =F16*2 -> 0.0035842294 | G23: =G16*2 -> 0.018034265 | H23: =H16*2 -> 0.01814882 | I23: =I16*2 -> -0.018518519 | J23: =J16*2 -> -0.018903592 | K23: =K16*2 -> -0.019665683 | ... AP23: =AP16*2 -> 0
A24: ROE (NI) | D24: =D17*2 -> -0.0035650624 | E24: =E17*2 -> 0 | F24: =F17*2 -> 0 | G24: =G17*2 -> 0 | H24: =H17*2 -> 0 | I24: =I17*2 -> 0 | J24: =J17*2 -> 0 | K24: =K17*2 -> 0 | ... AP24: =AP17*2 -> 0
A26: TTM
A27: ROA (EBIT) | G27: =SUM(F9:G9)/AVERAGE(E2,G2) -> 0.009486166 | H27: =SUM(G9:H9)/AVERAGE(F2,H2) -> 0.015810277 | I27: =SUM(H9:I9)/AVERAGE(G2,I2) -> 0 | J27: =SUM(I9:J9)/AVERAGE(H2,J2) -> -0.0162206 | K27: =SUM(J9:K9)/AVERAGE(I2,K2) -> -0.016806723 | L27: =SUM(K9:L9)/AVERAGE(J2,L2) -> -0.016806723 | M27: =SUM(L9:M9)/AVERAGE(K2,M2) -> -0.003606853 | N27: =SUM(M9:N9)/AVERAGE(L2,N2) -> 0.010820559 | ... AP27: =SUM(AO9:AP9)/AVERAGE(AN2,AP2) -> 0.011904762
A28: ROA (NI) | G28: =SUM(F10:G10)/AVERAGE(E2,G2) -> 0 | H28: =SUM(G10:H10)/AVERAGE(F2,H2) -> 0 | I28: =SUM(H10:I10)/AVERAGE(G2,I2) -> 0 | J28: =SUM(I10:J10)/AVERAGE(H2,J2) -> 0 | K28: =SUM(J10:K10)/AVERAGE(I2,K2) -> 0 | L28: =SUM(K10:L10)/AVERAGE(J2,L2) -> 0 | M28: =SUM(L10:M10)/AVERAGE(K2,M2) -> 0 | N28: =SUM(M10:N10)/AVERAGE(L2,N2) -> 0 | ... AP28: =SUM(AO10:AP10)/AVERAGE(AN2,AP2) -> 0
A30: ROE (EBIT) | G30: =SUM(F9:G9)/AVERAGE(E5,G5) -> 0.010820559 | H30: =SUM(G9:H9)/AVERAGE(F5,H5) -> 0.018034265 | I30: =SUM(H9:I9)/AVERAGE(G5,I5) -> 0 | J30: =SUM(I9:J9)/AVERAGE(H5,J5) -> -0.018518519 | K30: =SUM(J9:K9)/AVERAGE(I5,K5) -> -0.019665683 | L30: =SUM(K9:L9)/AVERAGE(J5,L5) -> -0.019665683 | M30: =SUM(L9:M9)/AVERAGE(K5,M5) -> -0.0043620502 | N30: =SUM(M9:N9)/AVERAGE(L5,N5) -> 0.01308615 | ... AP30: =SUM(AO9:AP9)/AVERAGE(AN5,AP5) -> 0.013157895
A31: ROE (NI) | G31: =SUM(F10:G10)/AVERAGE(E5,G5) -> 0 | H31: =SUM(G10:H10)/AVERAGE(F5,H5) -> 0 | I31: =SUM(H10:I10)/AVERAGE(G5,I5) -> 0 | J31: =SUM(I10:J10)/AVERAGE(H5,J5) -> 0 | K31: =SUM(J10:K10)/AVERAGE(I5,K5) -> 0 | L31: =SUM(K10:L10)/AVERAGE(J5,L5) -> 0 | M31: =SUM(L10:M10)/AVERAGE(K5,M5) -> 0 | N31: =SUM(M10:N10)/AVERAGE(L5,N5) -> 0 | ... AP31: =SUM(AO10:AP10)/AVERAGE(AN5,AP5) -> 0
A33: Sales / Assets | D33: =D8*4/D3 -> 0.96860987 | E33: =E8*4/E3 -> 0.7250384 | F33: =F8*4/F3 -> 0.74565561 | G33: =G8*4/G3 -> 0.57549407 | H33: =H8*4/H3 -> 0.57594937 | I33: =I8*4/I3 -> 0.54501217 | J33: =J8*4/J3 -> 0.55906822 | K33: =K8*4/K3 -> 0.54453782 | ... AP33: =AP8*4/AP3 -> 0.66030014

Sheet ownership
A1: Name | B1: Title | C1: shares | D1: voting rights | E1: % shares | F1: % Voting

Sheet trilogiq_IS
C2: Trilogiq
C3: Premium Export
C6: Income Statement
D8: Q-39 | E8: Q-38 | F8: Q-37 | G8: Q-36 | H8: Q-35 | I8: Q-34 | J8: Q-33 | K8: Q-32 | L8: Q-31 | M8: Q-30 | N8: Q-29 | O8: Q-28 | P8: Q-27 | Q8: Q-26 | R8: Q-25 | S8: Q-24 | T8: Q-23 | U8: Q-22 | V8: Q-21 | W8: Q-20 | X8: Q-19 | Y8: Q-18 | Z8: Q-17 | AA8: Q-16 | AB8: Q-15 | AC8: Q-14 | AD8: Q-13 | AE8: Q-12 | AF8: Q-11 | AG8: Q-10 | AH8: Q-9 | AI8: Q-8 | AJ8: Q-7 | AK8: Q-6 | AL8: Q-5 | AM8: Q-4 | AN8: Q-3 | AO8: Q-2 | AP8: Q-1 | AQ8: Q
C10: Period End Date | D10: 2015-06-30 | E10: 2015-09-30 | F10: 2015-12-31 | G10: 2016-03-31 | H10: 2016-06-30 | I10: 2016-09-30 | J10: 2016-12-31 | K10: 2017-03-31 | L10: 2017-06-30 | M10: 2017-09-30 | N10: 2017-12-31 | O10: 2018-03-31 | P10: 2018-06-30 | Q10: 2018-09-30 | R10: 2018-12-31 | S10: 2019-03-31 | T10: 2019-06-30 | U10: 2019-09-30 | V10: 2019-12-31 | W10: 2020-03-31 | X10: 2020-06-30 | Y10: 2020-09-30 | Z10: 2020-12-31 | AA10: 2021-03-31 | AB10: 2021-06-30 | AC10: 2021-09-30 | AD10: 2021-12-31 | AE10: 2022-03-31 | AF10: 2022-06-30 | AG10: 2022-09-30 | AH10: 2022-12-31 | AI10: 2023-03-31 | AJ10: 2023-06-30 | AK10: 2023-09-30 | AL10: 2023-12-31 | AM10: 2024-03-31 | AN10: 2024-06-30 | AO10: 2024-09-30 | AP10: 2024-12-31 | AQ10: 2025-03-31
C12: Revenue | D12: 16.2 | E12: 16.2 | F12: 11.8 | G12: 11.8 | H12: 9.1 | I12: 9.1 | J12: 8.4 | K12: 8.4 | L12: 8.1 | M12: 8.1 | N12: 8.7 | O12: 8.7 | P12: 8.2 | Q12: 8.2 | R12: 7.8 | S12: 7.8 | T12: 6.3 | U12: 6.3 | V12: 5.4 | W12: 5.4 | X12: 5 | Y12: 5 | Z12: 6.3 | AA12: 6.3 | AB12: 5.3 | AC12: 5.3 | AD12: 5.4 | AE12: 5.4 | AF12: 5.3 | AG12: 5.3 | AH12: 5.8 | AI12: 5.8 | AJ12: 5.6 | AK12: 5.6 | AL12: 6.4 | AM12: 6.4 | AN12: 6.1 | AO12: 6.1 | AP12: 5.5 | AQ12: 5.5
C13: Revenue Growth (YoY) | D13: -0.8% | E13: -0.8% | F13: -31.3% | G13: -31.3% | H13: -43.9% | I13: -43.9% | J13: -29.1% | K13: -29.1% | L13: -10.8% | M13: -10.8% | N13: 3.3% | O13: 3.3% | P13: 1.2% | Q13: 1.2% | R13: -10.1% | S13: -10.1% | T13: -22.7% | U13: -22.7% | V13: -30.1% | W13: -30.1% | X13: -21.1% | Y13: -21.1% | Z13: 15.8% | AA13: 15.8% | AB13: 5.4% | AC13: 5.4% | AD13: -14.1% | AE13: -14.1% | AF13: 0.1% | AG13: 0.1% | AH13: 7.6% | AI13: 7.6% | AJ13: 6.4% | AK13: 6.4% | AL13: 10.4% | AM13: 10.4% | AN13: 8.3% | AO13: 8.3% | AP13: -14.0% | AQ13: -14.0%
C15: Cost of Revenues | D15: -9.2 | E15: -9.2 | F15: -7.7 | G15: -7.7 | H15: -5.5 | I15: -5.5 | J15: -5.9 | K15: -5.9 | L15: -5.7 | M15: -5.7 | N15: -8.5 | O15: -8.5 | P15: -5.6 | Q15: -5.6 | R15: -5 | S15: -5 | T15: -4 | U15: -4 | V15: -3.6 | W15: -3.6 | X15: -2.9 | Y15: -2.9 | Z15: -3.7 | AA15: -3.7 | AB15: -2.1 | AC15: -2.1 | AD15: -3.4 | AE15: -3.4 | AF15: -2.1 | AG15: -2.1 | AH15: -2.6 | AI15: -2.6 | AJ15: -2.3 | AK15: -2.3 | AL15: -2.4 | AM15: -2.4 | AN15: -2.2 | AO15: -2.2 | AP15: -2 | AQ15: -2
C16: Gross Profit | D16: 6.9 | E16: 6.9 | F16: 4.1 | G16: 4.1 | H16: 3.5 | I16: 3.5 | J16: 2.5 | K16: 2.5 | L16: 2.4 | M16: 2.4 | N16: 0.2 | O16: 0.2 | P16: 2.6 | Q16: 2.6 | R16: 2.8 | S16: 2.8 | T16: 2.3 | U16: 2.3 | V16: 1.9 | W16: 1.9 | X16: 2.1 | Y16: 2.1 | Z16: 2.6 | AA16: 2.6 | AB16: 3.1 | AC16: 3.1 | AD16: 2 | AE16: 2 | AF16: 3.2 | AG16: 3.2 | AH16: 3.2 | AI16: 3.2 | AJ16: 3.3 | AK16: 3.3 | AL16: 4.1 | AM16: 4.1 | AN16: 3.9 | AO16: 3.9 | AP16: 3.5 | AQ16: 3.5
C17: Gross Profit Margin | D17: 42.8% | E17: 42.8% | F17: 34.9% | G17: 34.9% | H17: 38.7% | I17: 38.7% | J17: 29.9% | K17: 29.9% | L17: 29.7% | M17: 29.7% | N17: 2.1% | O17: 2.1% | P17: 31.6% | Q17: 31.6% | R17: 35.5% | S17: 35.5% | T17: 36.4% | U17: 36.4% | V17: 34.7% | W17: 34.7% | X17: 42.5% | Y17: 42.5% | Z17: 41.4% | AA17: 41.4% | AB17: 59.8% | AC17: 59.8% | AD17: 36.8% | AE17: 36.8% | AF17: 60.4% | AG17: 60.4% | AH17: 55.7% | AI17: 55.7% | AJ17: 59.1% | AK17: 59.1% | AL17: 63.1% | AM17: 63.1% | AN17: 64.2% | AO17: 64.2% | AP17: 63.7% | AQ17: 63.7%
C19: R&D Expenses | D19: 0 | E19: 0 | F19: 0 | G19: 0 | H19: 0 | I19: 0 | J19: 0 | K19: 0 | L19: 0 | M19: 0 | N19: 0 | O19: 0 | P19: 0 | Q19: 0 | R19: 0 | S19: 0 | T19: 0 | U19: 0 | V19: 0 | W19: 0 | X19: 0 | Y19: 0 | Z19: 0 | AA19: 0 | AB19: 0 | AC19: 0 | AD19: 0 | AE19: 0 | AF19: 0 | AG19: 0 | AH19: 0 | AI19: 0 | AJ19: 0 | AK19: 0 | AL19: 0 | AM19: 0 | AN19: 0 | AO19: 0 | AP19: 0 | AQ19: 0
C20: Selling and Marketing Expense
C21: General & Admin Expenses
C22: Other Inc / (Exp) | D22: -1 | E22: -1 | F22: -0.7 | G22: -0.7 | H22: -1 | I22: -1 | J22: -0.6 | K22: -0.6 | L22: -1.2 | M22: -1.2 | N22: 2.7 | O22: 2.7 | P22: -1 | Q22: -1 | R22: -0.1 | S22: -0.1 | T22: -0.7 | U22: -0.7 | V22: -0.7 | W22: -0.7 | X22: -0.7 | Y22: -0.7 | Z22: -0.4 | AA22: -0.4 | AB22: -1.5 | AC22: -1.5 | AD22: -0.2 | AE22: -0.2 | AF22: -1.6 | AG22: -1.6 | AH22: -1.6 | AI22: -1.6 | AJ22: -1.4 | AK22: -1.4 | AL22: -1.7 | AM22: -1.7 | AN22: -1.5 | AO22: -1.5 | AP22: -1.6 | AQ22: -1.6
C23: Operating Expenses | D23: -5.8 | E23: -5.8 | F23: -4.7 | G23: -4.7 | H23: -3.9 | I23: -3.9 | J23: -3.6 | K23: -3.6 | L23: -4 | M23: -4 | N23: -3.1 | O23: -3.1 | P23: -3.6 | Q23: -3.6 | R23: -2.6 | S23: -2.6 | T23: -2.9 | U23: -2.9 | V23: -2.7 | W23: -2.7 | X23: -2.5 | Y23: -2.5 | Z23: -2.1 | AA23: -2.1 | AB23: -3.1 | AC23: -3.1 | AD23: -2 | AE23: -2 | AF23: -3.3 | AG23: -3.3 | AH23: -3.5 | AI23: -3.5 | AJ23: -3.2 | AK23: -3.2 | AL23: -3.6 | AM23: -3.6 | AN23: -3.4 | AO23: -3.4 | AP23: -3.7 | AQ23: -3.7
C24: Operating Income | D24: 1.1 | E24: 1.1 | F24: -0.6 | G24: -0.6 | H24: -0.4 | I24: -0.4 | J24: -1.1 | K24: -1.1 | L24: -1.6 | M24: -1.6 | N24: -2.9 | O24: -2.9 | P24: -1 | Q24: -1 | R24: 0.2 | S24: 0.2 | T24: -0.6 | U24: -0.6 | V24: -0.8 | W24: -0.8 | X24: -0.4 | Y24: -0.4 | Z24: 0.5 | AA24: 0.5 | AB24: 0 | AC24: 0 | AD24: 0 | AE24: 0 | AF24: -0.1 | AG24: -0.1 | AH24: -0.2 | AI24: -0.2 | AJ24: 0.1 | AK24: 0.1 | AL24: 0.5 | AM24: 0.5 | AN24: 0.5 | AO24: 0.5 | AP24: -0.2 | AQ24: -0.2
C26: Net Interest Expenses | D26: 0 | E26: 0 | F26: 0 | G26: 0 | H26: 0 | I26: 0 | J26: 0 | K26: 0 | L26: 0 | M26: 0 | N26: 0.2 | O26: 0.2 | P26: 0 | Q26: 0 | R26: 0 | S26: 0 | T26: 0 | U26: 0 | V26: 0 | W26: 0 | X26: 0 | Y26: 0 | Z26: 0 | AA26: 0 | AB26: 0 | AC26: 0 | AD26: 0.2 | AE26: 0.2 | AF26: 0 | AG26: 0 | AH26: 0.1 | AI26: 0.1 | AJ26: 0.1 | AK26: 0.1 | AL26: 0.2 | AM26: 0.2 | AN26: 0.2 | AO26: 0.2 | AP26: 0.2 | AQ26: 0.2
C27: EBT, Incl. Unusual Items | D27: 1.1 | E27: 1.1 | F27: -0.6 | G27: -0.6 | H27: -0.4 | I27: -0.4 | J27: -1.1 | K27: -1.1 | L27: -1.6 | M27: -1.6 | N27: -2.7 | O27: -2.7 | P27: -1 | Q27: -1 | R27: 0.2 | S27: 0.2 | T27: -0.6 | U27: -0.6 | V27: -0.8 | W27: -0.8 | X27: -0.4 | Y27: -0.4 | Z27: 0.5 | AA27: 0.5 | AB27: 0 | AC27: 0 | AD27: 0.2 | AE27: 0.2 | AF27: -0.1 | AG27: -0.1 | AH27: -0.1 | AI27: -0.1 | AJ27: 0.2 | AK27: 0.2 | AL27: 0.7 | AM27: 0.7 | AN27: 0.7 | AO27: 0.7 | AP27: 0 | AQ27: 0
C28: Earnings of Discontinued Ops.
C29: Income Tax Expense | D29: -0.4 | E29: -0.4 | F29: 0.4 | G29: 0.4 | H29: -0.2 | I29: -0.2 | J29: 0 | K29: 0 | L29: -0.1 | M29: -0.1 | N29: -0.1 | O29: -0.1 | P29: 0 | Q29: 0 | R29: -0.1 | S29: -0.1 | T29: 0 | U29: 0 | V29: 0 | W29: 0 | X29: -0.1 | Y29: -0.1 | Z29: -0.1 | AA29: -0.1 | AB29: 0 | AC29: 0 | AD29: -0.1 | AE29: -0.1 | AF29: 0 | AG29: 0 | AH29: -0.1 | AI29: -0.1 | AJ29: 0 | AK29: 0 | AL29: -0.1 | AM29: -0.1 | AN29: -0.1 | AO29: -0.1 | AP29: -0.1 | AQ29: -0.1
C30: Net Income to Company | D30: 0.7 | E30: 0.7 | F30: -0.1 | G30: -0.1 | H30: -0.6 | I30: -0.6 | J30: -1.1 | K30: -1.1 | L30: -1.6 | M30: -1.6 | N30: -2.8 | O30: -2.8 | P30: -1 | Q30: -1 | R30: 0.1 | S30: 0.1 | T30: -0.6 | U30: -0.6 | V30: -0.9 | W30: -0.9 | X30: -0.5 | Y30: -0.5 | Z30: 0.3 | AA30: 0.3 | AB30: 0 | AC30: 0 | AD30: 0.2 | AE30: 0.2 | AF30: -0.1 | AG30: -0.1 | AH30: -0.2 | AI30: -0.2 | AJ30: 0.2 | AK30: 0.2 | AL30: 0.6 | AM30: 0.6 | AN30: 0.7 | AO30: 0.7 | AP30: -0.1 | AQ30: -0.1
C32: Minority Interest in Earnings | D32: -0.1 | E32: -0.1 | F32: 0 | G32: 0 | H32: 0 | I32: 0 | J32: 0 | K32: 0 | L32: 0 | M32: 0 | N32: 0 | O32: 0 | P32: 0 | Q32: 0 | R32: 0 | S32: 0 | T32: 0 | U32: 0 | V32: 0 | W32: 0 | X32: 0 | Y32: 0 | Z32: 0 | AA32: 0 | AB32: 0 | AC32: 0 | AD32: 0 | AE32: 0 | AF32: 0 | AG32: 0 | AH32: 0 | AI32: 0 | AJ32: 0 | AK32: 0 | AL32: 0 | AM32: 0 | AN32: 0 | AO32: 0 | AP32: 0 | AQ32: 0
C33: Net Income to Stockholders | D33: 0.7 | E33: 0.7 | F33: -0.1 | G33: -0.1 | H33: -0.4 | I33: -0.4 | J33: -1.3 | K33: -1.3 | L33: -1.6 | M33: -1.6 | N33: -2.8 | O33: -2.8 | P33: -1 | Q33: -1 | R33: 0.1 | S33: 0.1 | T33: -0.6 | U33: -0.6 | V33: -0.8 | W33: -0.8 | X33: -0.5 | Y33: -0.5 | Z33: 0.3 | AA33: 0.3 | AB33: 0 | AC33: 0 | AD33: 0.2 | AE33: 0.2 | AF33: -0.1 | AG33: -0.1 | AH33: -0.2 | AI33: -0.2 | AJ33: 0.2 | AK33: 0.2 | AL33: 0.6 | AM33: 0.6 | AN33: 0.7 | AO33: 0.7 | AP33: -0.1 | AQ33: -0.1
C35: Preferred Dividends & Other Adj. | D35: 0 | E35: 0 | F35: 0 | G35: 0 | H35: -0.2 | I35: -0.2 | J35: 0.2 | K35: 0.2 | L35: 0 | M35: 0 | N35: 0 | O35: 0 | P35: 0 | Q35: 0 | R35: 0 | S35: 0 | T35: 0 | U35: 0 | V35: 0 | W35: 0 | X35: 0 | Y35: 0 | Z35: 0 | AA35: 0 | AB35: 0 | AC35: 0 | AD35: -0.1 | AE35: -0.1 | AF35: 0 | AG35: 0 | AH35: 0 | AI35: 0 | AJ35: 0 | AK35: 0 | AL35: 0 | AM35: 0 | AN35: 0 | AO35: 0 | AP35: 0 | AQ35: 0
C36: Net Income to Common Excl Extra Items | D36: 0.6 | E36: 0.6 | F36: -0.1 | G36: -0.1 | H36: -0.6 | I36: -0.6 | J36: -1.1 | K36: -1.1 | L36: -1.6 | M36: -1.6 | N36: -2.8 | O36: -2.8 | P36: -1 | Q36: -1 | R36: 0.1 | S36: 0.1 | T36: -0.6 | U36: -0.6 | V36: -0.8 | W36: -0.8 | X36: -0.5 | Y36: -0.5 | Z36: 0.3 | AA36: 0.3 | AB36: 0 | AC36: 0 | AD36: 0.2 | AE36: 0.2 | AF36: -0.1 | AG36: -0.1 | AH36: -0.2 | AI36: -0.2 | AJ36: 0.2 | AK36: 0.2 | AL36: 0.6 | AM36: 0.6 | AN36: 0.7 | AO36: 0.7 | AP36: -0.1 | AQ36: -0.1
C38: Basic EPS (Cont. Ops) | D38: 0.19 | E38: 0.19 | F38: -0.03 | G38: -0.03 | H38: -0.16 | I38: -0.16 | J38: -0.28 | K38: -0.28 | L38: -0.44 | M38: -0.44 | O38: -0.75 | P38: -0.27 | Q38: -0.27 | R38: 0.024 | S38: 0.024 | T38: -0.16 | U38: -0.16 | V38: -0.23 | W38: -0.23 | X38: -0.13 | Y38: -0.13 | AB38: 0.005 | AC38: 0.005 | AF38: -0.035 | AG38: -0.035 | AH38: -0.05 | AI38: -0.05 | AJ38: 0.05 | AK38: 0.05 | AL38: 0.16 | AM38: 0.16 | AN38: 0.18 | AO38: 0.18 | AP38: -0.036 | AQ38: -0.036
C39: Diluted EPS (Cont. Ops) | D39: 0.19 | E39: 0.19 | F39: -0.03 | G39: -0.03 | H39: -0.16 | I39: -0.16 | J39: -0.28 | K39: -0.28 | L39: -0.44 | M39: -0.44 | O39: -0.75 | P39: -0.27 | Q39: -0.27 | R39: 0.024 | S39: 0.024 | T39: -0.16 | U39: -0.16 | V39: -0.23 | W39: -0.23 | X39: -0.13 | Y39: -0.13 | AB39: 0.005 | AC39: 0.005 | AF39: -0.035 | AG39: -0.035 | AH39: -0.05 | AI39: -0.05 | AJ39: 0.05 | AK39: 0.05 | AL39: 0.16 | AM39: 0.16 | AN39: 0.18 | AO39: 0.18 | AP39: -0.036 | AQ39: -0.036
C40: Weighted Average Basic Shares Out. | D40: 3.4 | E40: 3.4 | F40: 3.5 | G40: 3.5 | H40: 3.6 | I40: 3.6 | J40: 3.8 | K40: 3.8 | L40: 3.7 | M40: 3.7 | O40: 3.7 | P40: 3.6 | Q40: 3.6 | R40: 3.7 | S40: 3.7 | T40: 3.6 | U40: 3.6 | V40: 3.6 | W40: 3.6 | X40: 3.6 | Y40: 3.6 | AB40: 4.5 | AC40: 4.5 | AF40: 3.7 | AG40: 3.7 | AH40: 3.8 | AI40: 3.8 | AJ40: 3.8 | AK40: 3.8 | AL40: 3.6 | AM40: 3.6 | AN40: 3.7 | AO40: 3.7 | AP40: 3.9 | AQ40: 3.9
C41: Weighted Average Diluted Shares Out. | D41: 3.4 | E41: 3.4 | F41: 3.5 | G41: 3.5 | H41: 3.6 | I41: 3.6 | J41: 3.8 | K41: 3.8 | L41: 3.7 | M41: 3.7 | O41: 3.7 | P41: 3.6 | Q41: 3.6 | R41: 3.7 | S41: 3.7 | T41: 3.6 | U41: 3.6 | V41: 3.6 | W41: 3.6 | X41: 3.6 | Y41: 3.6 | AB41: 4.5 | AC41: 4.5 | AF41: 3.7 | AG41: 3.7 | AH41: 3.8 | AI41: 3.8 | AJ41: 3.8 | AK41: 3.8 | AL41: 3.6 | AM41: 3.6 | AN41: 3.7 | AO41: 3.7 | AP41: 3.9 | AQ41: 3.9
C43: EBITDA | D43: 1.9 | E43: 1.9 | F43: 0.1 | G43: 0.1 | H43: 0.5 | I43: 0.5 | J43: -0.5 | K43: -0.5 | L43: -0.5 | M43: -0.5 | N43: 0.3 | O43: 0.3 | P43: -0.2 | Q43: -0.2 | R43: -0.3 | S43: -0.3 | T43: -0.1 | U43: -0.1 | V43: 0 | W43: 0 | X43: 0.3 | Y43: 0.3 | Z43: 0.7 | AA43: 0.7 | AB43: 0.5 | AC43: 0.5 | AD43: 0.3 | AE43: 0.4 | AF43: 0.2 | AG43: 0.2 | AH43: 0.2 | AI43: 0.2 | AJ43: 0.1 | AK43: 0.1 | AL43: 0.7 | AM43: 0.7 | AN43: 0.5 | AO43: 0.5 | AP43: 0 | AQ43: 0
C44: EBIT | D44: 1.3 | E44: 1.3 | F44: -0.6 | G44: -0.6 | H44: -0.3 | I44: -0.3 | J44: -1.2 | K44: -1.2 | L44: -1.4 | M44: -1.4 | N44: -1.4 | O44: -1.4 | P44: -0.9 | Q44: -0.9 | R44: -0.5 | S44: -0.5 | T44: -0.7 | U44: -0.7 | V44: -0.8 | W44: -0.8 | X44: -0.2 | Y44: -0.2 | Z44: 0.3 | AA44: 0.3 | AB44: 0.1 | AC44: 0.1 | AD44: -0.1 | AE44: -0.1 | AF44: -0.2 | AG44: -0.2 | AH44: 0 | AI44: 0 | AJ44: -0.1 | AK44: -0.1 | AL44: 0.5 | AM44: 0.5 | AN44: 0.4 | AO44: 0.4 | AP44: -0.2 | AQ44: -0.2
C46: Revenue (Reported) | D46: 16.2 | E46: 16.2 | F46: 11.8 | G46: 11.8 | H46: 9.1 | I46: 9.1 | J46: 8.4 | K46: 8.4 | L46: 8.1 | M46: 8.1 | N46: 8.7 | O46: 8.7 | P46: 8.2 | Q46: 8.2 | R46: 7.8 | S46: 7.8 | T46: 6.3 | U46: 6.3 | V46: 5.4 | W46: 5.4 | X46: 5 | Y46: 5 | Z46: 6.3 | AA46: 6.3 | AB46: 5.3 | AC46: 5.3 | AD46: 5.4 | AE46: 5.4 | AF46: 5.3 | AG46: 5.3 | AH46: 5.8 | AI46: 5.8 | AJ46: 5.6 | AK46: 5.6 | AL46: 6.4 | AM46: 6.4 | AN46: 6.1 | AO46: 6.1 | AP46: 5.5 | AQ46: 5.5
C47: Operating Income (Reported) | D47: 1.3 | E47: 1.3 | F47: -0.6 | G47: -0.6 | H47: -0.3 | I47: -0.3 | J47: -1.2 | K47: -1.2 | L47: -1.4 | M47: -1.4 | N47: -1.4 | O47: -1.4 | P47: -0.9 | Q47: -0.9 | R47: -0.5 | S47: -0.5 | T47: -0.7 | U47: -0.7 | V47: -0.8 | W47: -0.8 | X47: -0.2 | Y47: -0.2 | Z47: 0.4 | AA47: 0.4 | AD47: 0 | AE47: 0
C48: Operating Income (Adjusted) | D48: 1.3 | E48: 1.3 | F48: -0.6 | G48: -0.6 | H48: -0.3 | I48: -0.3 | J48: -1.2 | K48: -1.2 | L48: -1.4 | M48: -1.4 | N48: -1.4 | O48: -1.4 | P48: -0.9 | Q48: -0.9 | R48: -0.5 | S48: -0.5 | T48: -0.7 | U48: -0.7 | V48: -0.8 | W48: -0.8 | X48: -0.2 | Y48: -0.2 | Z48: 0.3 | AA48: 0.3 | AB48: 0.1 | AC48: 0.1 | AD48: -0.1 | AE48: -0.1 | AF48: -0.2 | AG48: -0.2 | AH48: 0 | AI48: 0 | AJ48: -0.1 | AK48: -0.1 | AL48: 0.5 | AM48: 0.5 | AN48: 0.4 | AO48: 0.4 | AP48: -0.2 | AQ48: -0.2

Sheet trilogiq_bs
C2: Trilogiq
C3: Premium Export
C6: Balance Sheet
D8: Q-39 | E8: Q-38 | F8: Q-37 | G8: Q-36 | H8: Q-35 | I8: Q-34 | J8: Q-33 | K8: Q-32 | L8: Q-31 | M8: Q-30 | N8: Q-29 | O8: Q-28 | P8: Q-27 | Q8: Q-26 | R8: Q-25 | S8: Q-24 | T8: Q-23 | U8: Q-22 | V8: Q-21 | W8: Q-20 | X8: Q-19 | Y8: Q-18 | Z8: Q-17 | AA8: Q-16 | AB8: Q-15 | AC8: Q-14 | AD8: Q-13 | AE8: Q-12 | AF8: Q-11 | AG8: Q-10 | AH8: Q-9 | AI8: Q-8 | AJ8: Q-7 | AK8: Q-6 | AL8: Q-5 | AM8: Q-4 | AN8: Q-3 | AO8: Q-2 | AP8: Q-1 | AQ8: Q
C10: Period End Date | D10: 2015-06-30 | E10: 2015-09-30 | F10: 2015-12-31 | G10: 2016-03-31 | H10: 2016-06-30 | I10: 2016-09-30 | J10: 2016-12-31 | K10: 2017-03-31 | L10: 2017-06-30 | M10: 2017-09-30 | N10: 2017-12-31 | O10: 2018-03-31 | P10: 2018-06-30 | Q10: 2018-09-30 | R10: 2018-12-31 | S10: 2019-03-31 | T10: 2019-06-30 | U10: 2019-09-30 | V10: 2019-12-31 | W10: 2020-03-31 | X10: 2020-06-30 | Y10: 2020-09-30 | Z10: 2020-12-31 | AA10: 2021-03-31 | AB10: 2021-06-30 | AC10: 2021-09-30 | AD10: 2021-12-31 | AE10: 2022-03-31 | AF10: 2022-06-30 | AG10: 2022-09-30 | AH10: 2022-12-31 | AI10: 2023-03-31 | AJ10: 2023-06-30 | AK10: 2023-09-30 | AL10: 2023-12-31 | AM10: 2024-03-31 | AN10: 2024-06-30 | AO10: 2024-09-30 | AP10: 2024-12-31 | AQ10: 2025-03-31
C12: Cash And Equivalents | D12: 8.4 | E12: 8.4 | F12: 15.6 | G12: 15.6 | H12: 10.2 | I12: 10.2 | J12: 7.6 | K12: 7.6 | L12: 9.4 | M12: 9.4 | N12: 11.6 | O12: 11.6 | R12: 7.3 | S12: 7.3 | T12: 6.7 | U12: 6.7 | V12: 7.9 | W12: 7.9 | X12: 7.6 | Y12: 7.6 | AB12: 6.5 | AC12: 6.5 | AF12: 7 | AG12: 7 | AH12: 4.9 | AI12: 4.9 | AJ12: 4.6 | AK12: 4.6 | AL12: 4 | AM12: 4 | AN12: 5 | AO12: 5 | AP12: 4.3 | AQ12: 4.3
C13: Short Term Investments | D13: 12 | E13: 12 | F13: 5 | G13: 5 | H13: 10 | I13: 10 | J13: 10 | K13: 10 | L13: 9 | M13: 9 | N13: 4 | O13: 4 | R13: 9 | S13: 9 | T13: 10.6 | U13: 10.6 | V13: 10.6 | W13: 10.6 | X13: 10.6 | Y13: 10.6 | AB13: 12.1 | AC13: 12.1 | AF13: 12.6 | AG13: 12.6 | AH13: 15.7 | AI13: 15.7 | AJ13: 17.2 | AK13: 17.2 | AL13: 19 | AM13: 19 | AN13: 19.1 | AO13: 19.1 | AP13: 20.9 | AQ13: 20.9
C14: Accounts Receivable, Net | D14: 12.8 | E14: 12.8 | F14: 9 | G14: 9 | H14: 8.2 | I14: 8.2 | J14: 7.8 | K14: 7.8 | L14: 7.2 | M14: 7.2 | N14: 7.3 | O14: 7.3 | R14: 6 | S14: 6 | T14: 5.7 | U14: 5.7 | V14: 4.6 | W14: 4.6 | X14: 5.2 | Y14: 5.2 | AB14: 4.9 | AC14: 4.9 | AF14: 4.8 | AG14: 4.8 | AH14: 4.6 | AI14: 4.6 | AJ14: 4.2 | AK14: 4.2 | AL14: 5.1 | AM14: 5.1 | AN14: 4.7 | AO14: 4.7 | AP14: 4.1 | AQ14: 4.1
C15: Inventory | D15: 9 | E15: 9 | F15: 7 | G15: 7 | H15: 7.6 | I15: 7.6 | J15: 7.2 | K15: 7.2 | L15: 6.9 | M15: 6.9 | N15: 6.8 | O15: 6.8 | R15: 5.5 | S15: 5.5 | T15: 4.9 | U15: 4.9 | V15: 4.1 | W15: 4.1 | X15: 3.9 | Y15: 3.9 | AB15: 5.1 | AC15: 5.1 | AF15: 5.6 | AG15: 5.6 | AH15: 4.6 | AI15: 4.6 | AJ15: 4.5 | AK15: 4.5 | AL15: 4.2 | AM15: 4.2 | AN15: 4.2 | AO15: 4.2 | AP15: 4 | AQ15: 4
C16: Prepaid Expenses | D16: 0.2 | E16: 0.2 | F16: 0.2 | G16: 0.2 | H16: 0.1 | I16: 0.1 | J16: 0.2 | K16: 0.2 | L16: 0.2 | M16: 0.2 | N16: 0.1 | O16: 0.1 | R16: 0.1 | S16: 0.1 | T16: 0.1 | U16: 0.1 | V16: 0 | W16: 0 | X16: 0 | Y16: 0 | AB16: 0.1 | AC16: 0.1
C17: Other Current Assets | D17: 3.3 | E17: 3.3 | F17: 4.3 | G17: 4.3 | H17: 4.5 | I17: 4.5 | J17: 4.1 | K17: 4.1 | L17: 3.8 | M17: 3.8 | N17: 3.6 | O17: 3.6 | P17: 0 | Q17: 0 | R17: 2.8 | S17: 2.8 | T17: 2.5 | U17: 2.5 | V17: 1.3 | W17: 1.3 | X17: 1.2 | Y17: 1.2 | Z17: 0 | AA17: 0 | AB17: 1.5 | AC17: 1.5 | AD17: 0 | AE17: 0 | AF17: 2.1 | AG17: 2.1 | AH17: 1.8 | AI17: 1.8 | AJ17: 1.8 | AK17: 1.8 | AL17: 1.8 | AM17: 1.8 | AN17: 1.4 | AO17: 1.4 | AP17: 1.4 | AQ17: 1.4
C18: Total Current Assets | D18: 45.6 | E18: 45.6 | F18: 41.1 | G18: 41.1 | H18: 40.5 | I18: 40.5 | J18: 36.7 | K18: 36.7 | L18: 36.6 | M18: 36.6 | N18: 33.4 | O18: 33.4 | R18: 30.6 | S18: 30.6 | T18: 30.4 | U18: 30.4 | V18: 28.5 | W18: 28.5 | X18: 28.6 | Y18: 28.6 | AB18: 30.1 | AC18: 30.1 | AF18: 32.1 | AG18: 32.1 | AH18: 31.6 | AI18: 31.6 | AJ18: 32.3 | AK18: 32.3 | AL18: 34 | AM18: 34 | AN18: 34.4 | AO18: 34.4 | AP18: 34.7 | AQ18: 34.7
C20: Property Plant And Equipment, Net | D20: 21 | E20: 21 | F20: 21.9 | G20: 21.9 | H20: 22.4 | I20: 22.4 | J20: 22.7 | K20: 22.7 | L20: 21 | M20: 21 | N20: 17.7 | O20: 17.7 | R20: 15.7 | S20: 15.7 | T20: 13.3 | U20: 13.3 | V20: 12 | W20: 12 | X20: 11 | Y20: 11 | AB20: 9.8 | AC20: 9.8 | AF20: 8.4 | AG20: 8.4 | AH20: 8.1 | AI20: 8.1 | AJ20: 7.8 | AK20: 7.8 | AL20: 7.8 | AM20: 7.8 | AN20: 7.5 | AO20: 7.5 | AP20: 7.2 | AQ20: 7.2
C21: Real Estate Owned
C22: Capitalized / Purchased Software
C23: Long-term Investments | D23: 0.1 | E23: 0.1 | F23: 0.1 | G23: 0.1 | H23: 0.1 | I23: 0.1 | J23: 0.1 | K23: 0.1 | L23: 0.3 | M23: 0.3 | N23: 0.3 | O23: 0.3 | R23: 0.2 | S23: 0.2 | T23: 0.1 | U23: 0.1 | V23: 0.1 | W23: 0.1 | X23: 0.1 | Y23: 0.1
C24: Goodwill | D24: 0 | E24: 0 | F24: 0 | G24: 0 | H24: 0 | I24: 0 | J24: 0 | K24: 0 | L24: 0 | M24: 0 | N24: 0 | O24: 0 | R24: 0 | S24: 0 | T24: 0 | U24: 0 | V24: 0 | W24: 0 | X24: 0 | Y24: 0 | AB24: 0 | AC24: 0 | AH24: 0 | AI24: 0 | AL24: 0 | AM24: 0 | AP24: 0 | AQ24: 0
C25: Other Intangibles | D25: 0.2 | E25: 0.2 | F25: 0.2 | G25: 0.2 | H25: 0.2 | I25: 0.2 | J25: 0.6 | K25: 0.6 | L25: 1 | M25: 1 | N25: 0.7 | O25: 0.7 | R25: 0.5 | S25: 0.5 | T25: 0.3 | U25: 0.3 | V25: 0.1 | W25: 0.1 | X25: 0.1 | Y25: 0.1 | AB25: 0 | AC25: 0 | AF25: 0 | AG25: 0 | AH25: 0 | AI25: 0 | AJ25: 0 | AK25: 0 | AL25: 0 | AM25: 0 | AN25: 0 | AO25: 0 | AP25: 0 | AQ25: 0
C26: Other Long-term Assets | D26: 0 | E26: 0 | F26: 0 | G26: 0 | H26: 0 | I26: 0 | J26: 0 | K26: 0 | L26: 0 | M26: 0 | N26: 0 | O26: 0 | P26: 0 | Q26: 0 | R26: 0 | S26: 0 | T26: 0 | U26: 0 | V26: 0 | W26: 0 | X26: 0 | Y26: 0 | Z26: 0 | AA26: 0 | AB26: 0.1 | AC26: 0.1 | AD26: 0 | AE26: 0 | AF26: 0.1 | AG26: 0.1 | AH26: 0.1 | AI26: 0.1 | AJ26: 0.1 | AK26: 0.1 | AL26: 0.1 | AM26: 0.1 | AN26: 0.1 | AO26: 0.1 | AP26: 0.1 | AQ26: 0.1
C27: Total Assets | D27: 66.9 | E27: 66.9 | F27: 63.3 | G27: 63.3 | H27: 63.2 | I27: 63.2 | J27: 60.1 | K27: 60.1 | L27: 58.9 | M27: 58.9 | N27: 52 | O27: 52 | R27: 47.1 | S27: 47.1 | T27: 44.2 | U27: 44.2 | V27: 40.8 | W27: 40.8 | X27: 39.7 | Y27: 39.7 | AB27: 40 | AC27: 40 | AF27: 40.7 | AG27: 40.7 | AH27: 39.8 | AI27: 39.8 | AJ27: 40.2 | AK27: 40.2 | AL27: 41.9 | AM27: 41.9 | AN27: 42 | AO27: 42 | AP27: 42 | AQ27: 42
C29: Accounts Payable | D29: 6.2 | E29: 6.2 | F29: 4.1 | G29: 4.1 | H29: 3.1 | I29: 3.1 | J29: 3.1 | K29: 3.1 | L29: 3.6 | M29: 3.6 | N29: 2.8 | O29: 2.8 | R29: 2.2 | S29: 2.2 | T29: 2 | U29: 2 | V29: 1.6 | W29: 1.6 | X29: 1.9 | Y29: 1.9 | AB29: 2.1 | AC29: 2.1 | AF29: 2 | AG29: 2 | AH29: 1.9 | AI29: 1.9 | AJ29: 2 | AK29: 2 | AL29: 2.3 | AM29: 2.3 | AN29: 1.9 | AO29: 1.9 | AP29: 1.7 | AQ29: 1.7
C30: Accrued Expenses
C31: Short-term Borrowings
C32: Current Portion of LT Debt
C33: Current Portion of Capital Lease Obligations
C34: Other Current Liabilities | D34: 4.2 | E34: 4.2 | F34: 3 | G34: 3 | H34: 3.1 | I34: 3.1 | J34: 2.1 | K34: 2.1 | L34: 1.8 | M34: 1.8 | N34: 2.3 | O34: 2.3 | P34: 0 | Q34: 0 | R34: 1.8 | S34: 1.8 | T34: 1.7 | U34: 1.7 | V34: 1.3 | W34: 1.3 | X34: 1.6 | Y34: 1.6 | Z34: 0 | AA34: 0 | AB34: 1.3 | AC34: 1.3 | AD34: 0 | AE34: 0 | AF34: 0 | AG34: 0 | AH34: 0 | AI34: 0 | AJ34: 0 | AK34: 0 | AL34: 0 | AM34: 0 | AN34: 0 | AO34: 0 | AP34: 0 | AQ34: 0
C35: Total Current Liabilities | D35: 10.4 | E35: 10.4 | F35: 7 | G35: 7 | H35: 6.2 | I35: 6.2 | J35: 5.2 | K35: 5.2 | L35: 5.4 | M35: 5.4 | N35: 5.1 | O35: 5.1 | R35: 4 | S35: 4 | T35: 3.6 | U35: 3.6 | V35: 2.9 | W35: 2.9 | X35: 3.5 | Y35: 3.5 | AB35: 3.4 | AC35: 3.4 | AF35: 2 | AG35: 2 | AH35: 1.9 | AI35: 1.9 | AJ35: 2 | AK35: 2 | AL35: 2.3 | AM35: 2.3 | AN35: 1.9 | AO35: 1.9 | AP35: 1.7 | AQ35: 1.7
C37: Long-term Debt | D37: 0 | E37: 0 | F37: 0 | G37: 0 | H37: 1.4 | I37: 1.4 | J37: 1.6 | K37: 1.6 | L37: 4.4 | M37: 4.4 | N37: 3.7 | O37: 3.7 | R37: 2.1 | S37: 2.1 | T37: 1.5 | U37: 1.5 | V37: 1.2 | W37: 1.2 | X37: 0.8 | Y37: 0.8 | AB37: 0.1 | AC37: 0.1 | AF37: 0 | AG37: 0 | AL37: 0 | AM37: 0 | AN37: 0 | AO37: 0 | AP37: 0 | AQ37: 0
C38: Capital Leases
C39: Other Non-current Liabilities | D39: 0.4 | E39: 0.4 | F39: 0.6 | G39: 0.6 | H39: 0.5 | I39: 0.5 | J39: 0.4 | K39: 0.4 | L39: 0.3 | M39: 0.3 | N39: 0.3 | O39: 0.3 | P39: 0 | Q39: 0 | R39: 0.2 | S39: 0.2 | T39: 0.2 | U39: 0.2 | V39: 0.2 | W39: 0.2 | X39: 0.3 | Y39: 0.3 | Z39: 0 | AA39: 0 | AB39: 0.6 | AC39: 0.6 | AD39: 0 | AE39: 0 | AF39: 2 | AG39: 2 | AH39: 2.1 | AI39: 2.1 | AJ39: 2 | AK39: 2 | AL39: 2.3 | AM39: 2.3 | AN39: 1.9 | AO39: 1.9 | AP39: 2.4 | AQ39: 2.4
C40: Total Liabilities | D40: 10.8 | E40: 10.8 | F40: 7.6 | G40: 7.6 | H40: 8.1 | I40: 8.1 | J40: 7.2 | K40: 7.2 | L40: 10.1 | M40: 10.1 | N40: 9.1 | O40: 9.1 | R40: 6.3 | S40: 6.3 | T40: 5.4 | U40: 5.4 | V40: 4.3 | W40: 4.3 | X40: 4.6 | Y40: 4.6 | AB40: 4.1 | AC40: 4.1 | AF40: 4.1 | AG40: 4.1 | AH40: 4 | AI40: 4 | AJ40: 4 | AK40: 4 | AL40: 4.6 | AM40: 4.6 | AN40: 3.9 | AO40: 3.9 | AP40: 4 | AQ40: 4
C42: Common Stock | D42: 5.6 | E42: 5.6 | F42: 5.6 | G42: 5.6 | H42: 5.6 | I42: 5.6 | J42: 5.6 | K42: 5.6 | L42: 5.6 | M42: 5.6 | N42: 5.6 | O42: 5.6 | R42: 5.6 | S42: 5.6 | T42: 5.6 | U42: 5.6 | V42: 5.6 | W42: 5.6 | X42: 5.6 | Y42: 5.6 | AB42: 5.6 | AC42: 5.6 | AF42: 5.6 | AG42: 5.6 | AH42: 5.6 | AI42: 5.6 | AJ42: 5.6 | AK42: 5.6 | AL42: 5.6 | AM42: 5.6 | AN42: 5.6 | AO42: 5.6 | AP42: 5.6 | AQ42: 5.6
C43: Additional Paid In Capital | D43: 0.4 | E43: 0.4 | F43: 0.4 | G43: 0.4 | H43: 0.4 | I43: 0.4 | J43: 0.4 | K43: 0.4 | L43: 0.4 | M43: 0.4 | N43: 0.4 | O43: 0.4 | R43: 0.4 | S43: 0.4 | T43: 0.4 | U43: 0.4 | V43: 0.4 | W43: 0.4 | X43: 0.4 | Y43: 0.4 | AB43: 0.4 | AC43: 0.4 | AF43: 0.4 | AG43: 0.4 | AH43: 0.4 | AI43: 0.4 | AJ43: 0.4 | AK43: 0.4 | AL43: 0.4 | AM43: 0.4 | AN43: 0.4 | AO43: 0.4 | AP43: 0.4 | AQ43: 0.4
C44: Retained Earnings | D44: 1.3 | E44: 1.3 | F44: 1.1 | G44: 1.1 | H44: -0.8 | I44: -0.8 | J44: -3.3 | K44: -3.3 | L44: -3.3 | M44: -3.3 | N44: -8.9 | O44: -8.9 | R44: -1.8 | S44: -1.8 | T44: -1.2 | U44: -1.2 | V44: -2.9 | W44: -2.9 | X44: -0.9 | Y44: -0.9 | AB44: 0 | AC44: 0 | AF44: -0.3 | AG44: -0.3 | AH44: -0.6 | AI44: -0.6 | AJ44: 0.4 | AK44: 0.4 | AL44: 1.5 | AM44: 1.5 | AN44: 1.3 | AO44: 1.3 | AP44: 1.1 | AQ44: 1.1
C45: Treasury Stock
