Workbook

Sheet Overview
A1: Company | C1: =tsh_IS!C2 -> TSH
A2: Industry | C2: Whiskey & bars
A3: Ticker | C3: KUH
A4: Country | C4: Singapore
A5: Currency | C5: SGD
A6: Price (input) | C6: 0.12
A7: Market Cap (mm USD) | C7: 4.28
A8: P/NCAV | C8: =ncav!AK46 -> 0.6497561
A9: Date Founded | C9: 2000
A10: Website | C10: https://tshcorp.com.sg/

Sheet ncav
D1: 2017-03-31 | E1: 2017-06-30 | F1: 2017-09-30 | G1: 2017-12-31 | H1: 2018-03-31 | I1: 2018-06-30 | J1: 2018-09-30 | K1: 2018-12-31 | L1: 2019-03-31 | M1: 2019-06-30 | N1: 2019-09-30 | O1: 2019-12-31 | P1: 2020-03-31 | Q1: 2020-06-30 | R1: 2020-09-30 | S1: 2020-12-31 | T1: 2021-03-31 | U1: 2021-06-30 | V1: 2021-09-30 | W1: 2021-12-31 | X1: 2022-03-31 | Y1: 2022-06-30 | Z1: 2022-09-30 | AA1: 2022-12-31 | AB1: 2023-03-31 | AC1: 2023-06-30 | AD1: 2023-09-30 | AE1: 2023-12-31 | AF1: 2024-03-31 | AG1: 2024-06-30 | AH1: 2024-09-30 | AI1: 2024-12-31 | AJ1: 2025-03-31 | AK1: 2025-06-30
A2: Cash & other liquid securities | D2: =_xlfn.NUMBERVALUE(tsh_bs!D12)+_xlfn.NUMBERVALUE(tsh_bs!D13) -> 0 | E2: =_xlfn.NUMBERVALUE(tsh_bs!E12)+_xlfn.NUMBERVALUE(tsh_bs!E13) -> 0 | F2: =_xlfn.NUMBERVALUE(tsh_bs!F12)+_xlfn.NUMBERVALUE(tsh_bs!F13) -> 0.9 | G2: =_xlfn.NUMBERVALUE(tsh_bs!G12)+_xlfn.NUMBERVALUE(tsh_bs!G13) -> 0.9 | H2: =_xlfn.NUMBERVALUE(tsh_bs!H12)+_xlfn.NUMBERVALUE(tsh_bs!H13) -> 1.1 | I2: =_xlfn.NUMBERVALUE(tsh_bs!I12)+_xlfn.NUMBERVALUE(tsh_bs!I13) -> 1.1 | J2: =_xlfn.NUMBERVALUE(tsh_bs!J12)+_xlfn.NUMBERVALUE(tsh_bs!J13) -> 1 | K2: =_xlfn.NUMBERVALUE(tsh_bs!K12)+_xlfn.NUMBERVALUE(tsh_bs!K13) -> 1 | ... AK2: =_xlfn.NUMBERVALUE(tsh_bs!AK12)+_xlfn.NUMBERVALUE(tsh_bs!AK13) -> 2.3
A3: AR | C3: 0.8 | D3: =_xlfn.NUMBERVALUE(tsh_bs!D14) -> 0 | E3: =_xlfn.NUMBERVALUE(tsh_bs!E14) -> 0 | F3: =_xlfn.NUMBERVALUE(tsh_bs!F14) -> 0.2 | G3: =_xlfn.NUMBERVALUE(tsh_bs!G14) -> 0.2 | H3: =_xlfn.NUMBERVALUE(tsh_bs!H14) -> 0.2 | I3: =_xlfn.NUMBERVALUE(tsh_bs!I14) -> 0.2 | J3: =_xlfn.NUMBERVALUE(tsh_bs!J14) -> 0.1 | K3: =_xlfn.NUMBERVALUE(tsh_bs!K14) -> 0.1 | ... AK3: =_xlfn.NUMBERVALUE(tsh_bs!AK14) -> 0.7
A4: Inventory | C4: 0.6 | D4: =_xlfn.NUMBERVALUE(tsh_bs!D15) -> 0 | E4: =_xlfn.NUMBERVALUE(tsh_bs!E15) -> 0 | F4: =_xlfn.NUMBERVALUE(tsh_bs!F15) -> 2.6 | G4: =_xlfn.NUMBERVALUE(tsh_bs!G15) -> 2.6 | H4: =_xlfn.NUMBERVALUE(tsh_bs!H15) -> 2.6 | I4: =_xlfn.NUMBERVALUE(tsh_bs!I15) -> 2.6 | J4: =_xlfn.NUMBERVALUE(tsh_bs!J15) -> 2.8 | K4: =_xlfn.NUMBERVALUE(tsh_bs!K15) -> 2.8 | ... AK4: =_xlfn.NUMBERVALUE(tsh_bs!AK15) -> 9.6
A5: Current Assets | D5: =_xlfn.NUMBERVALUE(tsh_bs!D18) -> 0 | E5: =_xlfn.NUMBERVALUE(tsh_bs!E18) -> 0 | F5: =_xlfn.NUMBERVALUE(tsh_bs!F18) -> 4 | G5: =_xlfn.NUMBERVALUE(tsh_bs!G18) -> 4 | H5: =_xlfn.NUMBERVALUE(tsh_bs!H18) -> 4.2 | I5: =_xlfn.NUMBERVALUE(tsh_bs!I18) -> 4.2 | J5: =_xlfn.NUMBERVALUE(tsh_bs!J18) -> 4.3 | K5: =_xlfn.NUMBERVALUE(tsh_bs!K18) -> 4.3 | ... AK5: =_xlfn.NUMBERVALUE(tsh_bs!AK18) -> 12.6
A6: Discounted CA | D6: =D3*$C$3+$C$4*D4+D2 -> 0 | E6: =E3*$C$3+$C$4*E4+E2 -> 0 | F6: =F3*$C$3+$C$4*F4+F2 -> 2.62 | G6: =G3*$C$3+$C$4*G4+G2 -> 2.62 | H6: =H3*$C$3+$C$4*H4+H2 -> 2.82 | I6: =I3*$C$3+$C$4*I4+I2 -> 2.82 | J6: =J3*$C$3+$C$4*J4+J2 -> 2.76 | K6: =K3*$C$3+$C$4*K4+K2 -> 2.76 | ... AK6: =AK3*$C$3+$C$4*AK4+AK2 -> 8.62
A9: Total Assets | D9: =_xlfn.NUMBERVALUE(tsh_bs!D27) -> 0 | E9: =_xlfn.NUMBERVALUE(tsh_bs!E27) -> 0 | F9: =_xlfn.NUMBERVALUE(tsh_bs!F27) -> 4.9 | G9: =_xlfn.NUMBERVALUE(tsh_bs!G27) -> 4.9 | H9: =_xlfn.NUMBERVALUE(tsh_bs!H27) -> 4.9 | I9: =_xlfn.NUMBERVALUE(tsh_bs!I27) -> 4.9 | J9: =_xlfn.NUMBERVALUE(tsh_bs!J27) -> 5.9 | K9: =_xlfn.NUMBERVALUE(tsh_bs!K27) -> 5.9 | ... AK9: =_xlfn.NUMBERVALUE(tsh_bs!AK27) -> 14.1
A10: Intangible Assets | D10: =_xlfn.NUMBERVALUE(SUM(tsh_bs!D24:D25)) -> 0 | E10: =_xlfn.NUMBERVALUE(SUM(tsh_bs!E24:E25)) -> 0 | F10: =_xlfn.NUMBERVALUE(SUM(tsh_bs!F24:F25)) -> 0 | G10: =_xlfn.NUMBERVALUE(SUM(tsh_bs!G24:G25)) -> 0 | H10: =_xlfn.NUMBERVALUE(SUM(tsh_bs!H24:H25)) -> 0 | I10: =_xlfn.NUMBERVALUE(SUM(tsh_bs!I24:I25)) -> 0 | J10: =_xlfn.NUMBERVALUE(SUM(tsh_bs!J24:J25)) -> 0 | K10: =_xlfn.NUMBERVALUE(SUM(tsh_bs!K24:K25)) -> 0 | ... AK10: =_xlfn.NUMBERVALUE(SUM(tsh_bs!AK24:AK25)) -> 0
A12: Current Liabilities | D12: =_xlfn.NUMBERVALUE(tsh_bs!D35) -> 0 | E12: =_xlfn.NUMBERVALUE(tsh_bs!E35) -> 0 | F12: =_xlfn.NUMBERVALUE(tsh_bs!F35) -> 3 | G12: =_xlfn.NUMBERVALUE(tsh_bs!G35) -> 3 | H12: =_xlfn.NUMBERVALUE(tsh_bs!H35) -> 2.4 | I12: =_xlfn.NUMBERVALUE(tsh_bs!I35) -> 2.4 | J12: =_xlfn.NUMBERVALUE(tsh_bs!J35) -> 2.1 | K12: =_xlfn.NUMBERVALUE(tsh_bs!K35) -> 2.1 | ... AK12: =_xlfn.NUMBERVALUE(tsh_bs!AK35) -> 3.7
A13: Total Liabilities | D13: =_xlfn.NUMBERVALUE(tsh_bs!D40) -> 0 | E13: =_xlfn.NUMBERVALUE(tsh_bs!E40) -> 0 | F13: =_xlfn.NUMBERVALUE(tsh_bs!F40) -> 3.1 | G13: =_xlfn.NUMBERVALUE(tsh_bs!G40) -> 3.1 | H13: =_xlfn.NUMBERVALUE(tsh_bs!H40) -> 2.5 | I13: =_xlfn.NUMBERVALUE(tsh_bs!I40) -> 2.5 | J13: =_xlfn.NUMBERVALUE(tsh_bs!J40) -> 2.3 | K13: =_xlfn.NUMBERVALUE(tsh_bs!K40) -> 2.3 | ... AK13: =_xlfn.NUMBERVALUE(tsh_bs!AK40) -> 4.4
A15: Debt | D15: =_xlfn.NUMBERVALUE(tsh_bs!D32)+_xlfn.NUMBERVALUE(tsh_bs!D37)+_xlfn.NUMBERVALUE(tsh_bs!D31) -> 0 | E15: =_xlfn.NUMBERVALUE(tsh_bs!E32)+_xlfn.NUMBERVALUE(tsh_bs!E37)+_xlfn.NUMBERVALUE(tsh_bs!E31) -> 0 | F15: =_xlfn.NUMBERVALUE(tsh_bs!F32)+_xlfn.NUMBERVALUE(tsh_bs!F37)+_xlfn.NUMBERVALUE(tsh_bs!F31) -> 2.3 | G15: =_xlfn.NUMBERVALUE(tsh_bs!G32)+_xlfn.NUMBERVALUE(tsh_bs!G37)+_xlfn.NUMBERVALUE(tsh_bs!G31) -> 2.3 | H15: =_xlfn.NUMBERVALUE(tsh_bs!H32)+_xlfn.NUMBERVALUE(tsh_bs!H37)+_xlfn.NUMBERVALUE(tsh_bs!H31) -> 1.7 | I15: =_xlfn.NUMBERVALUE(tsh_bs!I32)+_xlfn.NUMBERVALUE(tsh_bs!I37)+_xlfn.NUMBERVALUE(tsh_bs!I31) -> 1.7 | J15: =_xlfn.NUMBERVALUE(tsh_bs!J32)+_xlfn.NUMBERVALUE(tsh_bs!J37)+_xlfn.NUMBERVALUE(tsh_bs!J31) -> 0.7 | K15: =_xlfn.NUMBERVALUE(tsh_bs!K32)+_xlfn.NUMBERVALUE(tsh_bs!K37)+_xlfn.NUMBERVALUE(tsh_bs!K31) -> 0.7 | ... AK15: =_xlfn.NUMBERVALUE(tsh_bs!AK32)+_xlfn.NUMBERVALUE(tsh_bs!AK37)+_xlfn.NUMBERVALUE(tsh_bs!AK31) -> 0.4
A16: Equity | D16: =_xlfn.NUMBERVALUE(tsh_bs!D51) -> 0.7 | E16: =_xlfn.NUMBERVALUE(tsh_bs!E51) -> 0 | F16: =_xlfn.NUMBERVALUE(tsh_bs!F51) -> 1.8 | G16: =_xlfn.NUMBERVALUE(tsh_bs!G51) -> 1.8 | H16: =_xlfn.NUMBERVALUE(tsh_bs!H51) -> 2.4 | I16: =_xlfn.NUMBERVALUE(tsh_bs!I51) -> 2.4 | J16: =_xlfn.NUMBERVALUE(tsh_bs!J51) -> 3.6 | K16: =_xlfn.NUMBERVALUE(tsh_bs!K51) -> 3.6 | ... AK16: =_xlfn.NUMBERVALUE(tsh_bs!AK51) -> 9.7
A18: Net Tangible Assets | D18: =D9-D10-D13 -> 0 | E18: =E9-E10-E13 -> 0 | F18: =F9-F10-F13 -> 1.8 | G18: =G9-G10-G13 -> 1.8 | H18: =H9-H10-H13 -> 2.4 | I18: =I9-I10-I13 -> 2.4 | J18: =J9-J10-J13 -> 3.6 | K18: =K9-K10-K13 -> 3.6 | ... AK18: =AK9-AK10-AK13 -> 9.7
A20: Shares Outstanding | D20: =_xlfn.NUMBERVALUE(tsh_IS!D40) -> 0 | E20: =_xlfn.NUMBERVALUE(tsh_IS!E40) -> 0 | F20: =_xlfn.NUMBERVALUE(tsh_IS!F40) -> 0 | G20: =_xlfn.NUMBERVALUE(tsh_IS!G40) -> 0 | H20: =_xlfn.NUMBERVALUE(tsh_IS!H40) -> 32.3 | I20: =_xlfn.NUMBERVALUE(tsh_IS!I40) -> 32.3 | J20: =_xlfn.NUMBERVALUE(tsh_IS!J40) -> 32.3 | K20: =_xlfn.NUMBERVALUE(tsh_IS!K40) -> 32.3 | ... AK20: =_xlfn.NUMBERVALUE(tsh_IS!AK40) -> 44.4
A22: Net Cash | D22: =IF(D2-D13>0,D2-D13, "NA") -> NA | E22: =IF(E2-E13>0,E2-E13, "NA") -> NA | F22: =IF(F2-F13>0,F2-F13, "NA") -> NA | G22: =IF(G2-G13>0,G2-G13, "NA") -> NA | H22: =IF(H2-H13>0,H2-H13, "NA") -> NA | I22: =IF(I2-I13>0,I2-I13, "NA") -> NA | J22: =IF(J2-J13>0,J2-J13, "NA") -> NA | K22: =IF(K2-K13>0,K2-K13, "NA") -> NA | ... AK22: =IF(AK2-AK13>0,AK2-AK13, "NA") -> NA
A23: Net Current Assets | D23: =D5-D13 -> 0 | E23: =E5-E13 -> 0 | F23: =F5-F13 -> 0.9 | G23: =G5-G13 -> 0.9 | H23: =H5-H13 -> 1.7 | I23: =I5-I13 -> 1.7 | J23: =J5-J13 -> 2 | K23: =K5-K13 -> 2 | ... AK23: =AK5-AK13 -> 8.2
A24: Discounted Net Current Assets | D24: =D6-D13 -> 0 | E24: =E6-E13 -> 0 | F24: =F6-F13 -> -0.48 | G24: =G6-G13 -> -0.48 | H24: =H6-H13 -> 0.32 | I24: =I6-I13 -> 0.32 | J24: =J6-J13 -> 0.46 | K24: =K6-K13 -> 0.46 | ... AK24: =AK6-AK13 -> 4.22
A26: Current Ratio | D26: =D5/D12 -> #DIV/0! | E26: =E5/E12 -> #DIV/0! | F26: =F5/F12 -> 1.3333333 | G26: =G5/G12 -> 1.3333333 | H26: =H5/H12 -> 1.75 | I26: =I5/I12 -> 1.75 | J26: =J5/J12 -> 2.047619 | K26: =K5/K12 -> 2.047619 | ... AK26: =AK5/AK12 -> 3.4054054
A27: 4 period ma | D27: =AVERAGE(D26:D26) -> #DIV/0! | E27: =AVERAGE(D26:E26) -> #DIV/0! | F27: =AVERAGE(D26:F26) -> #DIV/0! | G27: =AVERAGE(D26:G26) -> #DIV/0! | H27: =AVERAGE(E26:H26) -> #DIV/0! | I27: =AVERAGE(F26:I26) -> 1.5416667 | J27: =AVERAGE(G26:J26) -> 1.7202381 | K27: =AVERAGE(H26:K26) -> 1.8988095 | L27: =AVERAGE(I26:L26) -> 2.7554272 | M27: =AVERAGE(J26:M26) -> 3.6120448 | N27: =AVERAGE(K26:N26) -> 3.9705104 | ... AK27: =AVERAGE(AH26:AK26) -> 3.0693694
A29: Net Tangible Assets / Share | D29: =D18/D20 -> #DIV/0! | E29: =E18/E20 -> #DIV/0! | F29: =F18/F20 -> #DIV/0! | G29: =G18/G20 -> #DIV/0! | H29: =H18/H20 -> 0.074303406 | I29: =I18/I20 -> 0.074303406 | J29: =J18/J20 -> 0.11145511 | K29: =K18/K20 -> 0.11145511 | ... AK29: =AK18/AK20 -> 0.21846847
B30: % QoQ | E30: =E29/D29-1 -> #DIV/0! | F30: =F29/E29-1 -> #DIV/0! | G30: =G29/F29-1 -> #DIV/0! | H30: =H29/G29-1 -> #DIV/0! | I30: =I29/H29-1 -> 0 | J30: =J29/I29-1 -> 0.5 | K30: =K29/J29-1 -> 0 | L30: =L29/K29-1 -> 0.79867662 | ... AK30: =AK29/AJ29-1 -> 0
B31: % YoY | G31: =G29/D29-1 -> #DIV/0! | H31: =H29/E29-1 -> #DIV/0! | I31: =I29/F29-1 -> #DIV/0! | J31: =J29/G29-1 -> #DIV/0! | K31: =K29/H29-1 -> 0.5 | L31: =L29/I29-1 -> 1.6980149 | M31: =M29/J29-1 -> 0.79867662 | N31: =N29/K29-1 -> 0.75807057 | ... AK31: =AK29/AH29-1 -> 0.12790698
A34: NCAV / Share | D34: =D23/D20 -> #DIV/0! | E34: =E23/E20 -> #DIV/0! | F34: =F23/F20 -> #DIV/0! | G34: =G23/G20 -> #DIV/0! | H34: =H23/H20 -> 0.052631579 | I34: =I23/I20 -> 0.052631579 | J34: =J23/J20 -> 0.061919505 | K34: =K23/K20 -> 0.061919505 | ... AK34: =AK23/AK20 -> 0.18468468
B35: % QoQ | E35: =E34/D34-1 -> #DIV/0! | F35: =F34/E34-1 -> #DIV/0! | G35: =G34/F34-1 -> #DIV/0! | H35: =H34/G34-1 -> #DIV/0! | I35: =I34/H34-1 -> 0 | J35: =J34/I34-1 -> 0.17647059 | K35: =K34/J34-1 -> 0 | L35: =L34/K34-1 -> 1.0568396 | ... AK35: =AK34/AJ34-1 -> 0
B36: % YoY | H36: =H34/D34-1 -> #DIV/0! | I36: =I34/E34-1 -> #DIV/0! | J36: =J34/F34-1 -> #DIV/0! | K36: =K34/G34-1 -> #DIV/0! | L36: =L34/H34-1 -> 1.4198113 | M36: =M34/I34-1 -> 1.4198113 | N36: =N34/J34-1 -> 0.89144144 | O36: =O34/K34-1 -> 0.89144144 | ... AK36: =AK34/AG34-1 -> 0.54716981
A38: Discounted NCAV / Share | D38: =D24/D20 -> #DIV/0! | E38: =E24/E20 -> #DIV/0! | F38: =F24/F20 -> #DIV/0! | G38: =G24/G20 -> #DIV/0! | H38: =H24/H20 -> 0.0099071207 | I38: =I24/I20 -> 0.0099071207 | J38: =J24/J20 -> 0.014241486 | K38: =K24/K20 -> 0.014241486 | ... AK38: =AK24/AK20 -> 0.095045045
A41: Net Cash / Share | D41: =IFERROR(D22/D20, "NA") -> NA | E41: =IFERROR(E22/E20, "NA") -> NA | F41: =IFERROR(F22/F20, "NA") -> NA | G41: =IFERROR(G22/G20, "NA") -> NA | H41: =IFERROR(H22/H20, "NA") -> NA | I41: =IFERROR(I22/I20, "NA") -> NA | J41: =IFERROR(J22/J20, "NA") -> NA | K41: =IFERROR(K22/K20, "NA") -> NA | ... AK41: =IFERROR(AK22/AK20, "NA") -> NA
B42: % QoQ | D42: =IFERROR(D41/#REF!-1, "NA") -> NA | E42: =IFERROR(E41/D41-1, "NA") -> NA | F42: =IFERROR(F41/E41-1, "NA") -> NA | G42: =IFERROR(G41/F41-1, "NA") -> NA | H42: =IFERROR(H41/G41-1, "NA") -> NA | I42: =IFERROR(I41/H41-1, "NA") -> NA | J42: =IFERROR(J41/I41-1, "NA") -> NA | K42: =IFERROR(K41/J41-1, "NA") -> NA | L42: =IFERROR(L41/K41-1, "NA") -> NA | ... AK42: =IFERROR(AK41/AJ41-1, "NA") -> NA
A45: Price | AK45: 0.12 | AL45: Buy below: | AM45: =AK34*AM46 -> 0.12318468
A46: P / NCAV | AK46: =AK45/AK34 -> 0.6497561 | AM46: 0.667
A47: P / Discounted NCAV | AK47: =AK45/AK38 -> 1.2625592
A48: P / NTA | AK48: =AK45/AK29 -> 0.54927835
A49: P / Net Cash | AK49: =IFERROR(AK45/AK41, "NA") -> NA
A52: D / Assets | D52: =D15/D9 -> #DIV/0! | E52: =E15/E9 -> #DIV/0! | F52: =F15/F9 -> 0.46938776 | G52: =G15/G9 -> 0.46938776 | H52: =H15/H9 -> 0.34693878 | I52: =I15/I9 -> 0.34693878 | J52: =J15/J9 -> 0.11864407 | K52: =K15/K9 -> 0.11864407 | ... AK52: =AK15/AK9 -> 0.028368794
A53: D / E | D53: =D15/D16 -> 0 | E53: =E15/E16 -> #DIV/0! | F53: =F15/F16 -> 1.2777778 | G53: =G15/G16 -> 1.2777778 | H53: =H15/H16 -> 0.70833333 | I53: =I15/I16 -> 0.70833333 | J53: =J15/J16 -> 0.19444444 | K53: =K15/K16 -> 0.19444444 | ... AK53: =AK15/AK16 -> 0.041237113
A54: Total Liabilities / Equity | D54: =D13/D16 -> 0 | E54: =E13/E16 -> #DIV/0! | F54: =F13/F16 -> 1.7222222 | G54: =G13/G16 -> 1.7222222 | H54: =H13/H16 -> 1.0416667 | I54: =I13/I16 -> 1.0416667 | J54: =J13/J16 -> 0.63888889 | K54: =K13/K16 -> 0.63888889 | ... AK54: =AK13/AK16 -> 0.45360825

Sheet profitability
C1: 2017-03-31 | D1: 2017-06-30 | E1: 2017-09-30 | F1: 2017-12-31 | G1: 2018-03-31 | H1: 2018-06-30 | I1: 2018-09-30 | J1: 2018-12-31 | K1: 2019-03-31 | L1: 2019-06-30 | M1: 2019-09-30 | N1: 2019-12-31 | O1: 2020-03-31 | P1: 2020-06-30 | Q1: 2020-09-30 | R1: 2020-12-31 | S1: 2021-03-31 | T1: 2021-06-30 | U1: 2021-09-30 | V1: 2021-12-31 | W1: 2022-03-31 | X1: 2022-06-30 | Y1: 2022-09-30 | Z1: 2022-12-31 | AA1: 2023-03-31 | AB1: 2023-06-30 | AC1: 2023-09-30 | AD1: 2023-12-31 | AE1: 2024-03-31 | AF1: 2024-06-30 | AG1: 2024-09-30 | AH1: 2024-12-31 | AI1: 2025-03-31 | AJ1: 2025-06-30
A2: Sales | C2: =_xlfn.NUMBERVALUE(tsh_IS!D12) -> 1.2 | D2: =_xlfn.NUMBERVALUE(tsh_IS!E12) -> 1.2 | E2: =_xlfn.NUMBERVALUE(tsh_IS!F12) -> 1.4 | F2: =_xlfn.NUMBERVALUE(tsh_IS!G12) -> 1.4 | G2: =_xlfn.NUMBERVALUE(tsh_IS!H12) -> 1.7 | H2: =_xlfn.NUMBERVALUE(tsh_IS!I12) -> 1.7 | I2: =_xlfn.NUMBERVALUE(tsh_IS!J12) -> 1.6 | J2: =_xlfn.NUMBERVALUE(tsh_IS!K12) -> 1.6 | ... AJ2: =_xlfn.NUMBERVALUE(tsh_IS!AK12) -> 2.8
B3: % QoQ | D3: =D2/C2-1 -> 0 | E3: =E2/D2-1 -> 0.16666667 | F3: =F2/E2-1 -> 0 | G3: =G2/F2-1 -> 0.21428571 | H3: =H2/G2-1 -> 0 | I3: =I2/H2-1 -> -0.058823529 | J3: =J2/I2-1 -> 0 | K3: =K2/J2-1 -> 0.1875 | ... V3: =V2/U2-1 -> 0 | W3: =W2/U2-1 -> 0.30769231 | X3: =X2/U2-1 -> 0.30769231 | Y3: =Y2/U2-1 -> 1.0769231 | Z3: =Z2/U2-1 -> 1.0769231 | AA3: =AA2/U2-1 -> 0.92307692 | AB3: =AB2/U2-1 -> 0.92307692 | AC3: =AC2/U2-1 -> 1.3076923 | AD3: =AD2/U2-1 -> 1.3076923 | AE3: =AE2/U2-1 -> 0.92307692 | AF3: =AF2/U2-1 -> 0.92307692 | AG3: =AG2/U2-1 -> 1.5384615 | AH3: =AH2/U2-1 -> 1.5384615 | AI3: =AI2/U2-1 -> 1.1538462 | AJ3: =AJ2/U2-1 -> 1.1538462
B4: % YoY | G4: =G2/C2-1 -> 0.41666667 | H4: =H2/D2-1 -> 0.41666667 | I4: =I2/E2-1 -> 0.14285714 | J4: =J2/F2-1 -> 0.14285714 | K4: =K2/G2-1 -> 0.11764706 | L4: =L2/H2-1 -> 0.11764706 | M4: =M2/I2-1 -> 0.25 | N4: =N2/J2-1 -> 0.25 | ... V4: =V2/R2-1 -> 0.083333333 | W4: =W2/R2-1 -> 0.41666667 | X4: =X2/R2-1 -> 0.41666667 | Y4: =Y2/R2-1 -> 1.25 | Z4: =Z2/R2-1 -> 1.25 | AA4: =AA2/R2-1 -> 1.0833333 | AB4: =AB2/R2-1 -> 1.0833333 | AC4: =AC2/R2-1 -> 1.5 | AD4: =AD2/R2-1 -> 1.5 | AE4: =AE2/R2-1 -> 1.0833333 | AF4: =AF2/R2-1 -> 1.0833333 | AG4: =AG2/R2-1 -> 1.75 | AH4: =AH2/R2-1 -> 1.75 | AI4: =AI2/R2-1 -> 1.3333333 | AJ4: =AJ2/R2-1 -> 1.3333333
A6: Gross Income | C6: =_xlfn.NUMBERVALUE(tsh_IS!D16) -> 0.7 | D6: =_xlfn.NUMBERVALUE(tsh_IS!E16) -> 0.7 | E6: =_xlfn.NUMBERVALUE(tsh_IS!F16) -> 1.1 | F6: =_xlfn.NUMBERVALUE(tsh_IS!G16) -> 1.1 | G6: =_xlfn.NUMBERVALUE(tsh_IS!H16) -> 1.1 | H6: =_xlfn.NUMBERVALUE(tsh_IS!I16) -> 1.1 | I6: =_xlfn.NUMBERVALUE(tsh_IS!J16) -> 1.3 | J6: =_xlfn.NUMBERVALUE(tsh_IS!K16) -> 1.3 | ... AJ6: =_xlfn.NUMBERVALUE(tsh_IS!AK16) -> 2.1
B7: % Margin | C7: =C6/C2 -> 0.58333333 | D7: =D6/D2 -> 0.58333333 | E7: =E6/E2 -> 0.78571429 | F7: =F6/F2 -> 0.78571429 | G7: =G6/G2 -> 0.64705882 | H7: =H6/H2 -> 0.64705882 | I7: =I6/I2 -> 0.8125 | J7: =J6/J2 -> 0.8125 | ... AJ7: =AJ6/AJ2 -> 0.75
B8: % Margin 4 per MA | C8: =AVERAGE(C7:C7) -> 0.58333333 | D8: =AVERAGE(C7:D7) -> 0.58333333 | E8: =AVERAGE(C7:E7) -> 0.65079365 | F8: =AVERAGE(C7:F7) -> 0.68452381 | G8: =AVERAGE(D7:G7) -> 0.70045518 | H8: =AVERAGE(E7:H7) -> 0.71638655 | I8: =AVERAGE(F7:I7) -> 0.72308298 | J8: =AVERAGE(G7:J7) -> 0.72977941 | K8: =AVERAGE(H7:K7) -> 0.75222523 | L8: =AVERAGE(I7:L7) -> 0.77467105 | M8: =AVERAGE(J7:M7) -> 0.75904605 | ... V8: =AVERAGE(S7:V7) -> 0.73076923 | W8: =AVERAGE(S7:W7) -> 0.73755656 | X8: =AVERAGE(S7:X7) -> 0.74208145 | Y8: =AVERAGE(S7:Y7) -> 0.74718092 | Z8: =AVERAGE(S7:Z7) -> 0.75100553 | AA8: =AVERAGE(S7:AA7) -> 0.74756047 | AB8: =AVERAGE(S7:AB7) -> 0.74480442 | AC8: =AVERAGE(S7:AC7) -> 0.7467919 | AD8: =AVERAGE(S7:AD7) -> 0.74844813 | AE8: =AVERAGE(S7:AE7) -> 0.74933674 | AF8: =AVERAGE(S7:AF7) -> 0.7500984 | AG8: =AVERAGE(S7:AG7) -> 0.75059689 | AH8: =AVERAGE(S7:AH7) -> 0.75103307 | AI8: =AVERAGE(S7:AI7) -> 0.7509723 | AJ8: =AVERAGE(S7:AJ7) -> 0.75091828
A10: Net Income | C10: =_xlfn.NUMBERVALUE(tsh_IS!D32) -> 0.1 | D10: =_xlfn.NUMBERVALUE(tsh_IS!E32) -> 0.1 | E10: =_xlfn.NUMBERVALUE(tsh_IS!F32) -> 0.4 | F10: =_xlfn.NUMBERVALUE(tsh_IS!G32) -> 0.4 | G10: =_xlfn.NUMBERVALUE(tsh_IS!H32) -> 0.3 | H10: =_xlfn.NUMBERVALUE(tsh_IS!I32) -> 0.3 | I10: =_xlfn.NUMBERVALUE(tsh_IS!J32) -> -0.1 | J10: =_xlfn.NUMBERVALUE(tsh_IS!K32) -> -0.1 | ... AJ10: =_xlfn.NUMBERVALUE(tsh_IS!AK32) -> 0.2
B11: % Margin | C11: =C10/C2 -> 0.083333333 | D11: =D10/D2 -> 0.083333333 | E11: =E10/E2 -> 0.28571429 | F11: =F10/F2 -> 0.28571429 | G11: =G10/G2 -> 0.17647059 | H11: =H10/H2 -> 0.17647059 | I11: =I10/I2 -> -0.0625 | J11: =J10/J2 -> -0.0625 | ... AJ11: =AJ10/AJ2 -> 0.071428571

Sheet piotrosky
A1: 1 | B1: Positive earnings | K1: 1 | L1: AUTO: NI = 0 (positive) | M1: =profitability!AJ10 -> 0.2 | N1: 2025-06-30
A2: =A1+1 -> 2 | B2: Positive CF | K2: 1 | L2: MANUAL: OCF data not available in standard export
A3: =A2+1 -> 3 | B3: Increasing ROA | K3: 0 | L3: AUTO: ROA: 2.92% -> 2.91% (↓) | M3: ro!AI21; ro!AJ21 | N3: 2025-03-31 → 2025-06-30
A4: =A3+1 -> 4 | B4: Increasing CFO | K4: 1 | L4: MANUAL: OCF data not available for accruals check
A5: =A4+1 -> 5 | B5: Decreasing long term debt as a proportion of total assets | K5: 1 | L5: AUTO: D/A: 4.26% -> 2.84% (↓) | M5: ncav!AI52; ncav!AK52 | N5: 2024-12-31 → 2025-06-30
A6: =A5+1 -> 6 | B6: increasing current ratio | K6: 1 | L6: AUTO: CR: 2.73x -> 3.41x (↑) | M6: ncav!AI26; ncav!AK26 | N6: 2024-12-31 → 2025-06-30
A7: =A6+1 -> 7 | B7: decreasing or stable numbers of standing shares | K7: 1 | L7: AUTO: Shares: 44 -> 44 (stable/↓) | M7: ncav!AI20; ncav!AK20 | N7: 2024-12-31 → 2025-06-30
A8: =A7+1 -> 8 | B8: increasing assets turnover (increasing sales as a proportion of total assets) | K8: 0 | L8: AUTO: AT: 0.82x -> 0.82x (↓) | M8: ro!AI33; ro!AJ33 | N8: 2025-03-31 → 2025-06-30
A9: =A8+1 -> 9 | B9: increasing gross margin | K9: 0 | L9: AUTO: GM: 89.3% -> 75.0% (↓) | M9: profitability!AI7; profitability!AJ7 | N9: 2025-03-31 → 2025-06-30
A10: Piotrosky score | K10: =SUM(K1:K9) -> 6

Sheet C7
A1: Core 9 Criteria
A2: Not Majority Chinese | H2: 1 | I2: MANUAL: Check company domicile manually
A3: Low Price-to-NACV (less than 67%) | H3: 1 | I3: AUTO: P/NCAV = 8257.32 (threshold: 0.67) | J3: =ncav!AK34 -> 0.18468468 | K3: 2025-06-30
A4: Low Debt-to-Equity | H4: 1 | I4: AUTO: D/E = 0.04 (threshold: 0.5) | J4: =ncav!AK53 -> 0.041237113 | K4: 2025-06-30
A5: Adequate Past Earnings or Catalyst (5%+ NI Margin) | H5: 1 | I5: AUTO: Max NI margin = 28.6% (threshold: 5%) | J5: =profitability!E11 -> 0.28571429 | K5: 2017-09-30
A6: Past Price Above NCAV | H6: 1 | I6: MANUAL: Requires historical price data
A7: Existing Operations or Liquidation | H7: 1 | I7: MANUAL: Qualitative assessment required
A8: Not Selling Shares | H8: 1 | I8: AUTO: Shares: 44 -> 44 | J8: ncav!AI20; ncav!AK20 | K8: 2024-12-31 → 2025-06-30
A9: Market Cap <$50mm | H9: 1 | I9: MANUAL: Market cap = 67,710 (currency/unit check needed) | J9: =ncav!AK20 -> 44.4 | K9: 2025-06-30
A10: Low NCAV Burn Rate | H10: 1 | I10: AUTO: Calculated NCAV YoY: 20.6% | J10: ncav!AI34; ncav!AK34 | K10: 2024-12-31 → 2025-06-30
A11: Total | H11: =SUM(H2:H10) -> 9 | I11: =SUM(I2:I10) -> 0 | J11: =SUM(J2:J10) -> 44.911636 | K11: =SUM(K2:K10) -> 0 | L11: =SUM(L2:L10) -> 0 | M11: =SUM(M2:M10) -> 0 | N11: =SUM(N2:N10) -> 0 | O11: =SUM(O2:O10) -> 0 | ... AQ11: =SUM(AQ2:AQ10) -> 0
A13: Ranking Criteria (out of 9)
A14: Large Current Ratio (over 1.5x) | H14: 1 | I14: AUTO: CR = 3.41x (threshold: 1.5x) | J14: =ncav!AK26 -> 3.4054054 | K14: 2025-06-30
A15: Not financial/real estate/closed end fund | H15: 1 | I15: MANUAL: Check industry classification manually
A16: Company is buying back stock | H16: 0 | I16: AUTO: Shares: 44 -> 44 (no buyback) | J16: ncav!AI20; ncav!AK20 | K16: 2024-12-31 → 2025-06-30
A17: Low Price-to-Net Cash | H17: 0 | I17: MANUAL: Net cash calculation requires manual review
A18: Insider Ownership | H18: 1 | I18: MANUAL: Check ownership sheet manually
A19: Insider Buys vs. Sells | H19: 0 | I19: MANUAL: Requires insider transaction data
A20: Burn Rate Low or Positive | H20: 1 | I20: AUTO: NCAV YoY: 20.6% | J20: ncav!AI34; ncav!AK34 | K20: 2024-12-31 → 2025-06-30
A21: Insider Pay | H21: 1 | I21: MANUAL: Qualitative assessment required
A22: Dividend Yield? | H22: 0 | I22: MANUAL: Requires dividend and price data
A23: Total | H23: =SUM(H14:H22) -> 5

Sheet ro
C1: 2017-03-31 | D1: 2017-06-30 | E1: 2017-09-30 | F1: 2017-12-31 | G1: 2018-03-31 | H1: 2018-06-30 | I1: 2018-09-30 | J1: 2018-12-31 | K1: 2019-03-31 | L1: 2019-06-30 | M1: 2019-09-30 | N1: 2019-12-31 | O1: 2020-03-31 | P1: 2020-06-30 | Q1: 2020-09-30 | R1: 2020-12-31 | S1: 2021-03-31 | T1: 2021-06-30 | U1: 2021-09-30 | V1: 2021-12-31 | W1: 2022-03-31 | X1: 2022-06-30 | Y1: 2022-09-30 | Z1: 2022-12-31 | AA1: 2023-03-31 | AB1: 2023-06-30 | AC1: 2023-09-30 | AD1: 2023-12-31 | AE1: 2024-03-31 | AF1: 2024-06-30 | AG1: 2024-09-30 | AH1: 2024-12-31 | AI1: 2025-03-31 | AJ1: 2025-06-30
A2: Total Assets | C2: =_xlfn.NUMBERVALUE(tsh_bs!D27) -> 0 | D2: =_xlfn.NUMBERVALUE(tsh_bs!E27) -> 0 | E2: =_xlfn.NUMBERVALUE(tsh_bs!F27) -> 4.9 | F2: =_xlfn.NUMBERVALUE(tsh_bs!G27) -> 4.9 | G2: =_xlfn.NUMBERVALUE(tsh_bs!H27) -> 4.9 | H2: =_xlfn.NUMBERVALUE(tsh_bs!I27) -> 4.9 | I2: =_xlfn.NUMBERVALUE(tsh_bs!J27) -> 5.9 | J2: =_xlfn.NUMBERVALUE(tsh_bs!K27) -> 5.9 | ... AJ2: =_xlfn.NUMBERVALUE(tsh_bs!AK27) -> 14.1
A3: 1 yr avg | D3: =AVERAGE(C2:D2) -> 0 | E3: =AVERAGE(D2:E2) -> 2.45 | F3: =AVERAGE(E2:F2) -> 4.9 | G3: =AVERAGE(F2:G2) -> 4.9 | H3: =AVERAGE(G2:H2) -> 4.9 | I3: =AVERAGE(H2:I2) -> 5.4 | J3: =AVERAGE(I2:J2) -> 5.9 | K3: =AVERAGE(J2:K2) -> 8.9 | ... V3: =AVERAGE(U2:V2) -> 11.5 | W3: =AVERAGE(U2:W2) -> 11.5 | X3: =AVERAGE(U2:X2) -> 11.5 | Y3: =AVERAGE(U2:Y2) -> 12.1 | Z3: =AVERAGE(U2:Z2) -> 12.5 | AA3: =AVERAGE(U2:AA2) -> 12.771429 | AB3: =AVERAGE(U2:AB2) -> 12.975 | AC3: =AVERAGE(U2:AC2) -> 13.211111 | AD3: =AVERAGE(U2:AD2) -> 13.4 | AE3: =AVERAGE(U2:AE2) -> 13.509091 | AF3: =AVERAGE(U2:AF2) -> 13.6 | AG3: =AVERAGE(U2:AG2) -> 13.638462 | AH3: =AVERAGE(U2:AH2) -> 13.671429 | AI3: =AVERAGE(U2:AI2) -> 13.7 | AJ3: =AVERAGE(U2:AJ2) -> 13.725
A5: Total Equity | C5: =_xlfn.NUMBERVALUE(tsh_bs!D51) -> 0.7 | D5: =_xlfn.NUMBERVALUE(tsh_bs!E51) -> 0 | E5: =_xlfn.NUMBERVALUE(tsh_bs!F51) -> 1.8 | F5: =_xlfn.NUMBERVALUE(tsh_bs!G51) -> 1.8 | G5: =_xlfn.NUMBERVALUE(tsh_bs!H51) -> 2.4 | H5: =_xlfn.NUMBERVALUE(tsh_bs!I51) -> 2.4 | I5: =_xlfn.NUMBERVALUE(tsh_bs!J51) -> 3.6 | J5: =_xlfn.NUMBERVALUE(tsh_bs!K51) -> 3.6 | ... AJ5: =_xlfn.NUMBERVALUE(tsh_bs!AK51) -> 9.7
A6: 1 yr avg | D6: =AVERAGE(C5:D5) -> 0.35 | E6: =AVERAGE(D5:E5) -> 0.9 | F6: =AVERAGE(E5:F5) -> 1.8 | G6: =AVERAGE(F5:G5) -> 2.1 | H6: =AVERAGE(G5:H5) -> 2.4 | I6: =AVERAGE(H5:I5) -> 3 | J6: =AVERAGE(I5:J5) -> 3.6 | K6: =AVERAGE(J5:K5) -> 6.05 | ... V6: =AVERAGE(U5:V5) -> 6.5 | W6: =AVERAGE(U5:W5) -> 6.6 | X6: =AVERAGE(U5:X5) -> 6.65 | Y6: =AVERAGE(U5:Y5) -> 6.78 | Z6: =AVERAGE(U5:Z5) -> 6.8666667 | AA6: =AVERAGE(U5:AA5) -> 6.9714286 | AB6: =AVERAGE(U5:AB5) -> 7.05 | AC6: =AVERAGE(U5:AC5) -> 7.1222222 | AD6: =AVERAGE(U5:AD5) -> 7.18 | AE6: =AVERAGE(U5:AE5) -> 7.2545455 | AF6: =AVERAGE(U5:AF5) -> 7.3166667 | AG6: =AVERAGE(U5:AG5) -> 7.4153846 | AH6: =AVERAGE(U5:AH5) -> 7.5 | AI6: =AVERAGE(U5:AI5) -> 7.6466667 | AJ6: =AVERAGE(U5:AJ5) -> 7.775
A8: Sales | C8: =_xlfn.NUMBERVALUE(tsh_IS!D12) -> 1.2 | D8: =_xlfn.NUMBERVALUE(tsh_IS!E12) -> 1.2 | E8: =_xlfn.NUMBERVALUE(tsh_IS!F12) -> 1.4 | F8: =_xlfn.NUMBERVALUE(tsh_IS!G12) -> 1.4 | G8: =_xlfn.NUMBERVALUE(tsh_IS!H12) -> 1.7 | H8: =_xlfn.NUMBERVALUE(tsh_IS!I12) -> 1.7 | I8: =_xlfn.NUMBERVALUE(tsh_IS!J12) -> 1.6 | J8: =_xlfn.NUMBERVALUE(tsh_IS!K12) -> 1.6 | ... AJ8: =_xlfn.NUMBERVALUE(tsh_IS!AK12) -> 2.8
A9: EBIT | C9: =_xlfn.NUMBERVALUE(tsh_IS!D23) -> 0.2 | D9: =_xlfn.NUMBERVALUE(tsh_IS!E23) -> 0.2 | E9: =_xlfn.NUMBERVALUE(tsh_IS!F23) -> 0.4 | F9: =_xlfn.NUMBERVALUE(tsh_IS!G23) -> 0.4 | G9: =_xlfn.NUMBERVALUE(tsh_IS!H23) -> 0.4 | H9: =_xlfn.NUMBERVALUE(tsh_IS!I23) -> 0.4 | I9: =_xlfn.NUMBERVALUE(tsh_IS!J23) -> -0.1 | J9: =_xlfn.NUMBERVALUE(tsh_IS!K23) -> -0.1 | ... AJ9: =_xlfn.NUMBERVALUE(tsh_IS!AK23) -> 0.2
A10: NI | C10: =_xlfn.NUMBERVALUE(tsh_IS!D29) -> 0.1 | D10: =_xlfn.NUMBERVALUE(tsh_IS!E29) -> 0.1 | E10: =_xlfn.NUMBERVALUE(tsh_IS!F29) -> 0.4 | F10: =_xlfn.NUMBERVALUE(tsh_IS!G29) -> 0.4 | G10: =_xlfn.NUMBERVALUE(tsh_IS!H29) -> 0.3 | H10: =_xlfn.NUMBERVALUE(tsh_IS!I29) -> 0.3 | I10: =_xlfn.NUMBERVALUE(tsh_IS!J29) -> -0.1 | J10: =_xlfn.NUMBERVALUE(tsh_IS!K29) -> -0.1 | ... AJ10: =_xlfn.NUMBERVALUE(tsh_IS!AK29) -> 0.2
A12: Semi-Annually
A13: ROA (EBIT) | D13: =D9/D3 -> #DIV/0! | E13: =E9/E3 -> 0.16326531 | F13: =F9/F3 -> 0.081632653 | G13: =G9/G3 -> 0.081632653 | H13: =H9/H3 -> 0.081632653 | I13: =I9/I3 -> -0.018518519 | J13: =J9/J3 -> -0.016949153 | K13: =K9/K3 -> 0.02247191 | ... AJ13: =AJ9/AJ3 -> 0.014571949
A14: ROA (NI) | D14: =D10/D3 -> #DIV/0! | E14: =E10/E3 -> 0.16326531 | F14: =F10/F3 -> 0.081632653 | G14: =G10/G3 -> 0.06122449 | H14: =H10/H3 -> 0.06122449 | I14: =I10/I3 -> -0.018518519 | J14: =J10/J3 -> -0.016949153 | K14: =K10/K3 -> 0.02247191 | ... AJ14: =AJ10/AJ3 -> 0.014571949
A16: ROE (EBIT) | D16: =D9/D6 -> 0.57142857 | E16: =E9/E6 -> 0.44444444 | F16: =F9/F6 -> 0.22222222 | G16: =G9/G6 -> 0.19047619 | H16: =H9/H6 -> 0.16666667 | I16: =I9/I6 -> -0.033333333 | J16: =J9/J6 -> -0.027777778 | K16: =K9/K6 -> 0.033057851 | ... AJ16: =AJ9/AJ6 -> 0.025723473
A17: ROE (NI) | D17: =D10/D6 -> 0.28571429 | E17: =E10/E6 -> 0.44444444 | F17: =F10/F6 -> 0.22222222 | G17: =G10/G6 -> 0.14285714 | H17: =H10/H6 -> 0.125 | I17: =I10/I6 -> -0.033333333 | J17: =J10/J6 -> -0.027777778 | K17: =K10/K6 -> 0.033057851 | ... AJ17: =AJ10/AJ6 -> 0.025723473
A19: Annualized
A20: ROA (EBIT) | D20: =D13*2 -> #DIV/0! | E20: =E13*2 -> 0.32653061 | F20: =F13*2 -> 0.16326531 | G20: =G13*2 -> 0.16326531 | H20: =H13*2 -> 0.16326531 | I20: =I13*2 -> -0.037037037 | J20: =J13*2 -> -0.033898305 | K20: =K13*2 -> 0.04494382 | ... AJ20: =AJ13*2 -> 0.029143898
A21: ROA (NI) | D21: =D14*2 -> #DIV/0! | E21: =E14*2 -> 0.32653061 | F21: =F14*2 -> 0.16326531 | G21: =G14*2 -> 0.12244898 | H21: =H14*2 -> 0.12244898 | I21: =I14*2 -> -0.037037037 | J21: =J14*2 -> -0.033898305 | K21: =K14*2 -> 0.04494382 | ... AJ21: =AJ14*2 -> 0.029143898
A23: ROE (EBIT) | D23: =D16*2 -> 1.1428571 | E23: =E16*2 -> 0.88888889 | F23: =F16*2 -> 0.44444444 | G23: =G16*2 -> 0.38095238 | H23: =H16*2 -> 0.33333333 | I23: =I16*2 -> -0.066666667 | J23: =J16*2 -> -0.055555556 | K23: =K16*2 -> 0.066115702 | ... AJ23: =AJ16*2 -> 0.051446945
A24: ROE (NI) | D24: =D17*2 -> 0.57142857 | E24: =E17*2 -> 0.88888889 | F24: =F17*2 -> 0.44444444 | G24: =G17*2 -> 0.28571429 | H24: =H17*2 -> 0.25 | I24: =I17*2 -> -0.066666667 | J24: =J17*2 -> -0.055555556 | K24: =K17*2 -> 0.066115702 | ... AJ24: =AJ17*2 -> 0.051446945
A26: TTM
A27: ROA (EBIT) | G27: =SUM(F9:G9)/AVERAGE(E2,G2) -> 0.16326531 | H27: =SUM(G9:H9)/AVERAGE(F2,H2) -> 0.16326531 | I27: =SUM(H9:I9)/AVERAGE(G2,I2) -> 0.055555556 | J27: =SUM(I9:J9)/AVERAGE(H2,J2) -> -0.037037037 | K27: =SUM(J9:K9)/AVERAGE(I2,K2) -> 0.011235955 | L27: =SUM(K9:L9)/AVERAGE(J2,L2) -> 0.04494382 | M27: =SUM(L9:M9)/AVERAGE(K2,M2) -> 0.024193548 | N27: =SUM(M9:N9)/AVERAGE(L2,N2) -> 0.016129032 | ... AJ27: =SUM(AI9:AJ9)/AVERAGE(AH2,AJ2) -> 0.028368794
A28: ROA (NI) | G28: =SUM(F10:G10)/AVERAGE(E2,G2) -> 0.14285714 | H28: =SUM(G10:H10)/AVERAGE(F2,H2) -> 0.12244898 | I28: =SUM(H10:I10)/AVERAGE(G2,I2) -> 0.037037037 | J28: =SUM(I10:J10)/AVERAGE(H2,J2) -> -0.037037037 | K28: =SUM(J10:K10)/AVERAGE(I2,K2) -> 0.011235955 | L28: =SUM(K10:L10)/AVERAGE(J2,L2) -> 0.04494382 | M28: =SUM(L10:M10)/AVERAGE(K2,M2) -> 0.024193548 | N28: =SUM(M10:N10)/AVERAGE(L2,N2) -> 0.016129032 | ... AJ28: =SUM(AI10:AJ10)/AVERAGE(AH2,AJ2) -> 0.028368794
A30: ROE (EBIT) | G30: =SUM(F9:G9)/AVERAGE(E5,G5) -> 0.38095238 | H30: =SUM(G9:H9)/AVERAGE(F5,H5) -> 0.38095238 | I30: =SUM(H9:I9)/AVERAGE(G5,I5) -> 0.1 | J30: =SUM(I9:J9)/AVERAGE(H5,J5) -> -0.066666667 | K30: =SUM(J9:K9)/AVERAGE(I5,K5) -> 0.016528926 | L30: =SUM(K9:L9)/AVERAGE(J5,L5) -> 0.066115702 | M30: =SUM(L9:M9)/AVERAGE(K5,M5) -> 0.034682081 | N30: =SUM(M9:N9)/AVERAGE(L5,N5) -> 0.023121387 | ... AJ30: =SUM(AI9:AJ9)/AVERAGE(AH5,AJ5) -> 0.043715847
A31: ROE (NI) | G31: =SUM(F10:G10)/AVERAGE(E5,G5) -> 0.33333333 | H31: =SUM(G10:H10)/AVERAGE(F5,H5) -> 0.28571429 | I31: =SUM(H10:I10)/AVERAGE(G5,I5) -> 0.066666667 | J31: =SUM(I10:J10)/AVERAGE(H5,J5) -> -0.066666667 | K31: =SUM(J10:K10)/AVERAGE(I5,K5) -> 0.016528926 | L31: =SUM(K10:L10)/AVERAGE(J5,L5) -> 0.066115702 | M31: =SUM(L10:M10)/AVERAGE(K5,M5) -> 0.034682081 | N31: =SUM(M10:N10)/AVERAGE(L5,N5) -> 0.023121387 | ... AJ31: =SUM(AI10:AJ10)/AVERAGE(AH5,AJ5) -> 0.043715847
A33: Sales / Assets | D33: =D8*4/D3 -> #DIV/0! | E33: =E8*4/E3 -> 2.2857143 | F33: =F8*4/F3 -> 1.1428571 | G33: =G8*4/G3 -> 1.3877551 | H33: =H8*4/H3 -> 1.3877551 | I33: =I8*4/I3 -> 1.1851852 | J33: =J8*4/J3 -> 1.0847458 | K33: =K8*4/K3 -> 0.85393258 | ... AJ33: =AJ8*4/AJ3 -> 0.81602914

Sheet ownership
A1: Name | B1: Title | C1: shares | D1: voting rights | E1: % shares | F1: % Voting

Sheet tsh_IS
C2: TSH
C3: Premium Export
C6: Income Statement
D8: Q-33 | E8: Q-32 | F8: Q-31 | G8: Q-30 | H8: Q-29 | I8: Q-28 | J8: Q-27 | K8: Q-26 | L8: Q-25 | M8: Q-24 | N8: Q-23 | O8: Q-22 | P8: Q-21 | Q8: Q-20 | R8: Q-19 | S8: Q-18 | T8: Q-17 | U8: Q-16 | V8: Q-15 | W8: Q-14 | X8: Q-13 | Y8: Q-12 | Z8: Q-11 | AA8: Q-10 | AB8: Q-9 | AC8: Q-8 | AD8: Q-7 | AE8: Q-6 | AF8: Q-5 | AG8: Q-4 | AH8: Q-3 | AI8: Q-2 | AJ8: Q-1 | AK8: Q
C10: Period End Date | D10: 2017-03-31 | E10: 2017-06-30 | F10: 2017-09-30 | G10: 2017-12-31 | H10: 2018-03-31 | I10: 2018-06-30 | J10: 2018-09-30 | K10: 2018-12-31 | L10: 2019-03-31 | M10: 2019-06-30 | N10: 2019-09-30 | O10: 2019-12-31 | P10: 2020-03-31 | Q10: 2020-06-30 | R10: 2020-09-30 | S10: 2020-12-31 | T10: 2021-03-31 | U10: 2021-06-30 | V10: 2021-09-30 | W10: 2021-12-31 | X10: 2022-03-31 | Y10: 2022-06-30 | Z10: 2022-09-30 | AA10: 2022-12-31 | AB10: 2023-03-31 | AC10: 2023-06-30 | AD10: 2023-09-30 | AE10: 2023-12-31 | AF10: 2024-03-31 | AG10: 2024-06-30 | AH10: 2024-09-30 | AI10: 2024-12-31 | AJ10: 2025-03-31 | AK10: 2025-06-30
C12: Revenue | D12: 1.2 | E12: 1.2 | F12: 1.4 | G12: 1.4 | H12: 1.7 | I12: 1.7 | J12: 1.6 | K12: 1.6 | L12: 1.9 | M12: 1.9 | N12: 2 | O12: 2 | P12: 0.9 | Q12: 0.9 | R12: 1.2 | S12: 1.2 | T12: 1.3 | U12: 1.3 | V12: 1.3 | W12: 1.3 | X12: 1.7 | Y12: 1.7 | Z12: 2.7 | AA12: 2.7 | AB12: 2.5 | AC12: 2.5 | AD12: 3 | AE12: 3 | AF12: 2.5 | AG12: 2.5 | AH12: 3.3 | AI12: 3.3 | AJ12: 2.8 | AK12: 2.8
C13: Revenue Growth (YoY) | D13: NM | E13: NM | F13: NM | G13: NM | H13: 41.6% | I13: 41.6% | J13: 17.9% | K13: 17.9% | L13: 15.9% | M13: 15.9% | N13: 21.4% | O13: 21.4% | P13: -53.1% | Q13: -53.1% | R13: -40.6% | S13: -40.6% | T13: 45.0% | U13: 45.0% | V13: 8.5% | W13: 8.5% | X13: 30.8% | Y13: 30.8% | Z13: 115.8% | AA13: 115.8% | AB13: 45.4% | AC13: 45.4% | AD13: 8.5% | AE13: 8.5% | AF13: 1.5% | AG13: 1.5% | AH13: 12.4% | AI13: 12.4% | AJ13: 9.0% | AK13: 9.0%
C15: Cost of Revenues | D15: -0.5 | E15: -0.5 | F15: -0.3 | G15: -0.3 | H15: -0.6 | I15: -0.6 | J15: -0.3 | K15: -0.3 | L15: -0.5 | M15: -0.5 | N15: -0.4 | O15: -0.4 | P15: -0.2 | Q15: -0.2 | R15: -0.3 | S15: -0.3 | T15: -0.3 | U15: -0.3 | V15: -0.4 | W15: -0.4 | X15: -0.4 | Y15: -0.4 | Z15: -0.6 | AA15: -0.6 | AB15: -0.7 | AC15: -0.7 | AD15: -0.7 | AE15: -0.7 | AF15: -0.6 | AG15: -0.6 | AH15: -0.9 | AI15: -0.9 | AJ15: -0.7 | AK15: -0.7
C16: Gross Profit | D16: 0.7 | E16: 0.7 | F16: 1.1 | G16: 1.1 | H16: 1.1 | I16: 1.1 | J16: 1.3 | K16: 1.3 | L16: 1.4 | M16: 1.4 | N16: 1.5 | O16: 1.5 | P16: 0.7 | Q16: 0.7 | R16: 0.8 | S16: 0.8 | T16: 1 | U16: 1 | V16: 0.9 | W16: 0.9 | X16: 1.3 | Y16: 1.3 | Z16: 2.1 | AA16: 2.1 | AB16: 1.8 | AC16: 1.8 | AD16: 2.3 | AE16: 2.3 | AF16: 1.9 | AG16: 1.9 | AH16: 2.5 | AI16: 2.5 | AJ16: 2.1 | AK16: 2.1
C17: Gross Profit Margin | D17: 60.4% | E17: 60.4% | F17: 81.8% | G17: 81.8% | H17: 65.4% | I17: 65.4% | J17: 80.7% | K17: 80.7% | L17: 72.7% | M17: 72.7% | N17: 77.2% | O17: 77.2% | P17: 76.6% | Q17: 76.6% | R17: 71.5% | S17: 71.5% | T17: 73.9% | U17: 73.9% | V17: 69.8% | W17: 69.8% | X17: 74.4% | Y17: 74.4% | Z17: 76.4% | AA17: 76.4% | AB17: 70.9% | AC17: 70.9% | AD17: 76.2% | AE17: 76.2% | AF17: 75.4% | AG17: 75.4% | AH17: 73.7% | AI17: 73.7% | AJ17: 74.2% | AK17: 74.2%
C19: R&D Expenses | D19: 0 | E19: 0 | F19: 0 | G19: 0 | H19: 0 | I19: 0 | J19: 0 | K19: 0 | L19: 0 | M19: 0 | N19: 0 | O19: 0 | P19: 0 | Q19: 0 | R19: 0 | S19: 0 | T19: 0 | U19: 0 | V19: 0 | W19: 0 | X19: 0 | Y19: 0 | Z19: 0 | AA19: 0 | AB19: 0 | AC19: 0 | AD19: 0 | AE19: 0 | AF19: 0 | AG19: 0 | AH19: 0 | AI19: 0 | AJ19: 0 | AK19: 0
C20: Selling, General & Admin Expenses
C21: Other Inc / (Exp) | D21: -0.1 | E21: -0.1 | F21: -0.2 | G21: -0.2 | H21: 0 | I21: 0 | J21: -0.3 | K21: -0.3 | L21: -0.3 | M21: -0.3 | N21: -0.3 | O21: -0.3 | P21: -0.1 | Q21: -0.1 | R21: -0.6 | S21: -0.6 | T21: 0.1 | U21: 0.1 | V21: -0.1 | W21: -0.1 | X21: 0 | Y21: 0 | Z21: -0.4 | AA21: -0.4 | AB21: -0.1 | AC21: -0.1 | AD21: -0.7 | AE21: -0.7 | AF21: -0.2 | AG21: -0.2 | AH21: -0.6 | AI21: -0.6 | AJ21: -0.3 | AK21: -0.3
C22: Operating Expenses | D22: -0.6 | E22: -0.6 | F22: -0.7 | G22: -0.7 | H22: -0.7 | I22: -0.7 | J22: -1.5 | K22: -1.5 | L22: -1.2 | M22: -1.2 | N22: -1.4 | O22: -1.4 | P22: -1 | Q22: -1 | R22: -1.5 | S22: -1.5 | T22: -0.8 | U22: -0.8 | V22: -1.1 | W22: -1.1 | X22: -1.1 | Y22: -1.1 | Z22: -1.8 | AA22: -1.8 | AB22: -1.6 | AC22: -1.6 | AD22: -2.1 | AE22: -2.1 | AF22: -1.7 | AG22: -1.7 | AH22: -2.1 | AI22: -2.1 | AJ22: -1.8 | AK22: -1.8
C23: Operating Income | D23: 0.2 | E23: 0.2 | F23: 0.4 | G23: 0.4 | H23: 0.4 | I23: 0.4 | J23: -0.1 | K23: -0.1 | L23: 0.2 | M23: 0.2 | N23: 0.1 | O23: 0.1 | P23: -0.3 | Q23: -0.3 | R23: -0.7 | S23: -0.7 | T23: 0.1 | U23: 0.1 | V23: -0.2 | W23: -0.2 | X23: 0.2 | Y23: 0.2 | Z23: 0.3 | AA23: 0.3 | AB23: 0.2 | AC23: 0.2 | AD23: 0.1 | AE23: 0.1 | AF23: 0.2 | AG23: 0.2 | AH23: 0.3 | AI23: 0.3 | AJ23: 0.2 | AK23: 0.2
C25: Net Interest Expenses | D25: 0 | E25: 0 | F25: 0 | G25: 0 | H25: 0 | I25: 0 | J25: 0 | K25: 0 | L25: 0 | M25: 0 | N25: 0 | O25: 0 | P25: 0 | Q25: 0 | R25: 0 | S25: 0 | T25: 0 | U25: 0 | V25: 0 | W25: 0 | X25: 0 | Y25: 0 | Z25: 0 | AA25: 0 | AB25: -0.1 | AC25: -0.1 | AD25: -0.1 | AE25: -0.1 | AF25: -0.1 | AG25: -0.1 | AH25: 0 | AI25: 0 | AJ25: 0 | AK25: 0
C26: EBT, Incl. Unusual Items | D26: 0.2 | E26: 0.2 | F26: 0.4 | G26: 0.4 | H26: 0.4 | I26: 0.4 | J26: -0.1 | K26: -0.1 | L26: 0.2 | M26: 0.2 | N26: 0.1 | O26: 0.1 | P26: -0.3 | Q26: -0.3 | R26: -0.7 | S26: -0.7 | T26: 0.1 | U26: 0.1 | V26: -0.3 | W26: -0.3 | X26: 0.2 | Y26: 0.2 | Z26: 0.3 | AA26: 0.3 | AB26: 0.1 | AC26: 0.1 | AD26: 0.1 | AE26: 0.1 | AF26: 0.1 | AG26: 0.1 | AH26: 0.3 | AI26: 0.3 | AJ26: 0.2 | AK26: 0.2
C27: Earnings of Discontinued Ops.
C28: Income Tax Expense | D28: 0 | E28: 0 | F28: 0 | G28: 0 | H28: 0 | I28: 0 | J28: 0 | K28: 0 | L28: 0 | M28: 0 | N28: 0 | O28: 0 | P28: 0 | Q28: 0 | R28: 0 | S28: 0 | T28: 0 | U28: 0 | V28: 0 | W28: 0 | X28: 0 | Y28: 0 | Z28: 0 | AA28: 0 | AB28: 0 | AC28: 0 | AD28: 0 | AE28: 0 | AF28: 0 | AG28: 0 | AH28: 0 | AI28: 0 | AJ28: 0 | AK28: 0
C29: Net Income to Company | D29: 0.1 | E29: 0.1 | F29: 0.4 | G29: 0.4 | H29: 0.3 | I29: 0.3 | J29: -0.1 | K29: -0.1 | L29: 0.2 | M29: 0.2 | N29: 0.1 | O29: 0.1 | P29: -0.3 | Q29: -0.3 | R29: -0.7 | S29: -0.7 | T29: 0.1 | U29: 0.1 | V29: -0.3 | W29: -0.3 | X29: 0.2 | Y29: 0.2 | Z29: 0.3 | AA29: 0.3 | AB29: 0.1 | AC29: 0.1 | AD29: 0.1 | AE29: 0.1 | AF29: 0.1 | AG29: 0.1 | AH29: 0.3 | AI29: 0.3 | AJ29: 0.2 | AK29: 0.2
C31: Minority Interest in Earnings
C32: Net Income to Stockholders | D32: 0.1 | E32: 0.1 | F32: 0.4 | G32: 0.4 | H32: 0.3 | I32: 0.3 | J32: -0.1 | K32: -0.1 | L32: 0.2 | M32: 0.2 | N32: 0.1 | O32: 0.1 | P32: -0.3 | Q32: -0.3 | R32: -0.7 | S32: -0.7 | T32: 0.1 | U32: 0.1 | V32: -0.3 | W32: -0.3 | X32: 0.2 | Y32: 0.2 | Z32: 0.3 | AA32: 0.3 | AB32: 0.1 | AC32: 0.1 | AD32: 0.1 | AE32: 0.1 | AF32: 0.1 | AG32: 0.1 | AH32: 0.3 | AI32: 0.3 | AJ32: 0.2 | AK32: 0.2
C34: Preferred Dividends & Other Adj. | D34: 0 | E34: 0 | F34: 0 | G34: 0 | H34: 0 | I34: 0 | J34: 0 | K34: 0 | L34: 0 | M34: 0 | N34: 0 | O34: 0 | P34: 0 | Q34: 0 | R34: 0 | S34: 0 | T34: 0 | U34: 0 | V34: 0 | W34: 0 | X34: 0 | Y34: 0 | Z34: 0 | AA34: 0 | AB34: 0 | AC34: 0 | AD34: 0 | AE34: 0 | AF34: 0 | AG34: 0 | AH34: 0 | AI34: 0 | AJ34: 0 | AK34: 0
C35: Net Income to Common Excl Extra Items | D35: 0.1 | E35: 0.1 | F35: 0.4 | G35: 0.4 | H35: 0.3 | I35: 0.3 | J35: -0.1 | K35: -0.1 | L35: 0.2 | M35: 0.2 | N35: 0.1 | O35: 0.1 | P35: -0.3 | Q35: -0.3 | R35: -0.7 | S35: -0.7 | T35: 0.1 | U35: 0.1 | V35: -0.3 | W35: -0.3 | X35: 0.2 | Y35: 0.2 | Z35: 0.3 | AA35: 0.3 | AB35: 0.1 | AC35: 0.1 | AD35: 0.1 | AE35: 0.1 | AF35: 0.1 | AG35: 0.1 | AH35: 0.3 | AI35: 0.3 | AJ35: 0.2 | AK35: 0.2
C37: Basic EPS (Cont. Ops) | H37: 0.01 | I37: 0.01 | J37: -0.0044 | K37: -0.0044 | L37: 0.004 | M37: 0.004 | N37: 0.0029 | O37: 0.0029 | P37: -0.0067 | Q37: -0.0067 | R37: -0.015 | S37: -0.015 | T37: 0.0024 | U37: 0.0024 | V37: -0.006 | W37: -0.006 | X37: 0.0037 | Y37: 0.0037 | Z37: 0.006 | AA37: 0.006 | AB37: 0.0031 | AC37: 0.0031 | AD37: 0.0013 | AE37: 0.0013 | AF37: 0.0031 | AG37: 0.0031 | AH37: 0.0065 | AI37: 0.0065 | AJ37: 0.0049 | AK37: 0.0049
C38: Diluted EPS (Cont. Ops) | H38: 0.01 | I38: 0.01 | J38: -0.0044 | K38: -0.0044 | L38: 0.004 | M38: 0.004 | N38: 0.0029 | O38: 0.0029 | P38: -0.0067 | Q38: -0.0067 | R38: -0.015 | S38: -0.015 | T38: 0.0024 | U38: 0.0024 | V38: -0.006 | W38: -0.006 | X38: 0.0037 | Y38: 0.0037 | Z38: 0.006 | AA38: 0.006 | AB38: 0.0031 | AC38: 0.0031 | AD38: 0.0013 | AE38: 0.0013 | AF38: 0.0031 | AG38: 0.0031 | AH38: 0.0065 | AI38: 0.0065 | AJ38: 0.0049 | AK38: 0.0049
C39: Weighted Average Basic Shares Out. | H39: 32.3 | I39: 32.3 | J39: 32.3 | K39: 32.3 | L39: 42.4 | M39: 42.4 | N39: 44.4 | O39: 44.4 | P39: 44.4 | Q39: 44.4 | R39: 44.4 | S39: 44.4 | T39: 44.4 | U39: 44.4 | V39: 44.4 | W39: 44.4 | X39: 44.4 | Y39: 44.4 | Z39: 44.4 | AA39: 44.4 | AB39: 44.4 | AC39: 44.4 | AD39: 44.4 | AE39: 44.4 | AF39: 44.4 | AG39: 44.4 | AH39: 44.4 | AI39: 44.4 | AJ39: 44.4 | AK39: 44.4
C40: Weighted Average Diluted Shares Out. | H40: 32.3 | I40: 32.3 | J40: 32.3 | K40: 32.3 | L40: 42.4 | M40: 42.4 | N40: 44.4 | O40: 44.4 | P40: 44.4 | Q40: 44.4 | R40: 44.4 | S40: 44.4 | T40: 44.4 | U40: 44.4 | V40: 44.4 | W40: 44.4 | X40: 44.4 | Y40: 44.4 | Z40: 44.4 | AA40: 44.4 | AB40: 44.4 | AC40: 44.4 | AD40: 44.4 | AE40: 44.4 | AF40: 44.4 | AG40: 44.4 | AH40: 44.4 | AI40: 44.4 | AJ40: 44.4 | AK40: 44.4
C42: EBITDA | D42: 0.1 | E42: 0.1 | F42: 0.5 | G42: 0.5 | H42: 0.4 | I42: 0.4 | J42: 0.2 | K42: 0.2 | L42: 0.2 | M42: 0.2 | N42: 0.2 | O42: 0.2 | P42: -0.5 | Q42: -0.5 | R42: -0.3 | S42: -0.3 | T42: -0.1 | U42: -0.1 | V42: -0.3 | W42: -0.3 | X42: 0.1 | Y42: 0.1 | Z42: 0.4 | AA42: 0.4 | AB42: 0 | AC42: 0 | AD42: 0.3 | AE42: 0.3 | AF42: 0.1 | AG42: 0.1 | AH42: 0.5 | AI42: 0.5 | AJ42: 0.2 | AK42: 0.2
C43: EBIT | D43: 0.1 | E43: 0.1 | F43: 0.4 | G43: 0.4 | H43: 0.3 | I43: 0.3 | J43: 0.1 | K43: 0.1 | L43: 0.1 | M43: 0.1 | N43: 0.1 | O43: 0.1 | P43: -0.5 | Q43: -0.5 | R43: -0.4 | S43: -0.4 | T43: -0.2 | U43: -0.2 | V43: -0.4 | W43: -0.4 | X43: 0.1 | Y43: 0.1 | Z43: 0.4 | AA43: 0.4 | AB43: 0 | AC43: 0 | AD43: 0.3 | AE43: 0.3 | AF43: 0.1 | AG43: 0.1 | AH43: 0.4 | AI43: 0.4 | AJ43: 0.2 | AK43: 0.2
C45: Revenue (Reported) | D45: 1.2 | E45: 1.2 | F45: 1.4 | G45: 1.4 | H45: 1.7 | I45: 1.7 | J45: 1.6 | K45: 1.6 | L45: 1.9 | M45: 1.9 | N45: 2 | O45: 2 | P45: 0.9 | Q45: 0.9 | R45: 1.2 | S45: 1.2 | T45: 1.3 | U45: 1.3 | V45: 1.3 | W45: 1.3 | X45: 1.7 | Y45: 1.7 | Z45: 2.7 | AA45: 2.7 | AB45: 2.5 | AC45: 2.5 | AD45: 3 | AE45: 3 | AF45: 2.5 | AG45: 2.5 | AH45: 3.3 | AI45: 3.3 | AJ45: 2.8 | AK45: 2.8
C46: Operating Income (Reported)
C47: Operating Income (Adjusted) | D47: 0.1 | E47: 0.1 | F47: 0.4 | G47: 0.4 | H47: 0.3 | I47: 0.3 | J47: 0.1 | K47: 0.1 | L47: 0.1 | M47: 0.1 | N47: 0.1 | O47: 0.1 | P47: -0.5 | Q47: -0.5 | R47: -0.4 | S47: -0.4 | T47: -0.2 | U47: -0.2 | V47: -0.4 | W47: -0.4 | X47: 0.1 | Y47: 0.1 | Z47: 0.4 | AA47: 0.4 | AB47: 0 | AC47: 0 | AD47: 0.3 | AE47: 0.3 | AF47: 0.1 | AG47: 0.1 | AH47: 0.4 | AI47: 0.4 | AJ47: 0.2 | AK47: 0.2
C48: Operating Income (Adjusted)

Sheet tsh_bs
C2: TSH
C3: Premium Export
C6: Balance Sheet
D8: Q-33 | E8: Q-32 | F8: Q-31 | G8: Q-30 | H8: Q-29 | I8: Q-28 | J8: Q-27 | K8: Q-26 | L8: Q-25 | M8: Q-24 | N8: Q-23 | O8: Q-22 | P8: Q-21 | Q8: Q-20 | R8: Q-19 | S8: Q-18 | T8: Q-17 | U8: Q-16 | V8: Q-15 | W8: Q-14 | X8: Q-13 | Y8: Q-12 | Z8: Q-11 | AA8: Q-10 | AB8: Q-9 | AC8: Q-8 | AD8: Q-7 | AE8: Q-6 | AF8: Q-5 | AG8: Q-4 | AH8: Q-3 | AI8: Q-2 | AJ8: Q-1 | AK8: Q
C10: Period End Date | D10: 2017-03-31 | E10: 2017-06-30 | F10: 2017-09-30 | G10: 2017-12-31 | H10: 2018-03-31 | I10: 2018-06-30 | J10: 2018-09-30 | K10: 2018-12-31 | L10: 2019-03-31 | M10: 2019-06-30 | N10: 2019-09-30 | O10: 2019-12-31 | P10: 2020-03-31 | Q10: 2020-06-30 | R10: 2020-09-30 | S10: 2020-12-31 | T10: 2021-03-31 | U10: 2021-06-30 | V10: 2021-09-30 | W10: 2021-12-31 | X10: 2022-03-31 | Y10: 2022-06-30 | Z10: 2022-09-30 | AA10: 2022-12-31 | AB10: 2023-03-31 | AC10: 2023-06-30 | AD10: 2023-09-30 | AE10: 2023-12-31 | AF10: 2024-03-31 | AG10: 2024-06-30 | AH10: 2024-09-30 | AI10: 2024-12-31 | AJ10: 2025-03-31 | AK10: 2025-06-30
C12: Cash And Equivalents | F12: 0.9 | G12: 0.9 | H12: 1 | I12: 1 | J12: 1 | K12: 1 | L12: 5.4 | M12: 5.4 | N12: 5.8 | O12: 5.8 | P12: 4.8 | Q12: 4.8 | R12: 4.4 | S12: 4.4 | T12: 5.9 | U12: 5.9 | V12: 4.7 | W12: 4.7 | X12: 4.1 | Y12: 4.1 | Z12: 3.7 | AA12: 3.7 | AB12: 1.8 | AC12: 1.8 | AD12: 1.9 | AE12: 1.9 | AF12: 1.7 | AG12: 1.7 | AH12: 2.5 | AI12: 2.5 | AJ12: 2.3 | AK12: 2.3
C13: Short Term Investments | F13: 0 | G13: 0 | H13: 0.1 | I13: 0.1 | J13: 0 | K13: 0 | N13: 0 | O13: 0 | R13: 0.1 | S13: 0.1 | V13: 0.2 | W13: 0.2 | Z13: 0.1 | AA13: 0.1 | AD13: 0 | AE13: 0 | AH13: 0.2 | AI13: 0.2
C14: Accounts Receivable, Net | F14: 0.2 | G14: 0.2 | H14: 0.2 | I14: 0.2 | J14: 0.1 | K14: 0.1 | L14: 0.6 | M14: 0.6 | N14: 0.1 | O14: 0.1 | P14: 0.9 | Q14: 0.9 | R14: 0.1 | S14: 0.1 | T14: 0.6 | U14: 0.6 | V14: 0.1 | W14: 0.1 | X14: 0.6 | Y14: 0.6 | Z14: 0.2 | AA14: 0.2 | AB14: 0.7 | AC14: 0.7 | AD14: 0.4 | AE14: 0.4 | AF14: 0.7 | AG14: 0.7 | AH14: 0.2 | AI14: 0.2 | AJ14: 0.7 | AK14: 0.7
C15: Inventory | F15: 2.6 | G15: 2.6 | H15: 2.6 | I15: 2.6 | J15: 2.8 | K15: 2.8 | L15: 2.8 | M15: 2.8 | N15: 3.2 | O15: 3.2 | P15: 3.3 | Q15: 3.3 | R15: 4 | S15: 4 | T15: 4.5 | U15: 4.5 | V15: 5.5 | W15: 5.5 | X15: 6.1 | Y15: 6.1 | Z15: 7.4 | AA15: 7.4 | AB15: 8.6 | AC15: 8.6 | AD15: 9 | AE15: 9 | AF15: 9.4 | AG15: 9.4 | AH15: 9.3 | AI15: 9.3 | AJ15: 9.6 | AK15: 9.6
C16: Prepaid Expenses | F16: 0 | G16: 0 | H16: 0 | I16: 0 | J16: 0 | K16: 0 | N16: 0.1 | O16: 0.1 | R16: 0.1 | S16: 0.1 | V16: 0.1 | W16: 0.1 | Z16: 0.1 | AA16: 0.1 | AD16: 0.1 | AE16: 0.1 | AH16: 0.1 | AI16: 0.1
C17: Other Current Assets | D17: 0 | E17: 0 | F17: 0.4 | G17: 0.4 | H17: 0.3 | I17: 0.3 | J17: 0.3 | K17: 0.3 | L17: 0 | M17: 0 | N17: 0.3 | O17: 0.3 | P17: 0 | Q17: 0 | R17: 0.3 | S17: 0.3 | T17: 0 | U17: 0 | V17: 0.3 | W17: 0.3 | X17: 0 | Y17: 0 | Z17: 0.3 | AA17: 0.3 | AB17: 0 | AC17: 0 | AD17: 0.2 | AE17: 0.2 | AF17: 0 | AG17: 0 | AH17: 0.1 | AI17: 0.1 | AJ17: 0 | AK17: 0
C18: Total Current Assets | F18: 4 | G18: 4 | H18: 4.2 | I18: 4.2 | J18: 4.3 | K18: 4.3 | L18: 8.8 | M18: 8.8 | N18: 9.4 | O18: 9.4 | P18: 9 | Q18: 9 | R18: 8.9 | S18: 8.9 | T18: 11 | U18: 11 | V18: 10.8 | W18: 10.8 | X18: 10.8 | Y18: 10.8 | Z18: 11.7 | AA18: 11.7 | AB18: 11.1 | AC18: 11.1 | AD18: 11.7 | AE18: 11.7 | AF18: 11.8 | AG18: 11.8 | AH18: 12.3 | AI18: 12.3 | AJ18: 12.6 | AK18: 12.6
C20: Property Plant And Equipment, Net | F20: 0.6 | G20: 0.6 | H20: 0.5 | I20: 0.5 | J20: 1.2 | K20: 1.2 | L20: 2.8 | M20: 2.8 | N20: 3.1 | O20: 3.1 | P20: 2.4 | Q20: 2.4 | R20: 0.9 | S20: 0.9 | T20: 0.7 | U20: 0.7 | V20: 0.5 | W20: 0.5 | X20: 0.6 | Y20: 0.6 | Z20: 2.6 | AA20: 2.6 | AB20: 3 | AC20: 3 | AD20: 3.1 | AE20: 3.1 | AF20: 2.4 | AG20: 2.4 | AH20: 1.5 | AI20: 1.5 | AJ20: 1.3 | AK20: 1.3
C21: Real Estate Owned
C22: Capitalized / Purchased Software | N22: 0 | O22: 0 | P22: 0 | Q22: 0 | R22: 0 | S22: 0 | T22: 0 | U22: 0 | V22: 0 | W22: 0 | X22: 0 | Y22: 0 | Z22: 0 | AA22: 0 | AD22: 0 | AE22: 0 | AF22: 0 | AG22: 0 | AH22: 0 | AI22: 0
C23: Long-term Investments | F23: 0 | G23: 0 | H23: 0 | I23: 0 | J23: 0 | K23: 0 | L23: 0 | M23: 0 | N23: 0 | O23: 0 | P23: 0 | Q23: 0
C24: Goodwill
C25: Other Intangibles | N25: 0 | O25: 0 | P25: 0 | Q25: 0 | R25: 0 | S25: 0 | T25: 0 | U25: 0 | V25: 0 | W25: 0 | X25: 0 | Y25: 0 | Z25: 0 | AA25: 0 | AD25: 0 | AE25: 0 | AF25: 0 | AG25: 0 | AH25: 0 | AI25: 0 | AJ25: 0 | AK25: 0
C26: Other Long-term Assets | D26: 0 | E26: 0 | F26: 0.2 | G26: 0.2 | H26: 0.2 | I26: 0.2 | J26: 0.3 | K26: 0.3 | L26: 0.3 | M26: 0.3 | N26: 0.4 | O26: 0.4 | P26: 0.4 | Q26: 0.4 | R26: 0.3 | S26: 0.3 | T26: 0.3 | U26: 0.3 | V26: 0.1 | W26: 0.1 | X26: 0.1 | Y26: 0.1 | Z26: 0.2 | AA26: 0.2 | AB26: 0.3 | AC26: 0.3 | AD26: 0.4 | AE26: 0.4 | AF26: 0.4 | AG26: 0.4 | AH26: 0.2 | AI26: 0.2 | AJ26: 0.2 | AK26: 0.2
C27: Total Assets | F27: 4.9 | G27: 4.9 | H27: 4.9 | I27: 4.9 | J27: 5.9 | K27: 5.9 | L27: 11.9 | M27: 11.9 | N27: 12.9 | O27: 12.9 | P27: 11.8 | Q27: 11.8 | R27: 10.2 | S27: 10.2 | T27: 12 | U27: 12 | V27: 11.5 | W27: 11.5 | X27: 11.5 | Y27: 11.5 | Z27: 14.5 | AA27: 14.5 | AB27: 14.4 | AC27: 14.4 | AD27: 15.1 | AE27: 15.1 | AF27: 14.6 | AG27: 14.6 | AH27: 14.1 | AI27: 14.1 | AJ27: 14.1 | AK27: 14.1
C29: Accounts Payable | F29: 0.2 | G29: 0.2 | H29: 0.1 | I29: 0.1 | J29: 0.3 | K29: 0.3 | L29: 1.4 | M29: 1.4 | N29: 0.4 | O29: 0.4 | P29: 1.7 | Q29: 1.7 | R29: 0.4 | S29: 0.4 | T29: 1.5 | U29: 1.5 | V29: 0.2 | W29: 0.2 | X29: 1.6 | Y29: 1.6 | Z29: 0.7 | AA29: 0.7 | AB29: 1.9 | AC29: 1.9 | AD29: 0.6 | AE29: 0.6 | AF29: 2.3 | AG29: 2.3 | AH29: 0.4 | AI29: 0.4 | AJ29: 1.9 | AK29: 1.9
C30: Accrued Expenses | F30: 0.3 | G30: 0.3 | H30: 0.4 | I30: 0.4 | J30: 0.5 | K30: 0.5 | N30: 0.5 | O30: 0.5 | R30: 0.5 | S30: 0.5 | V30: 0.5 | W30: 0.5 | Z30: 0.8 | AA30: 0.8 | AD30: 0.7 | AE30: 0.7 | AH30: 1 | AI30: 1
C31: Short-term Borrowings | F31: 2.3 | G31: 2.3 | H31: 1.7 | I31: 1.7 | J31: 0.7 | K31: 0.7 | AB31: 0.6 | AC31: 0.6
C32: Current Portion of LT Debt | T32: 0.3 | U32: 0.3 | V32: 0.6 | W32: 0.6 | X32: 0.6 | Y32: 0.6 | Z32: 0.6 | AA32: 0.6 | AD32: 0.6 | AE32: 0.6 | AF32: 0.6 | AG32: 0.6 | AH32: 0.6 | AI32: 0.6 | AJ32: 0.4 | AK32: 0.4
C33: Current Portion of Capital Lease Obligations | L33: 0.2 | M33: 0.2 | N33: 1 | O33: 1 | P33: 1 | Q33: 1 | R33: 0.8 | S33: 0.8 | T33: 0.5 | U33: 0.5 | V33: 0.5 | W33: 0.5 | X33: 0.4 | Y33: 0.4 | Z33: 0.8 | AA33: 0.8 | AB33: 1 | AC33: 1 | AD33: 1.4 | AE33: 1.4 | AF33: 1.4 | AG33: 1.4 | AH33: 1.4 | AI33: 1.4 | AJ33: 1.2 | AK33: 1.2
C34: Other Current Liabilities | D34: 0 | E34: 0 | F34: 0.2 | G34: 0.2 | H34: 0.2 | I34: 0.2 | J34: 0.7 | K34: 0.7 | L34: 0.1 | M34: 0.1 | N34: 0.9 | O34: 0.9 | P34: 0.1 | Q34: 0.1 | R34: 1 | S34: 1 | T34: 0.1 | U34: 0.1 | V34: 1 | W34: 1 | X34: 0.1 | Y34: 0.1 | Z34: 0.8 | AA34: 0.8 | AB34: 0 | AC34: 0 | AD34: 1.1 | AE34: 1.1 | AF34: 0.3 | AG34: 0.3 | AH34: 1.1 | AI34: 1.1 | AJ34: 0.2 | AK34: 0.2
C35: Total Current Liabilities | F35: 3 | G35: 3 | H35: 2.4 | I35: 2.4 | J35: 2.1 | K35: 2.1 | L35: 1.7 | M35: 1.7 | N35: 2.7 | O35: 2.7 | P35: 2.7 | Q35: 2.7 | R35: 2.7 | S35: 2.7 | T35: 2.4 | U35: 2.4 | V35: 2.8 | W35: 2.8 | X35: 2.7 | Y35: 2.7 | Z35: 3.8 | AA35: 3.8 | AB35: 3.6 | AC35: 3.6 | AD35: 4.4 | AE35: 4.4 | AF35: 4.6 | AG35: 4.6 | AH35: 4.5 | AI35: 4.5 | AJ35: 3.7 | AK35: 3.7
C37: Long-term Debt | T37: 2.2 | U37: 2.2 | V37: 1.9 | W37: 1.9 | X37: 1.6 | Y37: 1.6 | Z37: 1.3 | AA37: 1.3 | AB37: 1 | AC37: 1 | AD37: 0.7 | AE37: 0.7 | AF37: 0.4 | AG37: 0.4 | AH37: 0.1 | AI37: 0.1
C38: Capital Leases | L38: 1.5 | M38: 1.5 | N38: 1.3 | O38: 1.3 | P38: 0.8 | Q38: 0.8 | R38: 0.6 | S38: 0.6 | T38: 0.3 | U38: 0.3 | V38: 0.2 | W38: 0.2 | X38: 0.3 | Y38: 0.3 | Z38: 2 | AA38: 2 | AB38: 2 | AC38: 2 | AD38: 2.2 | AE38: 2.2 | AF38: 1.4 | AG38: 1.4 | AH38: 0.9 | AI38: 0.9 | AJ38: 0.7 | AK38: 0.7
C39: Other Non-current Liabilities | D39: 0 | E39: 0 | F39: 0.1 | G39: 0.1 | H39: 0.1 | I39: 0.1 | J39: 0.1 | K39: 0.1 | L39: 0.1 | M39: 0.1 | N39: 0.1 | O39: 0.1 | P39: 0.1 | Q39: 0.1 | R39: 0.1 | S39: 0.1 | T39: 0.1 | U39: 0.1 | V39: 0 | W39: 0 | X39: 0.1 | Y39: 0.1 | Z39: 0 | AA39: 0 | AB39: 0.1 | AC39: 0.1 | AD39: 0.1 | AE39: 0.1 | AF39: 0.1 | AG39: 0.1 | AH39: 0 | AI39: 0 | AJ39: 0 | AK39: 0
C40: Total Liabilities | F40: 3.1 | G40: 3.1 | H40: 2.5 | I40: 2.5 | J40: 2.3 | K40: 2.3 | L40: 3.4 | M40: 3.4 | N40: 4.2 | O40: 4.2 | P40: 3.7 | Q40: 3.7 | R40: 3.3 | S40: 3.3 | T40: 5 | U40: 5 | V40: 5 | W40: 5 | X40: 4.7 | Y40: 4.7 | Z40: 7.2 | AA40: 7.2 | AB40: 6.7 | AC40: 6.7 | AD40: 7.4 | AE40: 7.4 | AF40: 6.5 | AG40: 6.5 | AH40: 5.5 | AI40: 5.5 | AJ40: 4.4 | AK40: 4.4
C42: Common Stock | F42: 0 | G42: 0 | H42: 0 | I42: 0 | J42: 0 | K42: 0 | L42: 4.6 | M42: 4.6 | N42: 4.6 | O42: 4.6 | P42: 4.6 | Q42: 4.6 | R42: 4.6 | S42: 4.6 | T42: 4.6 | U42: 4.6 | V42: 4.6 | W42: 4.6 | X42: 4.6 | Y42: 4.6 | Z42: 4.6 | AA42: 4.6 | AB42: 4.6 | AC42: 4.6 | AD42: 4.6 | AE42: 4.6 | AF42: 4.6 | AG42: 4.6 | AH42: 4.6 | AI42: 4.6 | AJ42: 4.6 | AK42: 4.6
C43: Additional Paid In Capital
C44: Retained Earnings | F44: 1.8 | G44: 1.8 | H44: 2.4 | I44: 2.4 | J44: 2.1 | K44: 2.1 | L44: 2.5 | M44: 2.5 | N44: 2.7 | O44: 2.7 | P44: 2.1 | Q44: 2.1 | R44: 0.8 | S44: 0.8 | T44: 1 | U44: 1 | V44: 0.5 | W44: 0.5 | X44: 0.8 | Y44: 0.8 | Z44: 1.3 | AA44: 1.3 | AB44: 1.6 | AC44: 1.6 | AD44: 1.7 | AE44: 1.7 | AF44: 2 | AG44: 2 | AH44: 2.6 | AI44: 2.6 | AJ44: 3.6 | AK44: 3.6
C45: Treasury Stock
C46: Other Common Equity Adj | D46: 0.7 | E46: 0 | F46: 0 | G46: 0 | H46: 0 | I46: 0 | J46: 1.5 | K46: 1.5 | L46: 1.5 | M46: 1.5 | N46: 1.5 | O46: 1.5 | P46: 1.5 | Q46: 1.5 | R46: 1.5 | S46: 1.5 | T46: 1.5 | U46: 1.5 | V46: 1.5 | W46: 1.5 | X46: 1.5 | Y46: 1.5 | Z46: 1.5 | AA46: 1.5 | AB46: 1.5 | AC46: 1.5 | AD46: 1.5 | AE46: 1.5 | AF46: 1.5 | AG46: 1.5 | AH46: 1.5 | AI46: 1.5 | AJ46: 1.5 | AK46: 1.5
C47: Common Equity | D47: 0.7 | F47: 1.8 | G47: 1.8 | H47: 2.4 | I47: 2.4 | J47: 3.6 | K47: 3.6 | L47: 8.5 | M47: 8.5 | N47: 8.8 | O47: 8.8 | P47: 8.2 | Q47: 8.2 | R47: 6.8 | S47: 6.8 | T47: 7 | U47: 7 | V47: 6.5 | W47: 6.5 | X47: 6.8 | Y47: 6.8 | Z47: 7.3 | AA47: 7.3 | AB47: 7.6 | AC47: 7.6 | AD47: 7.7 | AE47: 7.7 | AF47: 8 | AG47: 8 | AH47: 8.6 | AI47: 8.6 | AJ47: 9.7 | AK47: 9.7
C48: Total Preferred Equity
C49: Minority Interest, Total
C50: Other Equity | D50: 0 | E50: 0 | F50: 0 | G50: 0 | H50: 0 | I50: 0 | J50: 0 | K50: 0 | L50: 0 | M50: 0 | N50: 0 | O50: 0 | P50: 0 | Q50: 0 | R50: 0 | S50: 0 | T50: 0 | U50: 0 | V50: 0 | W50: 0 | X50: 0 | Y50: 0 | Z50: 0 | AA50: 0 | AB50: 0 | AC50: 0 | AD50: 0 | AE50: 0 | AF50: 0 | AG50: 0 | AH50: 0 | AI50: 0 | AJ50: 0 | AK50: 0
...
